Workbook

Sheet Chek
B3: ДВД
A4: Договорн. стоймость обьектов: | B4: 2.1352396e+08 | C4: 2.1352396e+08 | D4: =B4-C4 -> 0
A5: Сданы по фактуре: | B5: 2.2553272e+08 | C5: 2.2553272e+08 | D5: =B5-C5 -> 0
A6: Всего оплачено: | B6: 2.1192651e+08 | C6: 2.1192651e+08 | D6: =B6-C6 -> 0
A7: Осталось по договор.: | B7: 1721212.6 | C7: 1721212.6 | D7: =B7-C7 -> 0
A8: Осталось по сданным: | B8: 13606218 | C8: 13606218 | D8: =B8-C8 -> 0
B11: კორპუსები
A12: Договорн. стоймость обьектов: | D12: =B12-C12 -> 0
A13: Сданы по фактуре: | D13: =B13-C13 -> 0
A14: Всего оплачено: | D14: =B14-C14 -> 0
A15: Осталось по договор.: | D15: =B15-C15 -> 0
A16: Осталось по сданным: | D16: =B16-C16 -> 0
A19: Договорн. стоймость обьектов: | D19: =B19-C19 -> 0
A20: Сданы по фактуре: | D20: =B20-C20 -> 0
A21: Всего оплачено: | D21: =B21-C21 -> 0
A22: Осталось по договор.: | D22: =B22-C22 -> 0
A23: Осталось по сданным: | D23: =B23-C23 -> 0

Sheet PIVOT_ALL
A3: Row Labels | B3: Sum of სულ შესრ 2025 | C3: Sum of ფაქტორ. ხარჯი 2025
A4: 5 | B4: 19 | C4: 69
A5: (Пр)-Архитект-Проджект Компани | B5: 0
A6: (Пр)-Газ Констракт | B6: 40275.55
A7: (Пр)-Газсервис | B7: 0
A8: (Пр)-Джи Пи | B8: 0
A9: (Пр)-Джорджия Газ Проджект | B9: 0
A10: (Пр)-Интер Газ | B10: 0
A11: (Пр)-Интерсервис 2011 | B11: 0
A12: (Пр)-Унимшени | B12: 11102
A13: (Пр)-Циспери Али | B13: 0
A14: Аркмшенсервис | B14: 2971405.6 | C14: 147436.03
A15: Бриджи | B15: 2058818.8
A16: Газ Констракт | B16: 9754642.7 | C16: 40232.14
A17: Газсервис | B17: 6922112 | C17: 262367.49
A18: Джорджия Газ Проджект | B18: 3142978.1 | C18: 31453.45
A19: Интер Газ | B19: 12717647 | C19: 466204.67
A20: Интерсервис 2011 | B20: 3187738 | C20: 28773.66
A21: Унимшени | B21: 3908525 | C21: 68062.52
A22: Энерджи сервис | B22: 2603053.6 | C22: 90214.92
A23: ჰაიდროკორპი | B23: 0
A24: (blank) | B24: 0
A25: Grand Total | B25: 47318317 | C25: 1134813.9

Sheet ДВД
A1: СОКАР ДЖОРДЖИЯ ГАЗ строительство-реабилитация | F1: 283649.11 | H1: =F1-H728 -> -0.00021742599 | Q1: კვანძი T-11 (ახალ. აბონ. მიერთება) | AM1: 5197 | AO1: 70809.72 | BK1: კვანძი (ახალ. აბონ. მიერთება) | BL1: 45639 | BM1: Принят | BN1: SGG | BO1: 45635 | BP1: SGG-C-24-70 | BS1: Yes
B2: Договорн. стоймость обьектов: | D2: =F7 -> 2.1352396e+08 | J2: 27000 | AO2: =AO7-AO1 -> 181174.7
B3: Сданы по фактуре: | D3: =H7 -> 2.2611158e+08 | J3: 1420.98 | BQ3: Yes
B4: Всего оплачено: | D4: =J7 -> 2.1295651e+08 | J4: =J3*1.18 -> 1676.7564
B5: Осталось по договор.: | D5: =K7 -> 691206.24 | J5: =J2+J4 -> 28676.756 | BQ5: No
B6: Осталось по сданным: | D6: =L7 -> 13155069 | H6: =(H1106-3000)/1.18 -> 50847.458 | AU6: 1048112.8 | AX6: 2198778.9 | BA6: 2361095.4 | BE6: 1840117.9
B7: =SUBTOTAL(3,B11:B3497) -> 1243 | C7: =SUBTOTAL(3,C11:C3497) -> 1237 | D7: =SUBTOTAL(3,D11:D3497) -> 1244 | E7: =SUBTOTAL(3,E11:E3497) -> 1244 | F7: =SUBTOTAL(9,F11:F3497) -> 2.1352396e+08 | H7: =SUBTOTAL(9,H11:H3497) -> 2.2611158e+08 | I7: =SUBTOTAL(9,I11:I3497) -> 90222850 | J7: =SUBTOTAL(9,J11:J3497) -> 2.1295651e+08 | K7: =SUBTOTAL(9,K11:K3497) -> 691206.24 | L7: =SUBTOTAL(9,L11:L3497) -> 13155069 | M7: =SUBTOTAL(9,M11:M3497) -> 1247112.5 | N7: =SUBTOTAL(9,N11:N3497) -> 39145851 | P7: =SUBTOTAL(9,P11:P3497) -> 261 | Q7: =SUBTOTAL(3,Q11:Q3497) -> 1212 | R7: =SUBTOTAL(9,R11:R3497) -> 58983622 | S7: =SUBTOTAL(9,S11:S3497) -> 16786679 | T7: =SUBTOTAL(9,T11:T3497) -> 16289115 | U7: =SUBTOTAL(9,U11:U3497) -> 57356.245 | V7: =SUBTOTAL(9,V11:V3497) -> 12456955 | W7: =SUBTOTAL(9,W11:W3497) -> 2484780.2 | X7: =SUBTOTAL(9,X11:X3497) -> 8376742.9 | Y7: =SUBTOTAL(9,Y11:Y3497) -> 1589027 | ... AQ7: =SUBTOTAL(9,AQ11:AQ3497) -> 0 | AR7: =SUBTOTAL(3,AR11:AR3497) -> 17 | AS7: =SUBTOTAL(9,AS11:AS3497) -> 27481391 | AT7: =SUBTOTAL(9,AT11:AT3497) -> 1994631.4 | AU7: =SUBTOTAL(9,AU11:AU3497) -> 1048112.8 | AV7: =SUBTOTAL(9,AV11:AV3497) -> 33780261 | AW7: =SUBTOTAL(9,AW11:AW3497) -> 2845141.9 | AX7: =SUBTOTAL(9,AX11:AX3497) -> 2198778.9 | AY7: =SUBTOTAL(9,AY11:AY3497) -> 32062781 | AZ7: =SUBTOTAL(9,AZ11:AZ3497) -> 1935256.3 | ... BE7: =SUBTOTAL(9,BE11:BE3497) -> 1840117.9 | BG7: =SUBTOTAL(9,BG11:BG3497) -> 30448206 | BJ7: =SUBTOTAL(3,BJ11:BJ3497) -> 856 | BK7: =SUBTOTAL(3,BK11:BK3497) -> 1240 | BL7: =SUBTOTAL(3,BL11:BL3497) -> 1244 | BM7: =SUBTOTAL(3,BM11:BM3497) -> 1244 | BN7: =SUBTOTAL(3,BN11:BN3497) -> 1244 | BO7: =SUBTOTAL(3,BO11:BO3497) -> 28 | BP7: =SUBTOTAL(3,BP11:BP3497) -> 115 | BQ7: =SUBTOTAL(3,BQ11:BQ3497) -> 1045
A9: № пп | B9: Регион | C9: Район/ Город | D9: Обьект | E9: Подрядная организация | F9: Договорная стоймость обьекта | G9: X | H9: Работы сданы по фактуре (A) | I9: ღირებულება პროექტის გარეშე | J9: Оплачено | K9: Осталось от договорн. стоймости | L9: Осталось от сданных работ | M9: Дл. (м) строящ. газопр. | N9: Возможный долг (Д) | O9: 1 | P9: Кол. нов. абон. | Q9: № по бюджету | R9: სულ შესრ 2025 | S9: სულ გად 2025 | T9: I შესრ | U9: I გად | V9: II შესრ | W9: II გად | X9: III შესრ | Y9: III გად | Z9: IV შესრ | AA9: IV გად | AB9: V შესრ | AC9: V გად | AD9: VI შესრ | AE9: VI გად | AF9: VII შესრ | AG9: VII გად | AH9: VIII შესრ | AI9: VIII გად | AJ9: IX შესრ | AK9: IX გად | AL9: X შესრ | AM9: X გად | AN9: XI შესრ | AO9: XI გად | AP9: XII შესრ | AQ9: XII გად | AR9: ჰარე | AS9: ფაქტორ. თანხა 2022 | AT9: ფაქტორ. ხარჯი 2022 | AU9: სხვაობა 2022 | AV9: ფაქტორ. თანხა 2023 | AW9: ფაქტორ. ხარჯი 2023 | AX9: სხვაობა 2023 | AY9: ფაქტორ. თანხა 2024 | AZ9: ფაქტორ. ხარჯი 2024 | BA9: სხვაობა 2024 (1) | BB9: სხვაობა 2024 (2) | BC9: ფაქტორ. თანხა 2025 | BD9: ფაქტორ. ხარჯი 2025 | BE9: სხვაობა 2025 (1) | BF9: სხვაობა 2025 (2) | BG9: ნაწილი მიღებულია ექსპლ. | BH9: ნაწილის ექსპლ. მიღ. თარიღი | BI9: Тип пр. | BJ9: Дата приема | BK9: Статус/прием в эксплуатацию | BL9: Примеч. Или Компания | BM9: Дата закл. договора | BN9: № Догов. | BO9: № Эксп. Сметы | BP9: Регистрация/ კომენტარი | BQ9: Примечание
A10: 1 | B10: 2 | C10: 3 | D10: 4 | E10: 5 | F10: 6 | G10: 7 | H10: 8 | I10: 9 | J10: 10 | K10: 11 | L10: 12 | M10: 13 | N10: 14 | O10: 15 | P10: 16 | Q10: 17 | R10: 19 | S10: 20 | T10: 22 | U10: 23 | V10: 25 | W10: 26 | X10: 28 | Y10: 29 | Z10: 31 | AA10: 32 | AB10: 34 | AC10: 35 | AD10: 37 | AE10: 38 | AF10: 40 | AG10: 41 | AH10: 43 | AI10: 44 | AJ10: 46 | AK10: 47 | AL10: 49 | AM10: 50 | AN10: 52 | AO10: 53 | AP10: 55 | AQ10: 56 | AR10: 57 | AS10: 58 | AT10: 59 | AU10: 60 | AV10: 61 | AW10: 62 | AX10: 63 | AY10: 64 | AZ10: 65 | BA10: 66 | BB10: 67 | BC10: 68 | BD10: 69 | BG10: 70 | BH10: 71 | BI10: 72 | BJ10: 73 | BK10: 74 | BL10: 75 | BM10: 76 | BN10: 77 | BO10: 78 | BP10: 79 | BQ10: 80 | BR10: 81
A11: 700 | B11: Квемо Картли | C11: Болниси | D11: ს. მუშევანის გაზიფიცირების პროექტის შედგენა. | E11: (Пр)-Архитект-Проджект Компани | F11: 26113.5 | G11: 2 | H11: =14922*1.75 -> 26113.5 | J11: =3983.415+22130.085 -> 26113.5 | K11: =F11-J11 -> 0 | L11: =H11-J11 -> 0 | N11: =IF(OR(BK11="принят",BK11="Завершено"),H11-J11,F11-J11) -> 0 | O11: 0 | R11: =T11+V11+X11+Z11+AB11+AD11+AF11+AH11+AJ11+AL11+AN11+AP11 -> 0 | S11: =U11+W11+Y11+AA11+AC11+AE11+AG11+AI11+AK11+AM11+AO11+AQ11 -> 0 | AS11: 0 | AT11: 0 | AU11: 0 | BI11: Проектирование | BJ11: 45625 | BK11: ПриПро | BL11: Сакорггаз | BM11: 45538 | BN11: СС-240903-1/0
A12: 905 | B12: Аджара | C12: Кобулети | D12: ს. მუხაესტატედან ს. ქაქუთამდე მიწისქვეშა გაზსადენის მშენებლობის საპროექტო სამუშაოები. | E12: (Пр)-Унимшени | F12: 0 | G12: 2 | H12: =R12 -> 11102 | J12: =S12 -> 11102 | K12: =F12-J12 -> -11102 | L12: =H12-J12 -> 0 | N12: =IF(OR(BK12="принят",BK12="Завершено"),H12-J12,F12-J12) -> -11102 | O12: 2 | P12: 0 | R12: =T12+V12+X12+Z12+AB12+AD12+AF12+AH12+AJ12+AL12+AN12+AP12 -> 11102 | S12: =U12+W12+Y12+AA12+AC12+AE12+AG12+AI12+AK12+AM12+AO12+AQ12 -> 11102 | AB12: =6344*1.75 -> 11102 | AE12: =1693.53+9408.47 -> 11102 | AS12: 0 | AT12: 0 | AU12: 0 | BI12: Проектирование | BJ12: 45805 | BK12: ПриПро | BL12: SGG | BM12: 45509 | BN12: BSG-240805-2/0 (1) | BP12: GGTC-ს აშენებულმა ქსელმა წნევა ვერ დაიჭირა. | BQ12: No
A13: 980 | B13: Аджара | C13: Кобулети | D13: ს. მუხაესტატედან ს. ქაქუთამდე მიწისქვეშა გაზსადენის სამშენებლო სამუშაოები. | E13: Унимшени | F13: 1200000 | G13: 2 | H13: =R13 -> 738389 | J13: =S13+AV13+AY13+BC13 -> 690000 | K13: =F13-J13 -> 510000 | L13: =H13-J13 -> 48389 | N13: =IF(OR(BK13="принят",BK13="Завершено"),H13-J13,F13-J13) -> 48389 | O13: 1 | R13: =T13+V13+X13+Z13+AB13+AD13+AF13+AH13+AJ13+AL13+AN13+AP13 -> 738389 | S13: =U13+W13+Y13+AA13+AC13+AE13+AG13+AI13+AK13+AM13+AO13+AQ13 -> 105254.22 | V13: 90000 | X13: 200000 | Y13: 13728.81 | Z13: 200000 | AA13: 30508.47 | AB13: 200000 | AC13: 30508.47 | AE13: 30508.47 | AJ13: 48389 | AS13: 0 | AT13: 0 | AU13: 0 | BC13: =76271.19+169491.53+169491.53+169491.53 -> 584745.78 | BD13: =1467.44+24615.74+21592.76+21736.71 -> 69412.65 | BI13: Реаб. | BJ13: 45910 | BK13: Принят | BL13: SGG | BM13: 45509 | BN13: BSG-240805-2/0 (2) | BP13: GGTC-ს აშენებულმა ქსელმა წნევა ვერ დაიჭირა. | BQ13: Yes
A14: 1374 | B14: Имерети | C14: Багдати | D14: Ремонт офиса с/центра Багдади | E14: Газсервис | F14: 69496 | H14: 87450.58 | J14: =87450.58 -> 87450.58 | K14: =F14-J14 -> -17954.58 | L14: =H14-J14 -> 0 | M14: 0 | N14: =IF(OR(BK14="принят",BK14="Завершено"),H14-J14,F14-J14) -> 0 | O14: 0 | R14: =T14+V14+X14+Z14+AB14+AD14+AF14+AH14+AJ14+AL14+AN14+AP14 -> 0 | S14: =U14+W14+Y14+AA14+AC14+AE14+AG14+AI14+AK14+AM14+AO14+AQ14 -> 0 | AS14: 0 | AT14: 0 | AU14: 0 | BI14: Ремонт офиса | BJ14: 44925 | BK14: Принят | BL14: SGG | BM14: 44811 | BN14: SGG-C-22-64 | BQ14: No
A15: 1487 | B15: Шида Картли | C15: Гори | D15: На ул. Размадзе, реаб. Газопр. | E15: Газ Констракт | F15: 65177 | H15: 45857 | J15: 45857 | K15: =F15-J15 -> 19320 | L15: =H15-J15 -> 0 | M15: =865+147 -> 1012 | N15: =IF(OR(BK15="принят",BK15="Завершено",BK15="ПриПро"),H15-J15,F15-J15) -> 0 | O15: 0 | Q15: P.3.115 | R15: =T15+V15+X15+Z15+AB15+AD15+AF15+AH15+AJ15+AL15+AN15+AP15 -> 0 | S15: =U15+W15+Y15+AA15+AC15+AE15+AG15+AI15+AK15+AM15+AO15+AQ15 -> 0 | AS15: 0 | AT15: 0 | AU15: =IF(H15<50000,0,IF(AT15>0,(H15/1.18-AT15-H15/100*0.8)*0.1,(H15/1.18-H15/1.18/100*5.4-H15/100*0.8)*0.1)) -> 0 | BI15: Реаб. | BJ15: 44592 | BK15: Принят | BL15: Сакорггаз | BM15: 44477 | BN15: BC-211008-1/0 | BO15: 120 | BQ15: Yes
A16: 1494 | B16: Самцхе Джавахети | C16: Адигени | D16: В с. Вархани реабилитация подз. Газопровода. | E16: Газ Констракт | F16: 6286 | H16: 2939 | J16: 2939 | K16: =F16-J16 -> 3347 | L16: =H16-J16 -> 0 | M16: 226 | N16: =IF(OR(BK16="принят",BK16="Завершено",BK16="ПриПро"),H16-J16,F16-J16) -> 0 | O16: 0 | Q16: Поручение | R16: =T16+V16+X16+Z16+AB16+AD16+AF16+AH16+AJ16+AL16+AN16+AP16 -> 0 | S16: =U16+W16+Y16+AA16+AC16+AE16+AG16+AI16+AK16+AM16+AO16+AQ16 -> 0 | AS16: 0 | AT16: 0 | AU16: =IF(H16<50000,0,IF(AT16>0,(H16/1.18-AT16-H16/100*0.8)*0.1,(H16/1.18-H16/1.18/100*5.4-H16/100*0.8)*0.1)) -> 0 | BI16: Реаб. | BJ16: 44627 | BK16: принят | BL16: SGG | BM16: 44488 | BN16: BS-211019-1/0 | BO16: 144 | BQ16: Yes
A17: 1496 | B17: Кахети | C17: Лагодехи | D17: Питающий газопровод Цнори-Лагодехи, по направлению Лагодехи | E17: Бриджи | F17: =1197386+53648 -> 1251034 | H17: =405600+228800+416000+200634 -> 1251034 | J17: =150000+150000+61871.19+43000+160000+69528.81+200000+200000+31000+185634+S17 -> 1251034 | K17: =F17-J17 -> 0 | L17: =H17-J17 -> 0 | M17: 11377 | N17: =IF(OR(BK17="принят",BK17="Завершено",BK17="ПриПро"),H17-J17,F17-J17) -> 0 | O17: 0 | P17: 0 | Q17: P.2.6 | R17: =T17+V17+X17+Z17+AB17+AD17+AF17+AH17+AJ17+AL17+AN17+AP17 -> 0 | S17: =U17+W17+Y17+AA17+AC17+AE17+AG17+AI17+AK17+AM17+AO17+AQ17 -> 0 | AS17: 0 | AT17: 0 | AU17: 0 | BI17: Н. Стр. | BJ17: 44620 | BK17: Принят | BL17: SGG | BM17: 44620 | BN17: BS-211018-1/1 | BO17: 1511 | BQ17: Yes
A18: 1619 | B18: Имерети | C18: Самтредия | D18: 1.1.10. Строительство питающего газопровода Самтредиа - Хони. (P.6.115) | E18: Газсервис | F18: 3286000 | H18: =975000+950000+875000+460000+263977.93 -> 3523977.9 | J18: =148728.81+144915.25+133474.58+70169.49+40267.819+AS18+223710.121 -> 3523977.9 | K18: =F18-J18 -> -237977.93 | L18: =H18-J18 -> 0 | M18: 14407 | N18: =IF(OR(BK18="принят",BK18="Завершено",BK18="ПриПро"),H18-J18,F18-J18) -> 4.6566129e-10 | O18: 0 | Q18: P.6.115 | R18: =T18+V18+X18+Z18+AB18+AD18+AF18+AH18+AJ18+AL18+AN18+AP18 -> 0 | S18: =U18+W18+Y18+AA18+AC18+AE18+AG18+AI18+AK18+AM18+AO18+AQ18 -> 0 | AS18: 2762711.9 | AT18: 247979.81 | AU18: =IF(H18<50000,0,IF(AT18>0,(H18/1.18-AT18-147869.7-H18/100*0.8)*0.1,(H18/1.18-H18/1.18/100*5.4-147869.7-H18/100*0.8)*0.1)) -> 256238.06 | BI18: Реаб. | BJ18: 44925 | BK18: Принят | BL18: Сакорггаз | BM18: 44641 | BN18: BCP-220321-1/2(1.1.10) | BP18: GGG
A19: 1610 | B19: Имерети | C19: Вани | D19: 1.1.1. В г. Вани, строительство газопровода от улицы Соломона II до центра с . Сулори. (P.6.121) | E19: Газсервис | F19: 1203300 | H19: =910000+540000+426237.45 -> 1876237.4 | J19: =138813.56+82372.88+65019.27+AS19+361218.18 -> 1876237.4 | K19: =F19-J19 -> -672937.45 | L19: =H19-J19 -> 0 | M19: 10540 | N19: =IF(OR(BK19="принят",BK19="Завершено",BK19="ПриПро"),H19-J19,F19-J19) -> 0 | O19: 0 | Q19: P.6.121 | R19: =T19+V19+X19+Z19+AB19+AD19+AF19+AH19+AJ19+AL19+AN19+AP19 -> 0 | S19: =U19+W19+Y19+AA19+AC19+AE19+AG19+AI19+AK19+AM19+AO19+AQ19 -> 0 | AS19: 1228813.6 | AT19: 110836.44 | AU19: =IF(H19<50000,0,IF(AT19>0,(H19/1.18-AT19-H19/100*0.8)*0.1,(H19/1.18-H19/1.18/100*5.4-H19/100*0.8)*0.1)) -> 146418.54 | BI19: Реаб. | BJ19: 44925 | BK19: Принят | BL19: Сакорггаз | BM19: 44641 | BN19: BCP-220321-1/2(1.1.1)
A20: 1620 | B20: Имерети | C20: Самтредия | D20: 1.1.11. В с. Патара Джихайши, строительство питающего газопровода. (P.6.101) | E20: Газсервис | F20: 1185000 | H20: =642000+691360.32 -> 1333360.3 | J20: =97932.2+105461.74+AS20+585898.58 -> 1333360.3 | K20: =F20-J20 -> -148360.32 | L20: =H20-J20 -> 0 | M20: 5393 | N20: =IF(OR(BK20="принят",BK20="Завершено",BK20="ПриПро"),H20-J20,F20-J20) -> 0 | O20: 0 | Q20: P.6.101 | R20: =T20+V20+X20+Z20+AB20+AD20+AF20+AH20+AJ20+AL20+AN20+AP20 -> 0 | S20: =U20+W20+Y20+AA20+AC20+AE20+AG20+AI20+AK20+AM20+AO20+AQ20 -> 0 | AS20: 544067.8 | AT20: 32964.55 | AU20: =IF(H20<50000,0,IF(AT20>0,(H20/1.18-AT20-58834.37-H20/100*0.8)*0.1,(H20/1.18-H20/1.18/100*5.4-58834.37-H20/100*0.8)*0.1)) -> 102750.06 | BI20: Реаб. | BJ20: 44925 | BK20: Принят | BL20: Сакорггаз | BM20: 44641 | BN20: BCP-220321-1/2(1.1.11)
A21: 1505 | B21: Кахети | C21: Ахмета | D21: Часть (30м) ул. Руставели (I этап) | E21: Интерсервис 2011 | F21: 5313 | H21: 3751 | J21: =572.186+3178.814 -> 3751 | K21: =F21-J21 -> 1562 | L21: =H21-J21 -> 0 | M21: =30-17 -> 13 | N21: =IF(OR(BK21="принят",BK21="Завершено",BK21="ПриПро"),H21-J21,F21-J21) -> 0 | O21: 0 | Q21: P.2.94 | R21: =T21+V21+X21+Z21+AB21+AD21+AF21+AH21+AJ21+AL21+AN21+AP21 -> 0 | S21: =U21+W21+Y21+AA21+AC21+AE21+AG21+AI21+AK21+AM21+AO21+AQ21 -> 0 | AS21: 0 | AT21: 0 | AU21: =IF(H21<50000,0,IF(AT21>0,(H21/1.18-AT21-H21/100*0.8)*0.1,(H21/1.18-H21/1.18/100*5.4-H21/100*0.8)*0.1)) -> 0 | BE21: 0 | BI21: Реаб. | BJ21: 44651 | BK21: Принят | BL21: SGG | BM21: 44511 | BN21: BS-211111-1/0 | BO21: 1516 | BQ21: Yes
A22: 1497 | B22: Квемо Картли | C22: Гардабани | D22: Реаб. в селе Вахтангиси, Гардабанского муниципалитета включая замену и вынос счетчиков; | E22: Интерсервис 2011 | F22: 658219 | H22: =488220+65204+64429+38553 -> 656406 | J22: =74474.24+183744.76+200000+9946.37+9828.15+50412.48+88000+20000+20000 -> 656406 | K22: =F22-J22 -> 1813 | L22: =H22-J22 -> 0 | M22: 13346 | N22: =IF(OR(BK22="принят",BK22="Завершено",BK22="ПриПро"),H22-J22,F22-J22) -> 0 | O22: 0 | Q22: обязательство перед государством | R22: =T22+V22+X22+Z22+AB22+AD22+AF22+AH22+AJ22+AL22+AN22+AP22 -> 0 | S22: =U22+W22+Y22+AA22+AC22+AE22+AG22+AI22+AK22+AM22+AO22+AQ22 -> 0 | AS22: 0 | AT22: 0 | AU22: =IF(H22<50000,0,IF(AT22>0,(H22/1.18-AT22-H22/100*0.8)*0.1,(H22/1.18-H22/1.18/100*5.4-H22/100*0.8)*0.1)) -> 52098.61 | BE22: 0 | BI22: Реаб. | BJ22: 44712 | BK22: Принят | BL22: SGG | BM22: 44423 | BN22: BS-210815-1/0 | BO22: 1505 | BQ22: Yes
A23: 1616 | B23: Имерети | C23: Терджола | D23: 1.1.7. В г. Тержола, поселке Метлахис Кархана, реабилитация питающего газопровода. (проектирование и строительство). (P.6.135) | E23: Газсервис | F23: 610000 | H23: =420000+130000+47280.69+7904.75+N("Project") -> 605185.44 | J23: =64067.8+19830.51+7212.308+1205.809+AS23+46767.323 -> 605185.44 | K23: =F23-J23 -> 4814.56 | L23: =H23-J23 -> 0 | M23: 4354 | N23: =IF(OR(BK23="принят",BK23="Завершено",BK23="ПриПро"),H23-J23,F23-J23) -> 0 | O23: 0 | Q23: P.6.135 | R23: =T23+V23+X23+Z23+AB23+AD23+AF23+AH23+AJ23+AL23+AN23+AP23 -> 0 | S23: =U23+W23+Y23+AA23+AC23+AE23+AG23+AI23+AK23+AM23+AO23+AQ23 -> 0 | AS23: 466101.69 | AT23: 43787.44 | AU23: =IF(H23<50000,0,IF(AT23>0,(H23/1.18-AT23-H23/100*0.8)*0.1,(H23/1.18-H23/1.18/100*5.4-H23/100*0.8)*0.1)) -> 46424.009 | BI23: Реаб. | BJ23: 44925 | BK23: принят | BL23: Сакорггаз | BM23: 44641 | BN23: BCP-220321-1/2(1.1.7)
A24: 1509 | B24: Квемо Картли | C24: Рустави | D24: Вынос счетчиков на ул. Тбилиси №22, №3 I-го прохода Мегоброба, ул. Руставели №16 и ул. Батуми №17 | E24: Интерсервис 2011 | F24: 22886 | H24: 22751 | J24: =3470.49+19280.51 -> 22751 | K24: =F24-J24 -> 135 | L24: =H24-J24 -> 0 | M24: 448.5 | N24: =IF(OR(BK24="принят",BK24="Завершено",BK24="ПриПро"),H24-J24,F24-J24) -> 0 | O24: 0 | Q24: P.2.72 (1 и 2) Поручение | R24: =T24+V24+X24+Z24+AB24+AD24+AF24+AH24+AJ24+AL24+AN24+AP24 -> 0 | S24: =U24+W24+Y24+AA24+AC24+AE24+AG24+AI24+AK24+AM24+AO24+AQ24 -> 0 | AS24: 0 | AT24: 0 | AU24: =IF(H24<50000,0,IF(AT24>0,(H24/1.18-AT24-H24/100*0.8)*0.1,(H24/1.18-H24/1.18/100*5.4-H24/100*0.8)*0.1)) -> 0 | BE24: 0 | BI24: Реаб. | BJ24: 44651 | BK24: Принят | BL24: Сакорггаз | BM24: 44533 | BN24: BC-211203-1/0 | BO24: 155 | BQ24: Yes
A25: 1513 | B25: Самцхе Джавахети | C25: Адигени | D25: в Абастумани, строит. сети вместе с Фондом Муниц. Развития (I этап 1.6 км.) | E25: Интер Газ | F25: =63700.88+2991.16 -> 66692.04 | H25: =63700.88+2991.16 -> 66692.04 | J25: =56518.68+10173.36+S25 -> 66692.04 | K25: =F25-J25 -> 0 | L25: =H25-J25 -> 0 | M25: 1604 | N25: =IF(OR(BK25="принят",BK25="Завершено",BK25="ПриПро"),H25-J25,F25-J25) -> -1.4551915e-11 | O25: 0 | Q25: P.3.231 | R25: =T25+V25+X25+Z25+AB25+AD25+AF25+AH25+AJ25+AL25+AN25+AP25 -> 0 | S25: =U25+W25+Y25+AA25+AC25+AE25+AG25+AI25+AK25+AM25+AO25+AQ25 -> 0 | AS25: 0 | AT25: 0 | AU25: 0 | BI25: Н. Стр. | BJ25: 44655 | BK25: Принят | BL25: SGG | BM25: 44508 | BN25: BSP-211108-1/0 | BO25: Бюро Экспертизы Самхараули | BQ25: No
A26: 1514 | B26: Гурия | C26: Чохатаури | D26: Реаб. Газопр. На ул. Думбадзе | E26: (Пр)-Унимшени | F26: 1426.25 | H26: 1426.25 | J26: 1426.25 | K26: =F26-J26 -> 0 | L26: =H26-J26 -> 0 | N26: =IF(OR(BK26="принят",BK26="Завершено",BK26="ПриПро"),H26-J26,F26-J26) -> 0 | O26: 0 | Q26: Поручение | R26: =T26+V26+X26+Z26+AB26+AD26+AF26+AH26+AJ26+AL26+AN26+AP26 -> 0 | S26: =U26+W26+Y26+AA26+AC26+AE26+AG26+AI26+AK26+AM26+AO26+AQ26 -> 0 | AS26: 0 | AT26: 0 | AU26: 0 | BI26: Проектирование | BJ26: 44621 | BK26: ПриПро | BL26: SGG | BM26: 44607 | BN26: CS-220215-1/0
A27: 1515 | B27: Гурия | C27: Чохатаури | D27: Реаб. Газопр. На ул. Думбадзе | E27: Унимшени | F27: 47083 | H27: 42187 | J27: =6435.30508474576+35751.6949152542 -> 42187 | K27: =F27-J27 -> 4896 | L27: =H27-J27 -> 0 | M27: 813.8 | N27: =IF(OR(BK27="принят",BK27="Завершено",BK27="ПриПро"),H27-J27,F27-J27) -> 4.3655746e-11 | O27: 0 | Q27: Поручение | R27: =T27+V27+X27+Z27+AB27+AD27+AF27+AH27+AJ27+AL27+AN27+AP27 -> 0 | S27: =U27+W27+Y27+AA27+AC27+AE27+AG27+AI27+AK27+AM27+AO27+AQ27 -> 0 | AS27: 0 | AT27: 0 | AU27: 0 | BI27: Реаб. | BJ27: 44681 | BK27: принят | BL27: SGG | BM27: 44621 | BN27: BS-220301-1/0 | BO27: 001-22 | BQ27: Yes
A28: 1516 | B28: Имерети | C28: Чиатура | D28: Реаб. Газопр. в с. Дарквети. d-40 mm (из за оползни) | E28: (Пр)-Газсервис | F28: 549.5 | H28: 549.5 | J28: 549.5 | K28: =F28-J28 -> 0 | L28: =H28-J28 -> 0 | N28: =IF(OR(BK28="принят",BK28="Завершено",BK28="ПриПро"),H28-J28,F28-J28) -> 0 | O28: 0 | Q28: Поручение | R28: =T28+V28+X28+Z28+AB28+AD28+AF28+AH28+AJ28+AL28+AN28+AP28 -> 0 | S28: =U28+W28+Y28+AA28+AC28+AE28+AG28+AI28+AK28+AM28+AO28+AQ28 -> 0 | AS28: 0 | AT28: 0 | AU28: 0 | BI28: Проектирование | BJ28: 44620 | BK28: ПриПро | BL28: SGG | BM28: 44602 | BN28: CS-220210-1/0
A29: 1517 | B29: Имерети | C29: Чиатура | D29: Реаб. Газопр. в с. Дарквети. d-40 mm (из за оползни) | E29: Газсервис | F29: 12812 | H29: 12801 | J29: =1952.69+10848.31 -> 12801 | K29: =F29-J29 -> 11 | L29: =H29-J29 -> 0 | M29: =314+5 -> 319 | N29: =IF(OR(BK29="принят",BK29="Завершено",BK29="ПриПро"),H29-J29,F29-J29) -> 0 | O29: 0 | Q29: Поручение | R29: =T29+V29+X29+Z29+AB29+AD29+AF29+AH29+AJ29+AL29+AN29+AP29 -> 0 | S29: =U29+W29+Y29+AA29+AC29+AE29+AG29+AI29+AK29+AM29+AO29+AQ29 -> 0 | AS29: 0 | AT29: 0 | AU29: =IF(H29<50000,0,IF(AT29>0,(H29/1.18-AT29-H29/100*0.8)*0.1,(H29/1.18-H29/1.18/100*5.4-H29/100*0.8)*0.1)) -> 0 | BI29: Реаб. | BJ29: 44651 | BK29: Принят | BL29: SGG | BM29: 44624 | BN29: BS-220304-1/0 | BO29: 002-22 | BQ29: Yes
A30: 1518 | B30: Имерети | C30: Кутаиси | D30: Участ. ул. Давида Агмашенебели (от ул. Гамсахурдиа до ул. Ниношвили) | E30: (Пр)-Газсервис | F30: 3024 | H30: 3024 | J30: =461.288+2562.712 -> 3024 | K30: =F30-J30 -> 0 | L30: =H30-J30 -> 0 | N30: =IF(OR(BK30="принят",BK30="Завершено",BK30="ПриПро"),H30-J30,F30-J30) -> 0 | O30: 0 | Q30: Поручение | R30: =T30+V30+X30+Z30+AB30+AD30+AF30+AH30+AJ30+AL30+AN30+AP30 -> 0 | S30: =U30+W30+Y30+AA30+AC30+AE30+AG30+AI30+AK30+AM30+AO30+AQ30 -> 0 | AS30: 0 | AT30: 0 | AU30: 0 | BI30: Проектирование | BJ30: 44627 | BK30: ПриПро | BL30: Сакорггаз | BM30: 44620 | BN30: CC-220228-1/0
A31: 1519 | B31: Имерети | C31: Кутаиси | D31: Участ. ул. Давида Агмашенебели (от ул. Гамсахурдиа до ул. Ниношвили) | E31: Газсервис | F31: 306010 | G31: ამოსაღებია მცირე ეტაპები (გადასვლები) გაკეთდა ექსპლუატაციით. | K31: =F31-J31 -> 306010 | L31: =H31-J31 -> 0 | M31: 1728 | N31: =IF(OR(BK31="принят",BK31="Завершено",BK31="ПриПро"),H31-J31,F31-J31) -> 306010 | O31: XO | Q31: Поручение | R31: =T31+V31+X31+Z31+AB31+AD31+AF31+AH31+AJ31+AL31+AN31+AP31 -> 0 | S31: =U31+W31+Y31+AA31+AC31+AE31+AG31+AI31+AK31+AM31+AO31+AQ31 -> 0 | AS31: 0 | AT31: 0 | AU31: 0 | BI31: Реаб. | BK31: 0 | BL31: Сакорггаз | BM31: 44631 | BN31: BC-220311-1/0 | BO31: 001-22 | BP31: გასაუქმებელია, მცირე ეტაპები (გადასვლები) გაკეთდა ექსპლუატაციით. | BQ31: Yes
A32: 1520 | B32: Квемо Картли | C32: Рустави | D32: Вынос счетч. С корпусов ул. Костава №25, ул. Мегоброба №26. | E32: (Пр)-Интерсервис 2011 | F32: =213.5+2380 -> 2593.5 | H32: =213.5+2380 -> 2593.5 | J32: =395.618+2197.882 -> 2593.5 | K32: =F32-J32 -> 0 | L32: =H32-J32 -> 0 | N32: =IF(OR(BK32="принят",BK32="Завершено",BK32="ПриПро"),H32-J32,F32-J32) -> 0 | O32: 0 | Q32: P | R32: =T32+V32+X32+Z32+AB32+AD32+AF32+AH32+AJ32+AL32+AN32+AP32 -> 0 | S32: =U32+W32+Y32+AA32+AC32+AE32+AG32+AI32+AK32+AM32+AO32+AQ32 -> 0 | AS32: 0 | AT32: 0 | AU32: 0 | BI32: Проектирование | BJ32: 44641 | BK32: ПриПро | BL32: Сакорггаз | BM32: 44620 | BN32: CC-220228-2/0
A33: 1584 | B33: Квемо Картли | C33: Рустави | D33: 1.1.7. В г. Рустави замена полиэтиленовых труб на фасадах корпусов (I и II этап). (P.2.72 (1 и 2)) (проектирование и строительство) | E33: Интерсервис 2011 | F33: 3380000 | G33: ?? | H33: =70450+44500+42000+33500+27172.25+37500+42500+41000+0+38800+16800+15300+43000+41500+49500+5908+64662.5+54000+47700+49300+31400+75000+58000+82600+18000+35900+43300+29800+50400+43200+8600+16200+4300+6400+5800+90000+18000+40000+25000+18000+15000+32000+15000+60000+18000+12000+35000+8000+20000+35000+10000+20000+10000+35000+35000+30000+35000+25000+30000+30000+17389.75+30000+20000+10000+50000+30000+35000+45000+60000+15000+10000+50000+11520.25+8000+15000+10996+6105.83+17891.88+16542.76+29844.78+28190.84+28551+29642+9509+6980+7596+1543+5442+737+2462+2906+559+259+23666+2859+7222+819+1386+3040+1106+201+4403+3641+9026+30000+28000+30000+50000+5000+3000+60000+50000+7540.75+35155+39940+3403+42395+56899+50569+64033+3242+28732+20983+673+12056+1008+4868+4817+40000+20000+15000+3000+3430+2568+17203+16484+28646+60450+60362+180725+125958+48697+60980+62487+46690+88896+112289+86109+43055+54798+47438+3679+73988+21012.25 -> 4601287.8 | J33: =10746.61+70000+5720.34+6483.05+6254.28+5918.64+2562.71+2333.9+6559.32+6330.51+7550.85+901.22+110526.48 +N("ოქტ დღგ 19 შუალედურის")+109584.88+N("ნოემბ 26 მიღების ჯამური დღგ")+3050.847+1525.42+7627.118+4576.27+5338.98+6864.406+9152.54+2288.14+1525.42+7627.118+1757.326+1220.338+2288.1355+1677.3559+931.397+2729.269+2523.47+4552.59+4300.297+4521.66+4355.237+53597.59+N("იანვრის 29 მიღების დღგ")+69302.1+N("Feb 20 მიღების დღგ")+AS33+AV33+687352.34+179635.92+N("მარტის 17 ჩაბარების დღგ")+272000+2501.91+3123.31+655.51+1181.99+1107.83 -> 4601287.8 | K33: =F33-J33 -> -1221287.8 | L33: =H33-J33 -> 0.0055999998 | N33: =IF(OR(BK33="принят",BK33="Завершено",BK33="ПриПро"),H33-J33,F33-J33) -> -1221287.8 | O33: 1 | Q33: P.2.72 (1 и 2) | R33: =T33+V33+X33+Z33+AB33+AD33+AF33+AH33+AJ33+AL33+AN33+AP33 -> 0 | S33: =U33+W33+Y33+AA33+AC33+AE33+AG33+AI33+AK33+AM33+AO33+AQ33 -> 0 | AS33: =2113185.44+N("68 ფაქტორინგი") -> 2113185.4 | AT33: =13852+N("მხოლოდ 2022-ში დასრულებული 8 ობიექტის (ჯამური თანხით 540 365 ლარი) ფაქტორინგი") -> 13852 | AU33: =(540365/1.18-AT33-(540365/100*0.8))*0.1 -> 43976.152 | AV33: =785737.77+N("შესაძლოა იყო ფაქტორინგი ათვისებული 2023-შიც") -> 785737.77 | BI33: Корп | BK33: =82996+68805.83+67191.88+64142.76+72344.78+61690.84+63551+59642 -> 540365.09 | BL33: Сакорггаз | BM33: 44677 | BN33: BCP-220426-1/2(1.1.7) | BP33: გასაყოფია სწორად, 2022-სა და 2023-ს შორის!
A34: 1626 | B34: Имерети | C34: Кутаиси | D34: 1.1.17. Реабилитация газопроводов по улицам Хандзтели, Сараджишвили, Каухчишвили и Табидзе в г. Кутаиси. (P.6.303) | E34: Газсервис | F34: 700000 | H34: =430000+94696.55 -> 524696.55 | J34: =65593.22+14445.236+80251.314+AS34 -> 524696.55 | K34: =F34-J34 -> 175303.45 | L34: =H34-J34 -> 0 | M34: 1307 | N34: =IF(OR(BK34="принят",BK34="Завершено",BK34="ПриПро"),H34-J34,F34-J34) -> 0 | O34: 0 | Q34: P.6.303 | R34: =T34+V34+X34+Z34+AB34+AD34+AF34+AH34+AJ34+AL34+AN34+AP34 -> 0 | S34: =U34+W34+Y34+AA34+AC34+AE34+AG34+AI34+AK34+AM34+AO34+AQ34 -> 0 | AS34: 364406.78 | AT34: 26571.75 | AU34: =IF(H34<50000,0,IF(AT34>0,(H34/1.18-AT34-H34/100*0.8)*0.1,(H34/1.18-H34/1.18/100*5.4-H34/100*0.8)*0.1)) -> 41388.877 | BI34: Реаб. | BJ34: 44925 | BK34: Принят | BL34: Сакорггаз | BM34: 44641 | BN34: BCP-220321-1/2(1.1.17)
A35: 1625 | B35: Имерети | C35: Кутаиси | D35: 1.1.16. В г. Кутаиси, реабилитация газопровода на ул. Гелати. (P.6.68) | E35: Газсервис | F35: 253000 | H35: =200000+200000+119999.52 -> 519999.52 | J35: =30508.47+30508.47+18305.01+101694.52+AS35 -> 519999.52 | K35: =F35-J35 -> -266999.52 | L35: =H35-J35 -> 0 | M35: 2126 | N35: =IF(OR(BK35="принят",BK35="Завершено",BK35="ПриПро"),H35-J35,F35-J35) -> 0 | O35: 0 | Q35: P.6.68 | R35: =T35+V35+X35+Z35+AB35+AD35+AF35+AH35+AJ35+AL35+AN35+AP35 -> 0 | S35: =U35+W35+Y35+AA35+AC35+AE35+AG35+AI35+AK35+AM35+AO35+AQ35 -> 0 | AS35: 338983.05 | AT35: 29384.72 | AU35: =IF(H35<50000,0,IF(AT35>0,(H35/1.18-AT35-H35/100*0.8)*0.1,(H35/1.18-H35/1.18/100*5.4-H35/100*0.8)*0.1)) -> 40713.284 | BI35: Реаб. | BJ35: 44925 | BK35: Принят | BL35: Сакорггаз | BM35: 44641 | BN35: BCP-220321-1/2(1.1.16)
A36: 1524 | B36: Шида Картли | C36: Каспи | D36: ул. Костава, А. Церетели и Ширикашвили (пересечения Важа Пшавела и Цулукидзе) (I этап) | E36: Газ Констракт | F36: =45318+2304 -> 47622 | H36: 47622 | J36: =7264.37+34879.66+5477.96999999999 -> 47622 | K36: =F36-J36 -> 0 | L36: =H36-J36 -> 0 | M36: 1143 | N36: =IF(OR(BK36="принят",BK36="Завершено",BK36="ПриПро"),H36-J36,F36-J36) -> 0 | O36: 0 | Q36: часть от P 3.49; и часть от P 3.105 | R36: =T36+V36+X36+Z36+AB36+AD36+AF36+AH36+AJ36+AL36+AN36+AP36 -> 0 | S36: =U36+W36+Y36+AA36+AC36+AE36+AG36+AI36+AK36+AM36+AO36+AQ36 -> 0 | AS36: 0 | AT36: 0 | AU36: =IF(H36<50000,0,IF(AT36>0,(H36/1.18-AT36-H36/100*0.8)*0.1,(H36/1.18-H36/1.18/100*5.4-H36/100*0.8)*0.1)) -> 0 | BI36: Реаб. | BJ36: 44651 | BK36: Принят | BL36: Сакорггаз | BM36: 44571 | BN36: BC-220110-1/1 | BO36: 133 | BQ36: Yes
A37: 1525 | B37: Имерети | C37: Кутаиси | D37: ул. Джибладзе реаб. Газопр. | E37: (Пр)-Газсервис | F37: 633.5 | H37: 633.5 | J37: 633.5 | K37: =F37-J37 -> 0 | L37: =H37-J37 -> 0 | N37: =IF(OR(BK37="принят",BK37="Завершено",BK37="ПриПро"),H37-J37,F37-J37) -> 0 | O37: 0 | Q37: Поручение | R37: =T37+V37+X37+Z37+AB37+AD37+AF37+AH37+AJ37+AL37+AN37+AP37 -> 0 | S37: =U37+W37+Y37+AA37+AC37+AE37+AG37+AI37+AK37+AM37+AO37+AQ37 -> 0 | AS37: 0 | AT37: 0 | AU37: 0 | BI37: Проектирование | BJ37: 44649 | BK37: ПриПро | BL37: Сакорггаз | BM37: 44645 | BN37: CC-220325-1/0
A38: 1526 | B38: Имерети | C38: Кутаиси | D38: ул. Джибладзе реаб. Газопр. | E38: Газсервис | F38: 29668 | H38: 29579 | J38: 29579 | K38: =F38-J38 -> 89 | L38: =H38-J38 -> 0 | M38: 362 | N38: =IF(OR(BK38="принят",BK38="Завершено",BK38="ПриПро"),H38-J38,F38-J38) -> 0 | O38: 0 | Q38: Поручение | R38: =T38+V38+X38+Z38+AB38+AD38+AF38+AH38+AJ38+AL38+AN38+AP38 -> 0 | S38: =U38+W38+Y38+AA38+AC38+AE38+AG38+AI38+AK38+AM38+AO38+AQ38 -> 0 | AS38: 0 | AT38: 0 | AU38: =IF(H38<50000,0,IF(AT38>0,(H38/1.18-AT38-H38/100*0.8)*0.1,(H38/1.18-H38/1.18/100*5.4-H38/100*0.8)*0.1)) -> 0 | BI38: Реаб. | BJ38: 44681 | BK38: Принят | BL38: Сакорггаз | BM38: 44650 | BN38: BC-220330-1/0 | BO38: 005-22 | BQ38: Yes
A39: 1527 | B39: Шида Картли | C39: Гори | D39: 1.11 Реабилитация газопровода в селе Бербуки. (P 3.109) | E39: Газ Констракт | F39: 29862 | H39: 29442 | J39: 29442 | K39: =F39-J39 -> 420 | L39: =H39-J39 -> 0 | M39: 768 | N39: =IF(OR(BK39="принят",BK39="Завершено",BK39="ПриПро"),H39-J39,F39-J39) -> 0 | O39: 0 | Q39: P 3.109 | R39: =T39+V39+X39+Z39+AB39+AD39+AF39+AH39+AJ39+AL39+AN39+AP39 -> 0 | S39: =U39+W39+Y39+AA39+AC39+AE39+AG39+AI39+AK39+AM39+AO39+AQ39 -> 0 | AS39: 0 | AT39: 0 | AU39: =IF(H39<50000,0,IF(AT39>0,(H39/1.18-AT39-H39/100*0.8)*0.1,(H39/1.18-H39/1.18/100*5.4-H39/100*0.8)*0.1)) -> 0 | BI39: Реаб. | BJ39: 44712 | BK39: принят | BL39: Сакорггаз | BM39: 44658 | BN39: BC-220407-1/0 | BQ39: Yes
A40: 1528 | B40: Самцхе Джавахети | C40: Адигени | D40: в Абастумани, строит. сети вместе с Фондом Муниц. Развития (II этап 1.8 км.) (проектирование и строительство) (P.3.231) | E40: Интер Газ | F40: 600000 | H40: =132163.32+166596.97+204135+400000+250000+30130.71+(13157*1.75)+N("23024,75") -> 1206050.8 | I40: =132163.32+166596.97+204135+400000+250000+30130.71 -> 1183026 | J40: =112002.81+20160.51+166596.97+31139.237+172995.763+61016.949+338983.051+AY40+42731.8+23024.75+S40 -> 1206050.8 | K40: =F40-J40 -> -606050.75 | L40: =H40-J40 -> 0 | M40: 7400 | N40: =IF(OR(BK40="принят",BK40="Завершено",BK40="ПриПро"),H40-J40,F40-J40) -> 0 | O40: 0 | Q40: P.3.231 | R40: =T40+V40+X40+Z40+AB40+AD40+AF40+AH40+AJ40+AL40+AN40+AP40 -> 0 | S40: =U40+W40+Y40+AA40+AC40+AE40+AG40+AI40+AK40+AM40+AO40+AQ40 -> 0 | AS40: 0 | AT40: 0 | AU40: 0 | AY40: =211864.41+25534.5 -> 237398.91 | AZ40: =13843.74+N("მეორე ფაქტორინგი აიღო საბოლოო ჩაბარების შემდეგ") -> 13843.74 | BA40: 0 | BB40: 0 | BI40: Реаб. | BJ40: 45593 | BK40: Принят | BL40: SGG | BM40: 44683 | BN40: BSP-220502-1/0 | BQ40: No
A41: 1529 | B41: Имерети | C41: Багдати | D41: 1.2.1. С. Рохи (проектирование и строительство) P.6.127 (5) | E41: Интер Газ | F41: 3154968.3 | H41: =1560000+500000+1000000+70262.5+N("ეს პროექტია")+180000+24730+N("რეგულატორები (301023)")-0+N("ეს პროექტია გამოკლებული")+2215.49 -> 3337208 | I41: =H41-70262.5 -> 3266945.5 | J41: =237966.1+76271.19+1000000+AS41+70262.5+27457.627+AV41+3772.37+337.956+22835.169 -> 3337208 | K41: =F41-J41 -> -182239.73 | L41: =H41-J41 -> 0 | M41: 34332.59 | N41: =IF(OR(BK41="принят",BK41="Завершено",BK41="ПриПро"),H41-J41,F41-J41) -> 0 | O41: 0 | Q41: P.6.127 (5) | R41: =T41+V41+X41+Z41+AB41+AD41+AF41+AH41+AJ41+AL41+AN41+AP41 -> 0 | S41: =U41+W41+Y41+AA41+AC41+AE41+AG41+AI41+AK41+AM41+AO41+AQ41 -> 0 | AS41: =1322033.898+423728.81 -> 1745762.7 | AT41: =(1322.03+131478.99)+(423.73+38832.13) -> 172056.88 | AU41: 0 | AV41: =152542.37 -> 152542.37 | AW41: 18980.03 | BG41: 2419436.3 | BH41: 44925 | BI41: Реаб. | BJ41: 45259 | BK41: Принят | BL41: Сакорггаз | BM41: 44648 | BN41: BCP-220328-1/2(1.2.1) | BP41: 6 სოფელია მოქცეული ერთ p-ში. | BQ41: No
...

Sheet კორპუსები
A1: СОКАР ДЖОРДЖИЯ ГАЗ строительство-реабилитация | F1: 73429.4 | H1: =F1-I210 -> 0 | I1: 1.75 | J1: ="მშენებლობა რეაბილიტაციისა და კორპუსების ჯამი"&TEXT(ДВД!#REF!+კორპუსები!I4," ### ###") -> #REF! | AA1: =AA7+AA3 -> 17560.569 | AB1: საქორი | AI1: Квемо Картли | AJ1: Рустави | AK1: (1) გამოსატანი მრიცხველების გამოტანა (P.2.647) (დავით გარეჯის ქ. №18 კორპ) | AL1: დავით გარეჯის ქ. №18 კორპ
B3: Договорн. стоймость обьектов: | D3: =SUBTOTAL(9,H11:H961) -> 0 | N3: =SUBTOTAL(9,N11:N961) -> 0 | AA3: 17560.569
B4: Сданы по фактуре: | D4: =SUBTOTAL(9,I11:I961) -> 305400 | F4: =ROUND(D4/D3*100,2)&"% от дог. стойм." -> #DIV/0! | H4: Дл. газопр. | I4: =SUBTOTAL(9,N11:N961) -> 0 | J4: =I17+I18+I19+I20+I21+I32 -> 142980.92 | L4: Цена | M4: 1 пог.м. | N4: 1 абон.
B5: Всего оплачено: | D5: =SUBTOTAL(9,K11:K961) -> 46418.636 | F5: =ROUND(D5/D3*100,2)&"% от дог. стойм." -> #DIV/0! | H5: Кол-во. абон. | I5: =SUBTOTAL(9,Q11:Q961) -> 0 | J5: =J4-J7 -> 142980.92 | L5: Мах. | M5: =SUBTOTAL(4,AF11:AF961) -> 0 | N5: =SUBTOTAL(4,AG11:AG961) -> 0 | O5: =N6/1.18 -> #DIV/0!
B6: Осталось по договор.: | D6: =SUBTOTAL(9,L11:L961) -> -46418.636 | F6: =ROUND(D6/D3*100,2)&"% от дог. стойм." -> #DIV/0! | H6: Реальн. абон. | I6: =SUBTOTAL(9,R11:R961) -> 0 | L6: Ср. | M6: =D4/I4 -> #DIV/0! | N6: =D4/I6 -> #DIV/0! | O6: =M6/1.18 -> #DIV/0! | S6: =S7+V7 -> 0 | T6: =T7+W7 -> 0
A7: =SUBTOTAL(3,A11:A961) -> 9 | B7: Осталось по сданным: | D7: =SUBTOTAL(9,M11:M961) -> 258981.36 | F7: =ROUND(D7/D4*100,2)&"% от сд. стойм." -> 84.8% от сд. стойм. | H7: "Признано" аб. | I7: =SUBTOTAL(9,AD11:AD961) -> 0 | J7: =SUBTOTAL(9,J11:J961) -> 0 | K7: =SUBTOTAL(9,K11:K961) -> 46418.636 | L7: Мин. | M7: =SUBTOTAL(5,AF11:AF961) -> 0 | N7: =SUBTOTAL(5,AG11:AG961) -> 0 | O7: =SUBTOTAL(9,O11:O961) -> -46418.636 | Q7: =SUBTOTAL(9,Q11:Q961) -> 0 | R7: =SUBTOTAL(9,R11:R961) -> 0 | S7: =SUBTOTAL(9,S11:S961) -> 0 | T7: =SUBTOTAL(9,T11:T961) -> 0 | U7: =SUBTOTAL(9,U11:U961) -> 0 | V7: =SUBTOTAL(9,V11:V961) -> 0 | W7: =SUBTOTAL(9,W11:W961) -> 0 | X7: =SUBTOTAL(9,X11:X961) -> 0 | ... AD7: =SUBTOTAL(9,AD11:AD961) -> 0 | AI7: =SUBTOTAL(3,AI11:AI961) -> 0 | AJ7: =SUBTOTAL(3,AJ11:AJ961) -> 9 | AK7: =SUBTOTAL(3,AK11:AK961) -> 9 | AN7: =SUBTOTAL(3,AN11:AN961) -> 0 | AP7: =SUBTOTAL(3,AP11:AP961) -> 9 | AQ7: =SUBTOTAL(3,AQ11:AQ961) -> 0
A9: № пп | B9: Регион | C9: Район/ Город | D9: Обьект | E9: კორპუსის დასახელება | F9: Подрядная организация | H9: Договорная стоймость обьекта | I9: Работы сданы по фактуре (A) | J9: ღირებულება პროექტის გარეშე | K9: Оплачено | L9: Осталось от договорн. стоймости | M9: Осталось от сданных работ | N9: Дл. (м) строящ. газопр. | O9: Возможный долг (Д) | P9: 1 | Q9: Кол. нов. абон. | R9: Кол-во реальн. Абон. | S9: ფაქტორ. თანხა 2022 | T9: ფაქტორ. ხარჯი 2022 | U9: სხვაობა 2022 | V9: ფაქტორ. თანხა 2023 | W9: ფაქტორ. ხარჯი 2023 | X9: სხვაობა 2023 | Y9: ფაქტორ. თანხა 2024 | Z9: ფაქტორ. ხარჯი 2024 | AA9: სხვაობა 2024 (1) | AB9: სხვაობა 2024 (2) | AC9: ნაწილი მიღებულია ექსპლუატაციაში 2022 წელს | AD9: "Признано" КАПТО | AE9: для КАПТО | AF9: Расход на 1 п/м | AG9: Расход на 1-го абонента | AH9: Тип пр. | AI9: Дата приема | AJ9: Статус/прием в эксплуатацию | AK9: Примеч. Или Компания | AL9: Дата закл. договора | AM9: № Догов. | AN9: № Эксп. Сметы | AO9: План/ Год | AP9: № по бюджету | AQ9: Регистрация/ კომენტარი
A11: 2040 | B11: Квемо Картли | C11: Рустави | D11: (6) გამოტანილი მრიცხველების პოლიეთილენის მილების შეცვლა რკინის მილებით (P.2.619) (მე-16-ე მკრ. 2 კორპ) | E11: მე-16-ე მკრ. 2 კორპ | F11: Интерсервис 2011 | G11: 619 | H11: =1130.5+50000+9134 -> 60264.5 | I11: =1130.5+50000+9134 -> 60264.5 | J11: =1130.5+50000-1130.5+9134 -> 59134 | K11: =172.45+958.05+7627.12+S11+V11+1393.32+7740.68 -> 60264.5 | L11: =H11-K11 -> 0 | M11: =I11-K11 -> 0 | N11: 675 | O11: =IF(OR(AJ11="принят",AJ11="Завершено",AJ11="ПриПро"),I11-K11,H11-K11) -> 0 | P11: 0 | S11: 0 | T11: 0 | U11: 0 | V11: 42372.88 | W11: 2120.97 | AA11: =IF(AJ11="Принят",(J11/1.18-W11-Z11)*0.1,J11/1.18*0.8*0.1) -> 4799.2589 | AB11: =IF(AJ11="Принят",(J11/1.18-W11-Z11)*0.1,J11/1.18*0.8*0.1)-AA11 -> 0 | AF11: =IF(OR(I11="",I11=0,N11="",N11=0),"Нет инфо",I11/N11) -> 89.280741 | AG11: =IF(OR(I11="",I11=0,R11="",R11=0),"Нет инфо",I11/R11) -> Нет инфо | AH11: Реаб. | AI11: 45321 | AJ11: Принят | AK11: Сакорггаз | AL11: 44935 | AM11: BCG-230109-1/0(6) | AO11: P.2.619 | AP11: P.2.619
A12: 2041 | B12: Квемо Картли | C12: Рустави | D12: (6) გამოტანილი მრიცხველების პოლიეთილენის მილების შეცვლა რკინის მილებით (P.2.619) (მე-16-ე მკრ. 3 კორპ) | E12: მე-16-ე მკრ. 3 კორპ | F12: Интерсервис 2011 | G12: 619 | H12: =1291.5+50000+12068 -> 63359.5 | I12: =1291.5+50000+12068 -> 63359.5 | J12: =1291.5+50000-1291.5+12068 -> 62068 | K12: =197.01+1094.49+7627.12+S12+V12+1840.88+10227.12 -> 63359.5 | L12: =H12-K12 -> 0 | M12: =I12-K12 -> 0 | N12: 789 | O12: =IF(OR(AJ12="принят",AJ12="Завершено",AJ12="ПриПро"),I12-K12,H12-K12) -> 0 | P12: 0 | S12: 0 | T12: 0 | U12: 0 | V12: 42372.88 | W12: 2120.97 | AA12: =IF(AJ12="Принят",(J12/1.18-W12-Z12)*0.1,J12/1.18*0.8*0.1) -> 5047.903 | AB12: =IF(AJ12="Принят",(J12/1.18-W12-Z12)*0.1,J12/1.18*0.8*0.1)-AA12 -> 0 | AF12: =IF(OR(I12="",I12=0,N12="",N12=0),"Нет инфо",I12/N12) -> 80.303549 | AG12: =IF(OR(I12="",I12=0,R12="",R12=0),"Нет инфо",I12/R12) -> Нет инфо | AH12: Реаб. | AI12: 45321 | AJ12: Принят | AK12: Сакорггаз | AL12: 44935 | AM12: BCG-230109-1/0(6) | AO12: P.2.619 | AP12: P.2.619
A13: 2042 | B13: Квемо Картли | C13: Рустави | D13: (6) გამოტანილი მრიცხველების პოლიეთილენის მილების შეცვლა რკინის მილებით (P.2.619) (მე-16-ე მკრ. 10 კორპ) | E13: მე-16-ე მკრ. 10 კორპ | F13: Интерсервис 2011 | G13: 619 | H13: =1195.25+50000+9970 -> 61165.25 | I13: =1195.25+50000+9970 -> 61165.25 | J13: =1195.25+50000-1195.25+9970 -> 59970 | K13: =182.33+1012.92+S13+V13+7627.12+1520.85+8449.15 -> 61165.25 | L13: =H13-K13 -> 0 | M13: =I13-K13 -> 0 | N13: 719 | O13: =IF(OR(AJ13="принят",AJ13="Завершено",AJ13="ПриПро"),I13-K13,H13-K13) -> 0 | P13: 0 | S13: 0 | T13: 0 | U13: 0 | V13: 42372.88 | W13: 2120.97 | AA13: =IF(AJ13="Принят",(J13/1.18-W13-Z13)*0.1,J13/1.18*0.8*0.1) -> 4870.1064 | AB13: =IF(AJ13="Принят",(J13/1.18-W13-Z13)*0.1,J13/1.18*0.8*0.1)-AA13 -> 0 | AF13: =IF(OR(I13="",I13=0,N13="",N13=0),"Нет инфо",I13/N13) -> 85.069889 | AG13: =IF(OR(I13="",I13=0,R13="",R13=0),"Нет инфо",I13/R13) -> Нет инфо | AH13: Реаб. | AI13: 45321 | AJ13: Принят | AK13: Сакорггаз | AL13: 44935 | AM13: BCG-230109-1/0(6) | AO13: P.2.619 | AP13: P.2.619
A14: 2043 | B14: Квемо Картли | C14: Рустави | D14: (4) გამოსატანი მრიცხველების გამოტანა P.2.577 (მესხიშვ. I გასასვლ. №7) | E14: მესხიშვ. I გასასვლ. №7 | F14: Интерсервис 2011 | G14: 577 | H14: =2264.5+80000+5000+8049 -> 95313.5 | I14: =2264.5+80000+5000+8049 -> 95313.5 | J14: =80000+5000-2264.5+8049 -> 90784.5 | K14: =S14+V14+12203.39+345.43+762.71+1227.81+8740.26 -> 95313.5 | L14: =H14-K14 -> 0 | M14: =I14-K14 -> 0 | N14: 908 | O14: =IF(OR(AJ14="принят",AJ14="Завершено",AJ14="ПриПро"),I14-K14,H14-K14) -> 1.4551915e-11 | P14: 0 | S14: 0 | T14: 0 | U14: 0 | V14: =67796.61+4237.29 -> 72033.9 | W14: =4318.55+212.1 -> 4530.65 | AA14: =IF(AJ14="Принят",(J14/1.18-W14-Z14)*0.1,J14/1.18*0.8*0.1) -> 7240.5367 | AB14: =IF(AJ14="Принят",(J14/1.18-W14-Z14)*0.1,J14/1.18*0.8*0.1)-AA14 -> 0 | AF14: =IF(OR(I14="",I14=0,N14="",N14=0),"Нет инфо",I14/N14) -> 104.97081 | AG14: =IF(OR(I14="",I14=0,R14="",R14=0),"Нет инфо",I14/R14) -> Нет инфо | AH14: Реаб. | AI14: 45321 | AJ14: Принят | AK14: Сакорггаз | AL14: 44935 | AM14: BCG-230109-1/0(4) | AO14: P.2.577 | AP14: P.2.577
A15: 2044 | B15: Квемо Картли | C15: Рустави | D15: (4) გამოსატანი მრიცხველების გამოტანა P.2.577 (მესხიშვ. I გასასვლ. №9) | E15: მესხიშვ. I გასასვლ. №9 | F15: Интерсервис 2011 | G15: 577 | H15: =1737.75+80000+28338 -> 110075.75 | I15: =1737.75+80000+28338 -> 110075.75 | J15: =1737.75-1737.75+80000+28338 -> 108338 | K15: =S15+V15+12203.39+265.08+4322.75+25487.92 -> 110075.75 | L15: =H15-K15 -> 0 | M15: =I15-K15 -> 0 | N15: 1253 | O15: =IF(OR(AJ15="принят",AJ15="Завершено",AJ15="ПриПро"),I15-K15,H15-K15) -> 0 | P15: 0 | S15: 0 | T15: 0 | U15: 0 | V15: 67796.61 | W15: 4318.55 | AA15: =IF(AJ15="Принят",(J15/1.18-W15-Z15)*0.1,J15/1.18*0.8*0.1) -> 8749.3314 | AB15: =IF(AJ15="Принят",(J15/1.18-W15-Z15)*0.1,J15/1.18*0.8*0.1)-AA15 -> 0 | AF15: =IF(OR(I15="",I15=0,N15="",N15=0),"Нет инфо",I15/N15) -> 87.849761 | AG15: =IF(OR(I15="",I15=0,R15="",R15=0),"Нет инфо",I15/R15) -> Нет инфо | AH15: Реаб. | AI15: 45321 | AJ15: Принят | AK15: Сакорггаз | AL15: 44935 | AM15: BCG-230109-1/0(4) | AO15: P.2.577 | AP15: P.2.577
A16: 2045 | B16: Квемо Картли | C16: Рустави | D16: (2) გამოტანილი მრიცხველების პოლიეთილენის მილების შეცვლა რკინის მილებით P.2.744 (რუსთაველის ქ. №28 კორპ) | E16: რუსთაველის ქ. №28 კორპ | F16: Интерсервис 2011 | G16: 744 | H16: =1610+50000+743 -> 52353 | I16: =1610+50000+743 -> 52353 | J16: =1610-1610+50000+743 -> 50743 | K16: =S16+V16+245.59+7627.12+743+1364.41 -> 52353 | L16: =H16-K16 -> 0 | M16: =I16-K16 -> 0 | N16: 702 | O16: =IF(OR(AJ16="принят",AJ16="Завершено",AJ16="ПриПро"),I16-K16,H16-K16) -> 0 | P16: 0 | S16: 0 | T16: 0 | U16: 0 | V16: 42372.88 | W16: 2120.97 | AA16: =IF(AJ16="Принят",(J16/1.18-W16-Z16)*0.1,J16/1.18*0.8*0.1) -> 4088.1572 | AB16: =IF(AJ16="Принят",(J16/1.18-W16-Z16)*0.1,J16/1.18*0.8*0.1)-AA16 -> 0 | AF16: 86.462889 | AG16: Нет инфо | AH16: Реаб. | AI16: 45321 | AJ16: Принят | AK16: Сакорггаз | AL16: 44935 | AM16: BCG-230109-1/0(2) | AO16: P.2.744 | AP16: P.2.744
A17: 2046 | B17: Самцхе Джавахети | C17: Борджоми | D17: 1.1.24. В г. Боржоми реабилитация/реконструкция наружных сетей в корпусах на улицах Руставели и Месхети. (P.3.106) (проектирование и строительство) (რუსთაველის ქ. №85) | E17: რუსთაველის ქ. №85 | F17: Газ Констракт | H17: =1055.25+26491.26 -> 27546.51 | I17: =1055.25+26491.26 -> 27546.51 | J17: =I17-1055.25 -> 26491.26 | K17: =160.97+4041.039+23344.5 -> 27546.509 | L17: =H17-K17 -> 0.001 | M17: =I17-K17 -> 0.001 | N17: 569.6 | O17: =IF(OR(AJ17="принят",AJ17="Завершено",AJ17="ПриПро"),I17-K17,H17-K17) -> 0.001 | P17: 0 | S17: 0 | T17: 0 | U17: 0 | V17: 0 | W17: 0 | AA17: =J17/1.18*0.1 -> 2245.022 | AB17: =IF(AJ17="Принят",(J17/1.18-W17-Z17)*0.1,J17/1.18*0.8*0.1)-AA17 -> 0 | AF17: =IF(OR(I17="",I17=0,N17="",N17=0),"Нет инфо",I17/N17) -> 48.361148 | AG17: =IF(OR(I17="",I17=0,R17="",R17=0),"Нет инфо",I17/R17) -> Нет инфо | AH17: Реаб. | AI17: 45322 | AJ17: Принят | AK17: Сакорггаз | AL17: 44676 | AM17: BCP-220425-1/2(1.1.24) | AO17: P.3.106 | AP17: P.3.106
A18: 2047 | B18: Самцхе Джавахети | C18: Борджоми | D18: 1.1.24. В г. Боржоми реабилитация/реконструкция наружных сетей в корпусах на улицах Руставели и Месхети. (P.3.106) (проектирование и строительство) (რუსთაველის ქ. №89) | E18: რუსთაველის ქ. №89 | F18: Газ Констракт | H18: =666.75+20650.93 -> 21317.68 | I18: =666.75+20650.93 -> 21317.68 | J18: =I18-666.75 -> 20650.93 | K18: =101.71+3150.14+18065.83 -> 21317.68 | L18: =H18-K18 -> 0 | M18: =I18-K18 -> 0 | N18: 368.2 | O18: =IF(OR(AJ18="принят",AJ18="Завершено",AJ18="ПриПро"),I18-K18,H18-K18) -> 0 | P18: 0 | S18: 0 | T18: 0 | U18: 0 | V18: 0 | W18: 0 | AA18: =J18/1.18*0.1 -> 1750.0788 | AB18: =IF(AJ18="Принят",(J18/1.18-W18-Z18)*0.1,J18/1.18*0.8*0.1)-AA18 -> 0 | AF18: =IF(OR(I18="",I18=0,N18="",N18=0),"Нет инфо",I18/N18) -> 57.897012 | AG18: =IF(OR(I18="",I18=0,R18="",R18=0),"Нет инфо",I18/R18) -> Нет инфо | AH18: Реаб. | AI18: 45322 | AJ18: Принят | AK18: Сакорггаз | AL18: 44676 | AM18: BCP-220425-1/2(1.1.24) | AO18: P.3.106 | AP18: P.3.106
A19: 2048 | B19: Самцхе Джавахети | C19: Борджоми | D19: 1.1.24. В г. Боржоми реабилитация/реконструкция наружных сетей в корпусах на улицах Руставели и Месхети. (P.3.106) (проектирование и строительство) (რუსთაველის ქ. №91) | E19: რუსთაველის ქ. №91 | F19: Газ Констракт | H19: =1237.25+28404.56 -> 29641.81 | I19: =1237.25+28404.56 -> 29641.81 | J19: =I19-1237.25 -> 28404.56 | K19: =188.74+4332.898+25120.17 -> 29641.808 | L19: =H19-K19 -> 0.002 | M19: =I19-K19 -> 0.002 | N19: 706.5 | O19: =IF(OR(AJ19="принят",AJ19="Завершено",AJ19="ПриПро"),I19-K19,H19-K19) -> 0.002 | P19: 0 | S19: 0 | T19: 0 | U19: 0 | V19: 0 | W19: 0 | AA19: =J19/1.18*0.1 -> 2407.1661 | AB19: =IF(AJ19="Принят",(J19/1.18-W19-Z19)*0.1,J19/1.18*0.8*0.1)-AA19 -> 0 | AF19: =IF(OR(I19="",I19=0,N19="",N19=0),"Нет инфо",I19/N19) -> 41.955853 | AG19: =IF(OR(I19="",I19=0,R19="",R19=0),"Нет инфо",I19/R19) -> Нет инфо | AH19: Реаб. | AI19: 45322 | AJ19: Принят | AK19: Сакорггаз | AL19: 44676 | AM19: BCP-220425-1/2(1.1.24) | AO19: P.3.106 | AP19: P.3.106
A20: 2049 | B20: Самцхе Джавахети | C20: Борджоми | D20: 1.1.24. В г. Боржоми реабилитация/реконструкция наружных сетей в корпусах на улицах Руставели и Месхети. (P.3.106) (проектирование и строительство) (რუსთაველის ქ. №95) | E20: რუსთაველის ქ. №95 | F20: Газ Констракт | H20: =217+6357.74 -> 6574.74 | I20: =217+6357.74 -> 6574.74 | J20: =I20-217 -> 6357.74 | K20: =33.1+969.82+5571.82 -> 6574.74 | L20: =H20-K20 -> 0 | M20: =I20-K20 -> 0 | N20: 112.8 | O20: =IF(OR(AJ20="принят",AJ20="Завершено",AJ20="ПриПро"),I20-K20,H20-K20) -> 0 | P20: 0 | S20: 0 | T20: 0 | U20: 0 | V20: 0 | W20: 0 | AA20: =J20/1.18*0.1 -> 538.79153 | AB20: =IF(AJ20="Принят",(J20/1.18-W20-Z20)*0.1,J20/1.18*0.8*0.1)-AA20 -> 0 | AF20: =IF(OR(I20="",I20=0,N20="",N20=0),"Нет инфо",I20/N20) -> 58.286702 | AG20: =IF(OR(I20="",I20=0,R20="",R20=0),"Нет инфо",I20/R20) -> Нет инфо | AH20: Реаб. | AI20: 45322 | AJ20: Принят | AK20: Сакорггаз | AL20: 44676 | AM20: BCP-220425-1/2(1.1.24) | AO20: P.3.106 | AP20: P.3.106
A21: 2050 | B21: Самцхе Джавахети | C21: Борджоми | D21: 1.1.24. В г. Боржоми реабилитация/реконструкция наружных сетей в корпусах на улицах Руставели и Месхети. (P.3.106) (проектирование и строительство) (რუსთაველის ქ. №109) | E21: რუსთაველის ქ. №109 | F21: Газ Констракт | H21: =318.5+7711.34 -> 8029.84 | I21: =318.5+7711.34 -> 8029.84 | J21: =I21-318.5 -> 7711.34 | K21: =48.58+1176.306+6804.95 -> 8029.836 | L21: =H21-K21 -> 0.004 | M21: =I21-K21 -> 0.004 | N21: 182.2 | O21: =IF(OR(AJ21="принят",AJ21="Завершено",AJ21="ПриПро"),I21-K21,H21-K21) -> 0.004 | P21: 0 | S21: 0 | T21: 0 | U21: 0 | V21: 0 | W21: 0 | AA21: =J21/1.18*0.1 -> 653.50339 | AB21: =IF(AJ21="Принят",(J21/1.18-W21-Z21)*0.1,J21/1.18*0.8*0.1)-AA21 -> 0 | AF21: =IF(OR(I21="",I21=0,N21="",N21=0),"Нет инфо",I21/N21) -> 44.07157 | AG21: =IF(OR(I21="",I21=0,R21="",R21=0),"Нет инфо",I21/R21) -> Нет инфо | AH21: Реаб. | AI21: 45322 | AJ21: Принят | AK21: Сакорггаз | AL21: 44676 | AM21: BCP-220425-1/2(1.1.24) | AO21: P.3.106 | AP21: P.3.106
A22: 2051 | B22: Квемо Картли | C22: Рустави | D22: (4) გამოსატანი მრიცხველების გამოტანა P.2.577 (შარტავას ქ. №9 კორპუსი) | E22: შარტავას ქ. №9 კორპუსი | F22: Интерсервис 2011 | G22: 577 | H22: =2070.25+80000+36640 -> 118710.25 | I22: =2070.25+80000+36640 -> 118710.25 | J22: =I22-2070.25 -> 116640 | K22: =315.8+V22+12203.39+5589.15+32805.3 -> 118710.25 | L22: =H22-K22 -> 0 | M22: =I22-K22 -> 0 | N22: 1447 | O22: =IF(OR(AJ22="принят",AJ22="Завершено",AJ22="ПриПро"),I22-K22,H22-K22) -> 0 | P22: 0 | S22: 0 | T22: 0 | U22: 0 | V22: 67796.61 | W22: 3393.55 | AA22: =IF(AJ22="Принят",(J22/1.18-W22-Z22)*0.1,J22/1.18*0.8*0.1) -> 9545.3908 | AB22: =IF(AJ22="Принят",(J22/1.18-W22-Z22)*0.1,J22/1.18*0.8*0.1)-AA22 -> 0 | AF22: =IF(OR(I22="",I22=0,N22="",N22=0),"Нет инфо",I22/N22) -> 82.038874 | AG22: =IF(OR(I22="",I22=0,R22="",R22=0),"Нет инфо",I22/R22) -> Нет инфо | AH22: Реаб. | AI22: 45380 | AJ22: Принят | AK22: Сакорггаз | AL22: 44935 | AM22: BCG-230109-1/0(4) | AO22: P.2.577 | AP22: P.2.577
A23: 2052 | B23: Квемо Картли | C23: Рустави | D23: (10) გამოტანილი მრიცხველების პოლიეთილენის მილების შეცვლა რკინის მილებით P.2.721 (მე-7ა-ე მკრ. №3 კორპ) | E23: მე-7ა-ე მკრ. №3 კორპ | F23: Интерсервис 2011 | G23: 721 | H23: =1153.25+35000+1000+10260 -> 47413.25 | I23: =1153.25+35000+1000+10260 -> 47413.25 | J23: =I23-1153.25 -> 46260 | K23: =S23+V23+175.92+5338.98+152.54+1565.08+9672.25 -> 47413.25 | L23: =H23-K23 -> 0 | M23: =I23-K23 -> 0 | N23: 714 | O23: =IF(OR(AJ23="принят",AJ23="Завершено",AJ23="ПриПро"),I23-K23,H23-K23) -> 0 | P23: 0 | S23: 0 | T23: 0 | U23: 0 | V23: =29661.02+847.46 -> 30508.48 | W23: =1889.37+25.92 -> 1915.29 | AA23: =IF(AJ23="Принят",(J23/1.18-W23-Z23)*0.1,J23/1.18*0.8*0.1) -> 3728.81 | AB23: =IF(AJ23="Принят",(J23/1.18-W23-Z23)*0.1,J23/1.18*0.8*0.1)-AA23 -> 0 | AF23: =IF(OR(I23="",I23=0,N23="",N23=0),"Нет инфо",I23/N23) -> 66.405112 | AG23: =IF(OR(I23="",I23=0,R23="",R23=0),"Нет инфо",I23/R23) -> Нет инфо | AH23: Реаб. | AI23: 45380 | AJ23: Принят | AK23: Сакорггаз | AL23: 44935 | AM23: BCG-230109-1/0(10) | AO23: P.2.721 | AP23: P.2.721
A24: 2053 | B24: Квемо Картли | C24: Рустави | D24: (8) გამოტანილი მრიცხველების პოლიეთილენის მილების შეცვლა რკინის მილებით (P.2.701) (მეგობრობის ქ. №23 კორპუსი) | E24: მეგობრობის ქ. №23 კორპუსი | F24: Интерсервис 2011 | G24: 701 | H24: =483+50000+2000+5000+3635 -> 61118 | I24: =483+50000+2000+5000+3635 -> 61118 | J24: =I24-483 -> 60635 | K24: =483+V24+7627.12+Y24+305.08+762.71+3635 -> 61118 | L24: =H24-K24 -> 0 | M24: =I24-K24 -> 0 | N24: 523 | O24: =IF(OR(AJ24="принят",AJ24="Завершено",AJ24="ПриПро"),I24-K24,H24-K24) -> 0 | P24: 0 | S24: 0 | T24: 0 | U24: 0 | V24: 42372.88 | W24: 2120.97 | Y24: =1694.92+4237.29 -> 5932.21 | Z24: =51.85+79.12 -> 130.97 | AA24: =IF(AJ24="Принят",(J24/1.18-W24-Z24)*0.1,J24/1.18*0.8*0.1) -> 4913.3653 | AB24: =IF(AJ24="Принят",(J24/1.18-W24-Z24)*0.1,J24/1.18*0.8*0.1)-AA24 -> 0 | AF24: =IF(OR(I24="",I24=0,N24="",N24=0),"Нет инфо",I24/N24) -> 116.86042 | AG24: =IF(OR(I24="",I24=0,R24="",R24=0),"Нет инфо",I24/R24) -> Нет инфо | AH24: Реаб. | AI24: 45393 | AJ24: Принят | AK24: Сакорггаз | AL24: 44935 | AM24: BCG-230109-1/0(8) | AO24: P.2.701 | AP24: P.2.701
A25: 2054 | B25: Квемо Картли | C25: Рустави | D25: (6) გამოტანილი მრიცხველების პოლიეთილენის მილების შეცვლა რკინის მილებით (P.2.619) (შარტავას ქ. №11 კორპ) | E25: შარტავას ქ. №11 კორპ | F25: Интерсервис 2011 | G25: 619 | H25: =1440.25+55000+9360 -> 65800.25 | I25: =1440.25+55000+9360 -> 65800.25 | J25: =I25-1440.25 -> 64360 | K25: =1440.25+8389.83+Y25+1427.8+7932.2 -> 65800.25 | L25: =H25-K25 -> 0 | M25: =I25-K25 -> 0 | N25: 989 | O25: =IF(OR(AJ25="принят",AJ25="Завершено",AJ25="ПриПро"),I25-K25,H25-K25) -> 0 | P25: 0 | S25: 0 | T25: 0 | U25: 0 | Y25: 46610.17 | Z25: 1425.76 | AA25: =IF(AJ25="Принят",(J25/1.18-W25-Z25)*0.1,J25/1.18*0.8*0.1) -> 5311.6613 | AB25: =IF(AJ25="Принят",(J25/1.18-W25-Z25)*0.1,J25/1.18*0.8*0.1)-AA25 -> 0 | AF25: =IF(OR(I25="",I25=0,N25="",N25=0),"Нет инфо",I25/N25) -> 66.532103 | AG25: =IF(OR(I25="",I25=0,R25="",R25=0),"Нет инфо",I25/R25) -> Нет инфо | AH25: Реаб. | AI25: 45370 | AJ25: Принят | AK25: Сакорггаз | AL25: 44935 | AM25: BCG-230109-1/0(6) | AO25: P.2.619 | AP25: P.2.619
A26: 2055 | B26: Квемо Картли | C26: Рустави | D26: (4) გამოსატანი მრიცხველების გამოტანა P.2.577 (შარტავას ქ. №5 კორპუსი) | E26: შარტავას ქ. №5 კორპუსი | F26: Интерсервис 2011 | G26: 577 | H26: =2051+80000+2000 -> 84051 | I26: =2051+80000+2000+10000+13567 -> 107618 | J26: =I26-2051 -> 105567 | K26: =312.86+S26+12203.39+V26+Y26+305.08+1525.42+15305.14 -> 107618 | L26: =H26-K26 -> -23567 | M26: =I26-K26 -> 0 | N26: 1136 | O26: =IF(OR(AJ26="принят",AJ26="Завершено",AJ26="ПриПро"),I26-K26,H26-K26) -> 0 | P26: 0 | S26: 0 | T26: 0 | U26: 0 | V26: =67796.61 -> 67796.61 | W26: 3393.55 | Y26: =1694.92+8474.58 -> 10169.5 | Z26: =51.85+158.23 -> 210.08 | AA26: =IF(AJ26="Принят",(J26/1.18-W26-Z26)*0.1,J26/1.18*0.8*0.1) -> 8585.9929 | AB26: =IF(AJ26="Принят",(J26/1.18-W26-Z26)*0.1,J26/1.18*0.8*0.1)-AA26 -> 0 | AF26: =IF(OR(I26="",I26=0,N26="",N26=0),"Нет инфо",I26/N26) -> 94.734155 | AG26: =IF(OR(I26="",I26=0,R26="",R26=0),"Нет инфо",I26/R26) -> Нет инфо | AH26: Реаб. | AI26: 45393 | AJ26: Принят | AK26: Сакорггаз | AL26: 44935 | AM26: BCG-230109-1/0(4) | AO26: P.2.577 | AP26: P.2.577
A27: 2056 | B27: Квемо Картли | C27: Рустави | D27: (4) გამოსატანი მრიცხველების გამოტანა P.2.577 (მესხიშვ. II გასასვლ. №6 კორპ) | E27: მესხიშვ. II გასასვლ. №6 კორპ | F27: Интерсервис 2011 | G27: 577 | H27: =789.25+40000+48407 -> 89196.25 | I27: =789.25+40000+48407 -> 89196.25 | J27: =I27-789.25 -> 88407 | K27: =789.25+Y27+6101.69+7384.12+41022.88 -> 89196.25 | L27: =H27-K27 -> 0 | M27: =I27-K27 -> 0 | N27: 1281 | O27: =IF(OR(AJ27="принят",AJ27="Завершено",AJ27="ПриПро"),I27-K27,H27-K27) -> 0 | P27: 0 | S27: 0 | T27: 0 | U27: 0 | V27: 0 | Y27: 33898.31 | Z27: 1036.92 | AA27: =IF(AJ27="Принят",(J27/1.18-W27-Z27)*0.1,J27/1.18*0.8*0.1) -> 7388.4266 | AB27: =IF(AJ27="Принят",(J27/1.18-W27-Z27)*0.1,J27/1.18*0.8*0.1)-AA27 -> 0 | AF27: =IF(OR(I27="",I27=0,N27="",N27=0),"Нет инфо",I27/N27) -> 69.630172 | AG27: =IF(OR(I27="",I27=0,R27="",R27=0),"Нет инфо",I27/R27) -> Нет инфо | AH27: Реаб. | AI27: 45380 | AJ27: Принят | AK27: Сакорггаз | AL27: 44935 | AM27: BCG-230109-1/0(4) | AO27: P.2.577 | AP27: P.2.577
A28: 2057 | B28: Квемо Картли | C28: Рустави | D28: (4) გამოსატანი მრიცხველების გამოტანა P.2.577 (მესხიშვ. II გასასვლ. №4 კორპ) | E28: მესხიშვ. II გასასვლ. №4 კორპ | F28: Интерсервис 2011 | G28: 577 | H28: =1214.5+40000+41772 -> 82986.5 | I28: =1214.5+40000+41772 -> 82986.5 | J28: =I28-1214.5 -> 81772 | K28: =185.26+6101.69+Y28+6372+36429.24 -> 82986.5 | L28: =H28-K28 -> 0 | M28: =I28-K28 -> 0 | N28: 1004 | O28: =IF(OR(AJ28="принят",AJ28="Завершено",AJ28="ПриПро"),I28-K28,H28-K28) -> 0 | P28: 0 | S28: 0 | T28: 0 | U28: 0 | V28: 0 | Y28: 33898.31 | Z28: 1036.92 | AA28: =IF(AJ28="Принят",(J28/1.18-W28-Z28)*0.1,J28/1.18*0.8*0.1) -> 6826.1385 | AB28: =IF(AJ28="Принят",(J28/1.18-W28-Z28)*0.1,J28/1.18*0.8*0.1)-AA28 -> 0 | AF28: =IF(OR(I28="",I28=0,N28="",N28=0),"Нет инфо",I28/N28) -> 82.655876 | AG28: =IF(OR(I28="",I28=0,R28="",R28=0),"Нет инфо",I28/R28) -> Нет инфо | AH28: Реаб. | AI28: 45380 | AJ28: Принят | AK28: Сакорггаз | AL28: 44935 | AM28: BCG-230109-1/0(4) | AO28: P.2.577 | AP28: P.2.577
A29: 2058 | B29: Квемо Картли | C29: Рустави | D29: (4) გამოსატანი მრიცხველების გამოტანა P.2.577 (მესხიშვ. II გასასვლ. №8 კორპ) | E29: მესხიშვ. II გასასვლ. №8 კორპ | F29: Интерсервис 2011 | G29: 577 | H29: =778.75+40000 -> 40778.75 | I29: =778.75+40000+31053 -> 71831.75 | J29: =I29-778.75 -> 71053 | K29: =778.75+6101.69+Y29+4736.89+26316.11 -> 71831.75 | L29: =H29-K29 -> -31053 | M29: =I29-K29 -> 0 | N29: 785 | O29: =IF(OR(AJ29="принят",AJ29="Завершено",AJ29="ПриПро"),I29-K29,H29-K29) -> 0 | P29: 0 | S29: 0 | T29: 0 | U29: 0 | V29: 0 | Y29: 33898.31 | Z29: 1036.92 | AA29: =IF(AJ29="Принят",(J29/1.18-W29-Z29)*0.1,J29/1.18*0.8*0.1) -> 5917.7487 | AB29: =IF(AJ29="Принят",(J29/1.18-W29-Z29)*0.1,J29/1.18*0.8*0.1)-AA29 -> 0 | AF29: =IF(OR(I29="",I29=0,N29="",N29=0),"Нет инфо",I29/N29) -> 91.505414 | AG29: =IF(OR(I29="",I29=0,R29="",R29=0),"Нет инфо",I29/R29) -> Нет инфо | AH29: Реаб. | AI29: 45380 | AJ29: Принят | AK29: Сакорггаз | AL29: 44935 | AM29: BCG-230109-1/0(4) | AO29: P.2.577 | AP29: P.2.577
A30: 2059 | B30: Квемо Картли | C30: Рустави | D30: (4) გამოსატანი მრიცხველების გამოტანა P.2.577 (შარტავას ქ. №15 კორპუსი) | E30: შარტავას ქ. №15 კორპუსი | F30: Интерсервис 2011 | G30: 577 | H30: =866.25+50000+29540 -> 80406.25 | I30: =866.25+50000+29540 -> 80406.25 | J30: =I30-866.25 -> 79540 | K30: =866.25+7627.12+Y30+4506.1+25033.9 -> 80406.25 | L30: =H30-K30 -> 0 | M30: =I30-K30 -> 0 | N30: 1201 | O30: =IF(OR(AJ30="принят",AJ30="Завершено",AJ30="ПриПро"),I30-K30,H30-K30) -> 0 | P30: 0 | S30: 0 | T30: 0 | U30: 0 | V30: 0 | Y30: 42372.88 | Z30: 1296.15 | AA30: =IF(AJ30="Принят",(J30/1.18-W30-Z30)*0.1,J30/1.18*0.8*0.1) -> 6611.063 | AB30: =IF(AJ30="Принят",(J30/1.18-W30-Z30)*0.1,J30/1.18*0.8*0.1)-AA30 -> 0 | AF30: =IF(OR(I30="",I30=0,N30="",N30=0),"Нет инфо",I30/N30) -> 66.949417 | AG30: =IF(OR(I30="",I30=0,R30="",R30=0),"Нет инфо",I30/R30) -> Нет инфо | AH30: Реаб. | AI30: 45370 | AJ30: Принят | AK30: Сакорггаз | AL30: 44935 | AM30: BCG-230109-1/0(4) | AO30: P.2.577 | AP30: P.2.577
A31: 2060 | B31: Квемо Картли | C31: Рустави | D31: (6) გამოტანილი მრიცხველების პოლიეთილენის მილების შეცვლა რკინის მილებით (P.2.619) (შარტავას ქ. №7 კორპ) | E31: შარტავას ქ. №7 კორპუსი | F31: Интерсервис 2011 | G31: 619 | H31: =1400+55000+24730 -> 81130 | I31: =1400+55000+24730 -> 81130 | J31: =I31-1400 -> 79730 | K31: =1400+8389.83+Y31+3772.37+20957.63 -> 81130 | L31: =H31-K31 -> 0 | M31: =I31-K31 -> 0 | N31: 1088 | O31: =IF(OR(AJ31="принят",AJ31="Завершено",AJ31="ПриПро"),I31-K31,H31-K31) -> 0 | P31: 0 | S31: 0 | T31: 0 | U31: 0 | Y31: 46610.17 | Z31: 1425.76 | AA31: =IF(AJ31="Принят",(J31/1.18-W31-Z31)*0.1,J31/1.18*0.8*0.1) -> 6614.2037 | AB31: =IF(AJ31="Принят",(J31/1.18-W31-Z31)*0.1,J31/1.18*0.8*0.1)-AA31 -> 0 | AF31: =IF(OR(I31="",I31=0,N31="",N31=0),"Нет инфо",I31/N31) -> 74.568015 | AG31: =IF(OR(I31="",I31=0,R31="",R31=0),"Нет инфо",I31/R31) -> Нет инфо | AH31: Реаб. | AI31: 45370 | AJ31: Принят | AK31: Сакорггаз | AL31: 44935 | AM31: BCG-230109-1/0(6) | AO31: P.2.619 | AP31: P.2.619
A32: 2061 | B32: Самцхе Джавахети | C32: Борджоми | D32: 1.1.24. В г. Боржоми реабилитация/реконструкция наружных сетей в корпусах на улицах Руставели и Месхети. (P.3.106) (проектирование и строительство) (აღმაშენებლის 35) | E32: აღმაშენებლის 35 | F32: Газ Констракт | H32: =47717.84+2152.5 -> 49870.34 | I32: =47717.84+2152.5 -> 49870.34 | J32: =I32-2152.5 -> 47717.84 | K32: =328.35+47717.84+1824.15 -> 49870.34 | L32: =H32-K32 -> 0 | M32: =I32-K32 -> 0 | N32: 1289.3 | O32: =IF(OR(AJ32="принят",AJ32="Завершено",AJ32="ПриПро"),I32-K32,H32-K32) -> 0 | P32: 0 | S32: 0 | T32: 0 | U32: 0 | V32: 0 | W32: 0 | Y32: 0 | Z32: 0 | AA32: =J32/1.18*0.1 -> 4043.8847 | AB32: =IF(AJ32="Принят",(J32/1.18-W32-Z32)*0.1,J32/1.18*0.8*0.1)-AA32 -> 0 | AF32: =IF(OR(I32="",I32=0,N32="",N32=0),"Нет инфо",I32/N32) -> 38.680168 | AG32: =IF(OR(I32="",I32=0,R32="",R32=0),"Нет инфо",I32/R32) -> Нет инфо | AH32: Реаб. | AI32: 45351 | AJ32: Принят | AK32: Сакорггаз | AL32: 44676 | AM32: BCP-220425-1/2(1.1.24) | AO32: P.3.106 | AP32: P.3.106
A33: 2062 | B33: Квемо Картли | C33: Рустави | D33: (4) გამოსატანი მრიცხველების გამოტანა P.2.577 (შარტავას ქ. №17 კორპუსი) | E33: შარტავას ქ. №17 კორპუსი | F33: Интерсервис 2011 | G33: 577 | H33: =1550.5+70000+40956 -> 112506.5 | I33: =1550.5+70000+40956 -> 112506.5 | J33: =I33-1550.5 -> 110956 | K33: =236.52+Y33+10677.97+42269.98 -> 112506.5 | L33: =H33-K33 -> 0 | M33: =I33-K33 -> 0 | N33: 1103 | O33: =IF(OR(AJ33="принят",AJ33="Завершено",AJ33="ПриПро"),I33-K33,H33-K33) -> 0 | P33: 0 | S33: 0 | T33: 0 | U33: 0 | Y33: 59322.03 | Z33: 1107.62 | AA33: =IF(AJ33="Принят",(J33/1.18-W33-Z33)*0.1,J33/1.18*0.8*0.1) -> 9292.2888 | AB33: =IF(AJ33="Принят",(J33/1.18-W33-Z33)*0.1,J33/1.18*0.8*0.1)-AA33 -> 0 | AF33: =IF(OR(I33="",I33=0,N33="",N33=0),"Нет инфо",I33/N33) -> 102.00045 | AG33: =IF(OR(I33="",I33=0,R33="",R33=0),"Нет инфо",I33/R33) -> Нет инфо | AH33: Реаб. | AI33: 45400 | AJ33: Принят | AK33: Сакорггаз | AL33: 44935 | AM33: BCG-230109-1/0(4) | AO33: P.2.577 | AP33: P.2.577
A34: 2063 | B34: Квемо Картли | C34: Рустави | D34: (4) გამოსატანი მრიცხველების გამოტანა P.2.577 (ტაშკენტის ქ. №5 კორპუსი) | E34: ტაშკენტის ქ. №5 კორპუსი | F34: Интерсервис 2011 | G34: 577 | H34: =2096.5+120000+20000+39778 -> 181874.5 | I34: =2096.5+120000+20000+39778 -> 181874.5 | J34: =I34-2096.5 -> 179778 | K34: =319.81+Y34+18305.08+3050.847+58503.843 -> 181874.5 | L34: =H34-K34 -> 0 | M34: =I34-K34 -> 0 | N34: 1851 | O34: =IF(OR(AJ34="принят",AJ34="Завершено",AJ34="ПриПро"),I34-K34,H34-K34) -> 0 | P34: 0 | S34: 0 | T34: 0 | U34: 0 | Y34: 101694.92 | Z34: 1898.77 | AA34: =IF(AJ34="Принят",(J34/1.18-W34-Z34)*0.1,J34/1.18*0.8*0.1) -> 15045.547 | AB34: =IF(AJ34="Принят",(J34/1.18-W34-Z34)*0.1,J34/1.18*0.8*0.1)-AA34 -> 0 | AF34: =IF(OR(I34="",I34=0,N34="",N34=0),"Нет инфо",I34/N34) -> 98.257428 | AG34: =IF(OR(I34="",I34=0,R34="",R34=0),"Нет инфо",I34/R34) -> Нет инфо | AH34: Реаб. | AI34: 45400 | AJ34: Принят | AK34: Сакорггаз | AL34: 44935 | AM34: BCG-230109-1/0(4) | AO34: P.2.577 | AP34: P.2.577
