Workbook

Sheet ALL-saboloo (NEW)
AK1: კორექტირებული გეგმა
B2: SGG | C2: =SUM(C7:C18) -> 69009208 | D2: =SUM(D7:D18) -> 34912216 | E2: =SUM(E7:E18) -> 34096992 | F2: =SUM(F7:F18) -> 40215128 | G2: =SUM(G7:G18) -> 35437490 | H2: =SUM(H7:H18) -> 6118136.9 | I2: =SUM(I7:I18) -> 4777638.4 | J2: =SUM(J7:J18) -> 7311091.5 | ... AI2: =SUM(AI7:AI18) -> 35437490 | AK2: =SUM(AK7:AK18) -> 3253936.6 | AL2: =SUM(AL7:AL18) -> 3110440.4 | AN2: =AH2+AK2+AL2 -> 40764368 | AO2: ჯამი ფაქტი+პროგნოზი | AR2: =SUM(AR7:AR18) -> 6150000 | AS2: =SUM(AS7:AS18) -> 2850000
B3: კონტრაქტორი | C3: ობიექტის საპროგნოზო ღირებულება | D3: შუალედური ჩაბარებები 22-24 წწ. | E3: 2025 წლის გეგმა | F3: 2025 წლის გეგმა განახლებული | G3: 2025 წლის ფაქტი | H3: გეგმის ზრდა | I3: გეგმიდან დარჩა ჩასაბარებელი | AK3: დარჩა ჩასაბარებელი | AN3: ნოემბრამდე+დარჩენილი 2 თვე | AR3: 2026
J4: იანვარი 2025 | L4: თებერვალი 2025 | N4: მარტი 2025 | P4: აპრილი 2025 | R4: მაისი 2025 | T4: ივნისი 2025 | V4: ივლისი 2025 | X4: აგვისტო 2025 | Z4: სექტემბერი 2025 | AB4: ოქტომბერი 2025 | AD4: ნოემბერი 2025 | AF4: დეკემბერი 2025 | AH4: სულ 2025 წელი
J5: სულ | L5: სულ | N5: სულ | P5: სულ | R5: სულ | T5: სულ | V5: სულ | X5: სულ | Z5: სულ | AB5: სულ | AD5: სულ | AF5: სულ | AH5: სულ | AK5: ნოემბერი | AL5: დეკემბერი | AR5: იანვარი | AS5: თებერვალი
J6: გეგმა | K6: ფაქტი | L6: გეგმა | M6: ფაქტი | N6: გეგმა | O6: ფაქტი | P6: გეგმა | Q6: ფაქტი | R6: გეგმა | S6: ფაქტი | T6: გეგმა | U6: ფაქტი | V6: გეგმა | W6: ფაქტი | X6: გეგმა | Y6: ფაქტი | Z6: გეგმა | AA6: ფაქტი | AB6: გეგმა | AC6: ფაქტი | AD6: გეგმა | AE6: ფაქტი | AF6: გეგმა | AG6: ფაქტი | AH6: კორექტ. გეგმა | AI6: ფაქტი | AK6: გეგმა | AL6: გეგმა | AR6: გეგმა | AS6: გეგმა
B7: ჯორჯია გაზ პროჯექტი | C7: 5180000 | D7: 265000 | E7: 4915000 | F7: 5571188 | G7: =K7+M7+O7+Q7+S7+U7+W7+Y7+AA7+AC7+AE7+AG7 -> 4808084.6 | H7: =F7-E7 -> 656188 | I7: =F7-G7 -> 763103.37 | J7: 930000 | K7: ='GeoGazProj (SGG)'!AT7 -> 930000 | L7: 705000 | M7: ='GeoGazProj (SGG)'!AZ7 -> 600000 | N7: 469188 | O7: ='GeoGazProj (SGG)'!BG7 -> 470000 | P7: 993500 | Q7: ='GeoGazProj (SGG)'!BN7 -> 422978.12 | R7: 1324500 | S7: ='GeoGazProj (SGG)'!BU7 -> 500000 | T7: 906000 | U7: ='GeoGazProj (SGG)'!CB7 -> 400000 | V7: 243000 | W7: ='GeoGazProj (SGG)'!CI7 -> 295000 | X7: 0 | Y7: ='GeoGazProj (SGG)'!CO7 -> 283134.29 | Z7: 0 | AA7: ='GeoGazProj (SGG)'!CU7 -> 100000 | AB7: 0 | AC7: ='GeoGazProj (SGG)'!DA7 -> 356972.22 | AD7: 0 | AE7: ='GeoGazProj (SGG)'!DG7 -> 450000 | AF7: 0 | AG7: ='GeoGazProj (SGG)'!DM7 -> 0 | AH7: 4915000 | AI7: =K7+M7+O7+Q7+S7+U7+W7+Y7+AA7+AC7+AE7+AG7 -> 4808084.6 | AK7: 700000 | AL7: 513103.37 | AR7: 300000 | AS7: 150000
B8: ბრიჯი | C8: 4641418 | D8: 2491418 | E8: 2150000 | F8: 3150000 | G8: =K8+M8+O8+Q8+S8+U8+W8+Y8+AA8+AC8+AE8+AG8 -> 2702662.8 | H8: =F8-E8 -> 1000000 | I8: =F8-G8 -> 447337.22 | J8: 600000 | K8: ='ბრიჯი SGG'!AQ7 -> 600000 | L8: 450000 | M8: ='ბრიჯი SGG'!AW7 -> 450000 | N8: 450000 | O8: ='ბრიჯი SGG'!BD7 -> 453425 | P8: 650000 | Q8: ='ბრიჯი SGG'!BK7 -> 552393.78 | R8: 0 | S8: ='ბრიჯი SGG'!BQ7 -> 3000 | T8: 0 | U8: ='ბრიჯი SGG'!BW7 -> 11100 | V8: 0 | W8: ='ბრიჯი SGG'!CC7 -> 30754 | X8: 0 | Y8: ='ბრიჯი SGG'!CI7 -> 280000 | Z8: 0 | AA8: ='ბრიჯი SGG'!CO7 -> 310490 | AB8: 0 | AC8: ='ბრიჯი SGG'!CU7 -> 11500 | AD8: 0 | AE8: ='ბრიჯი SGG'!DA7 -> 0 | AF8: 0 | AG8: ='ბრიჯი SGG'!DG7 -> 0 | AH8: 2150000 | AI8: =K8+M8+O8+Q8+S8+U8+W8+Y8+AA8+AC8+AE8+AG8 -> 2702662.8 | AK8: 0 | AL8: 447337 | AR8: 500000 | AS8: 300000
B9: არქმშენსერვისი | C9: 9745862.9 | D9: 6495862.9 | E9: 3250000 | F9: 5965000 | G9: =K9+M9+O9+Q9+S9+U9+W9+Y9+AA9+AC9+AE9+AG9 -> 2971405.6 | H9: =F9-E9 -> 2715000 | I9: =F9-G9 -> 2993594.4 | J9: 500000 | K9: ='არქმშენსერვისი SGG'!AS7 -> 500000 | L9: 1365000 | M9: ='არქმშენსერვისი SGG'!AY7 -> 1360000 | N9: 960000 | O9: ='არქმშენსერვისი SGG'!BF7 -> 960000 | P9: 890000 | Q9: ='არქმშენსერვისი SGG'!BM7 -> 151405.57 | R9: 750000 | S9: ='არქმშენსერვისი SGG'!BT7 -> 0 | T9: 750000 | U9: ='არქმშენსერვისი SGG'!CA7 -> 0 | V9: 750000 | W9: ='არქმშენსერვისი SGG'!CH7 -> 0 | X9: 0 | Y9: ='არქმშენსერვისი SGG'!CN7 -> 0 | Z9: 0 | AA9: ='არქმშენსერვისი SGG'!CT7 -> 0 | AB9: 0 | AC9: ='არქმშენსერვისი SGG'!CZ7 -> 0 | AD9: 0 | AE9: ='არქმშენსერვისი SGG'!DF7 -> 0 | AF9: 0 | AG9: ='არქმშენსერვისი SGG'!DL7 -> 0 | AH9: 3250000 | AI9: =K9+M9+O9+Q9+S9+U9+W9+Y9+AA9+AC9+AE9+AG9 -> 2971405.6 | AK9: 1000000 | AL9: 1000000 | AR9: 1000000 | AS9: 500000
B10: უნიმშენი | C10: 8805000 | D10: 3290000 | E10: 5515000 | F10: 4912827 | G10: =K10+M10+O10+Q10+S10+U10+W10+Y10+AA10+AC10+AE10+AG10 -> 4418016 | H10: =F10-E10 -> -602173 | I10: =F10-G10 -> 494811 | J10: 1265000 | K10: ='უნიმშენი SGG'!AQ7 -> 1037000 | L10: 650000 | M10: ='უნიმშენი SGG'!AW7 -> 1090000 | N10: 653688 | O10: ='უნიმშენი SGG'!BD7 -> 650000 | P10: 822638 | Q10: ='უნიმშენი SGG'!BK7 -> 731525 | R10: 566192 | S10: ='უნიმშენი SGG'!BR7 -> 411102 | T10: 300000 | U10: ='უნიმშენი SGG'!BY7 -> 300000 | V10: 124544 | W10: ='უნიმშენი SGG'!CF7 -> 0 | X10: 0 | Y10: ='უნიმშენი SGG'!CM7 -> 0 | Z10: 0 | AA10: ='უნიმშენი SGG'!CT7 -> 48389 | AB10: 150000 | AC10: ='უნიმშენი SGG'!DA7 -> 150000 | AD10: 180765 | AE10: ='უნიმშენი SGG'!DH7 -> 0 | AF10: 0 | AG10: ='უნიმშენი SGG'!DO7 -> 0 | AH10: 5515000 | AI10: =K10+M10+O10+Q10+S10+U10+W10+Y10+AA10+AC10+AE10+AG10 -> 4418016 | AK10: 294811 | AL10: 200000 | AR10: 350000 | AS10: 200000
B11: ინტერსერვისი 2011 | C11: 5455790 | D11: 3263716.2 | E11: 2192073.8 | F11: 2540463.8 | G11: =K11+M11+O11+Q11+S11+U11+W11+Y11+AA11+AC11+AE11+AG11 -> 2339837.6 | H11: =F11-E11 -> 348390 | I11: =F11-G11 -> 200626.17 | J11: 329173.75 | K11: ='ინტერსერვისი SGG'!AQ7 -> 321141.43 | L11: 401300 | M11: ='ინტერსერვისი SGG'!AW7 -> 481548.11 | N11: 582600 | O11: ='ინტერსერვისი SGG'!BD7 -> 582600 | P11: 357418 | Q11: ='ინტერსერვისი SGG'!BK7 -> 349048.62 | R11: 310372 | S11: ='ინტერსერვისი SGG'!BR7 -> 310000 | T11: 139600 | U11: ='ინტერსერვისი SGG'!BY7 -> 105000 | V11: 0 | W11: ='ინტერსერვისი SGG'!CE7 -> 0 | X11: 0 | Y11: ='ინტერსერვისი SGG'!CK7 -> 2000 | Z11: 0 | AA11: ='ინტერსერვისი SGG'!CQ7 -> 5000 | AB11: 0 | AC11: ='ინტერსერვისი SGG'!CW7 -> 5000 | AD11: 0 | AE11: ='ინტერსერვისი SGG'!DC7 -> 178499.42 | AF11: 0 | AG11: ='ინტერსერვისი SGG'!DI7 -> 0 | AH11: 2192073.8 | AI11: =K11+M11+O11+Q11+S11+U11+W11+Y11+AA11+AC11+AE11+AG11 -> 2339837.6 | AK11: 149125.59 | AL11: 230000 | AR11: 450000 | AS11: 300000
B12: გაზსერვისი | C12: 2241000 | D12: 850000 | E12: =1391000 -> 1391000 | F12: 2337302.8 | G12: =K12+M12+O12+Q12+S12+U12+W12+Y12+AA12+AC12+AE12+AG12 -> 1838896.2 | H12: =F12-E12 -> 946302.77 | I12: =F12-G12 -> 498406.55 | J12: 250000 | K12: ='გაზსერვისი SGG'!AS7 -> 250000 | L12: 1227302.8 | M12: ='გაზსერვისი SGG'!AY7 -> 1227302.8 | N12: 160000 | O12: ='გაზსერვისი SGG'!BF7 -> 160172.27 | P12: 0 | Q12: ='გაზსერვისი SGG'!BM7 -> 0 | R12: 0 | S12: ='გაზსერვისი SGG'!BS7 -> 0 | T12: 100000 | U12: ='გაზსერვისი SGG'!BY7 -> 0 | V12: 0 | W12: ='გაზსერვისი SGG'!CE7 -> 201421.18 | X12: 0 | Y12: ='გაზსერვისი SGG'!CK7 -> 0 | Z12: 0 | AA12: ='გაზსერვისი SGG'!CQ7 -> 0 | AB12: 0 | AC12: ='გაზსერვისი SGG'!CW7 -> 0 | AD12: 0 | AE12: ='გაზსერვისი SGG'!DC7 -> 0 | AF12: 0 | AG12: ='გაზსერვისი SGG'!DI7 -> 0 | AH12: 1694000 | AI12: =K12+M12+O12+Q12+S12+U12+W12+Y12+AA12+AC12+AE12+AG12 -> 1838896.2 | AK12: 500000 | AL12: 0 | AR12: 1000000 | AS12: 350000
B13: არქიტექტ პროჯექტ კომპანი | C13: 0 | D13: 0 | E13: 0 | F13: 120000 | G13: =K13+M13+O13+Q13+S13+U13+W13+Y13+AA13+AC13+AE13+AG13 -> 0 | H13: =F13-E13 -> 120000 | I13: =F13-G13 -> 120000 | J13: 0 | K13: ='გაზსერვისი SGG'!AS8 -> 0 | L13: 0 | M13: ='გაზსერვისი SGG'!AY8 -> 0 | N13: 120000 | O13: ='გაზსერვისი SGG'!BF8 -> 0 | P13: 0 | Q13: ='გაზსერვისი SGG'!BM8 -> 0 | R13: 0 | S13: ='გაზსერვისი SGG'!BS8 -> 0 | T13: 0 | U13: ='გაზსერვისი SGG'!BY8 -> 0 | V13: 0 | W13: ='გაზსერვისი SGG'!CE8 -> 0 | X13: 0 | Y13: ='გაზსერვისი SGG'!CK8 -> 0 | Z13: 0 | AA13: ='გაზსერვისი SGG'!CQ8 -> 0 | AB13: 0 | AC13: ='გაზსერვისი SGG'!CW8 -> 0 | AD13: 0 | AE13: ='გაზსერვისი SGG'!DC8 -> 0 | AF13: 0 | AG13: ='გაზსერვისი SGG'!DI8 -> 0 | AH13: 0 | AI13: =K13+M13+O13+Q13+S13+U13+W13+Y13+AA13+AC13+AE13+AG13 -> 0 | AK13: 0 | AL13: 120000 | AR13: 0 | AS13: 0
B14: ჯი პი + ჰაიდროკორპი | F14: 0 | AK14: 0 | AL14: 0 | AR14: 0 | AS14: 0
B15: ინტერგაზი | C15: 13206051 | D15: 9606050.8 | E15: 3600000 | F15: 4390000 | G15: =K15+M15+O15+Q15+S15+U15+W15+Y15+AA15+AC15+AE15+AG15 -> 5111920.6 | H15: =F15-E15 -> 790000 | I15: =F15-G15 -> -721920.58 | J15: 1200000 | K15: ='ინტერგაზი SGG'!AS7 -> 1200000 | L15: 500000 | M15: ='ინტერგაზი SGG'!AY7 -> 1160000 | N15: 1570000 | O15: ='ინტერგაზი SGG'!BF7 -> 1500000 | P15: 770000 | Q15: ='ინტერგაზი SGG'!BM7 -> 0 | R15: 0 | S15: ='ინტერგაზი SGG'!BT7 -> 300000 | T15: 0 | U15: ='ინტერგაზი SGG'!BZ7 -> 550000 | V15: 0 | W15: ='ინტერგაზი SGG'!CF7 -> 0 | X15: 0 | Y15: ='ინტერგაზი SGG'!CL7 -> 401920.58 | Z15: 0 | AA15: ='ინტერგაზი SGG'!CR7 -> 0 | AB15: 0 | AC15: ='ინტერგაზი SGG'!CX7 -> 0 | AD15: 0 | AE15: ='ინტერგაზი SGG'!DD7 -> 0 | AF15: 0 | AG15: ='ინტერგაზი SGG'!DJ7 -> 0 | AH15: 3600000 | AI15: =K15+M15+O15+Q15+S15+U15+W15+Y15+AA15+AC15+AE15+AG15 -> 5111920.6 | AK15: 0 | AL15: 350000 | AR15: 1000000 | AS15: 300000
B16: გაზკონსტრაქტი | C16: 16581886 | D16: 8624668.4 | E16: 7957217.8 | F16: 8109146.8 | G16: =K16+M16+O16+Q16+S16+U16+W16+Y16+AA16+AC16+AE16+AG16 -> 8066078.9 | H16: =F16-E16 -> 151929.1 | I16: =F16-G16 -> 43067.948 | J16: 1860217.8 | K16: ='გაზკონსტრაქტი SGG'!AT7 -> 1858820 | L16: 1507000 | M16: ='გაზკონსტრაქტი SGG'!AZ7 -> 1505000 | N16: 524273.1 | O16: ='გაზკონსტრაქტი SGG'!BG7 -> 529191.64 | P16: 1325619 | Q16: ='გაზკონსტრაქტი SGG'!BN7 -> 1329383.7 | R16: 1116370 | S16: ='გაზკონსტრაქტი SGG'!BU7 -> 1000313.2 | T16: 535667 | U16: ='გაზკონსტრაქტი SGG'!CB7 -> 206327.51 | V16: 440000 | W16: ='გაზკონსტრაქტი SGG'!CI7 -> 837335.43 | X16: 350000 | Y16: ='გაზკონსტრაქტი SGG'!CP7 -> 29114.88 | Z16: 300000 | AA16: ='გაზკონსტრაქტი SGG'!CW7 -> 0 | AB16: 0 | AC16: ='გაზკონსტრაქტი SGG'!DC7 -> 448228.72 | AD16: 0 | AE16: ='გაზკონსტრაქტი SGG'!DI7 -> 322363.82 | AF16: 0 | AG16: ='გაზკონსტრაქტი SGG'!DO7 -> 0 | AH16: 7957217.8 | AI16: =K16+M16+O16+Q16+S16+U16+W16+Y16+AA16+AC16+AE16+AG16 -> 8066078.9 | AK16: 360000 | AL16: 0 | AR16: 1300000 | AS16: 500000
B17: ენერჯი სერვისი | C17: 3152200 | D17: 25500 | E17: 3126700 | F17: 3119200 | G17: =K17+M17+O17+Q17+S17+U17+W17+Y17+AA17+AC17+AE17+AG17 -> 3180587.7 | H17: =F17-E17 -> -7500 | I17: =F17-G17 -> -61387.74 | J17: 376700 | K17: ='ენერჯი სერვისი SGG'!AQ7 -> 376700 | L17: 250000 | M17: ='ენერჯი სერვისი SGG'!AW7 -> 257500 | N17: =250000-7500 -> 242500 | O17: ='ენერჯი სერვისი SGG'!BC7 -> 245500 | P17: 250000 | Q17: ='ენერჯი სერვისი SGG'!BI7 -> 258500 | R17: 250000 | S17: ='ენერჯი სერვისი SGG'!BO7 -> 269972.1 | T17: 250000 | U17: ='ენერჯი სერვისი SGG'!BU7 -> 257084.6 | V17: 250000 | W17: ='ენერჯი სერვისი SGG'!CA7 -> 185000 | X17: 250000 | Y17: ='ენერჯი სერვისი SGG'!CG7 -> 120276.23 | Z17: 250000 | AA17: ='ენერჯი სერვისი SGG'!CM7 -> 413196.81 | AB17: 250000 | AC17: ='ენერჯი სერვისი SGG'!CS7 -> 216000 | AD17: 250000 | AE17: ='ენერჯი სერვისი SGG'!CY7 -> 580858 | AF17: 250000 | AG17: ='ენერჯი სერვისი SGG'!DE7 -> 0 | AH17: 3126700 | AI17: =K17+M17+O17+Q17+S17+U17+W17+Y17+AA17+AC17+AE17+AG17 -> 3180587.7 | AK17: 250000 | AL17: 250000 | AR17: 250000 | AS17: 250000
B20: SOG | C20: =SUM(C25:C36) -> 46842061 | D20: =SUM(D25:D36) -> 21796004 | E20: =SUM(E25:E36) -> 25046058 | F20: =SUM(F25:F36) -> 33975472 | G20: =SUM(G25:G36) -> 23546132 | H20: =SUM(H25:H36) -> 8929414.4 | I20: =SUM(I25:I36) -> 10429340 | J20: =SUM(J25:J36) -> 9558807.6 | ... AI20: =SUM(AI25:AI36) -> 23546132 | AK20: =SUM(AK25:AK35) -> 2415000 | AL20: =SUM(AL25:AL35) -> 5831000 | AN20: =AH20+AK20+AL20 -> 35052058 | AO20: ჯამი ფაქტი+პროგნოზი | AR20: =SUM(AR25:AR35) -> 6950000 | AS20: =SUM(AS25:AS35) -> 1950000
B21: კონტრაქტორი | C21: ობიექტის საპროგნოზო ღირებულება | D21: შუალედური ჩაბარებები 22-24 წწ. | E21: 2025 წლის გეგმა | F21: 2025 წლის გეგმა განახლებული | G21: 2025 წლის ფაქტი | H21: გეგმის ზრდა | I21: გეგმიდან დარჩა ჩასაბარებელი | AK21: დარჩა ჩასაბარებელი | AN21: ნოემბრამდე+დარჩენილი 2 თვე | AR21: 2026
J22: იანვარი 2025 | L22: თებერვალი 2025 | N22: მარტი 2025 | P22: აპრილი 2025 | R22: მაისი 2025 | T22: ივნისი 2025 | V22: ივლისი 2025 | X22: აგვისტო 2025 | Z22: სექტემბერი 2025 | AB22: ოქტომბერი 2025 | AD22: ნოემბერი 2025 | AF22: დეკემბერი 2025 | AH22: სულ 2025 წელი
J23: სულ | L23: სულ | N23: სულ | P23: სულ | R23: სულ | T23: სულ | V23: სულ | X23: სულ | Z23: სულ | AB23: სულ | AD23: სულ | AF23: სულ | AH23: სულ | AK23: ნოემბერი | AL23: დეკემბერი | AR23: იანვარი | AS23: თებერვალი
J24: გეგმა | K24: ფაქტი | L24: გეგმა | M24: ფაქტი | N24: გეგმა | O24: ფაქტი | P24: გეგმა | Q24: ფაქტი | R24: გეგმა | S24: ფაქტი | T24: გეგმა | U24: ფაქტი | V24: გეგმა | W24: ფაქტი | X24: გეგმა | Y24: ფაქტი | Z24: გეგმა | AA24: ფაქტი | AB24: გეგმა | AC24: ფაქტი | AD24: გეგმა | AE24: ფაქტი | AF24: გეგმა | AG24: ფაქტი | AH24: კორექტ. გეგმა | AI24: ფაქტი | AK24: გეგმა | AL24: გეგმა | AR24: გეგმა | AS24: გეგმა
B25: ჯორჯია გაზ პროჯექტი | C25: 1963780.2 | D25: 1441780.2 | E25: 522000 | F25: 576000 | G25: =K25+M25+O25+Q25+S25+U25+W25+Y25+AA25+AC25+AE25+AG25 -> 470439 | H25: =F25-E25 -> 54000 | I25: =F25-G25 -> 105561 | J25: 150000 | K25: ='GeoGazProj (SOG)'!AQ7 -> 100000 | L25: 0 | M25: ='GeoGazProj (SOG)'!AW7 -> 76000 | N25: 90000 | O25: ='GeoGazProj (SOG)'!BD7 -> 44000 | P25: 80000 | Q25: ='GeoGazProj (SOG)'!BK7 -> 0 | R25: 200000 | S25: ='GeoGazProj (SOG)'!BR7 -> 0 | T25: 56000 | U25: ='GeoGazProj (SOG)'!BY7 -> 0 | V25: 0 | W25: ='GeoGazProj (SOG)'!CE7 -> 70000 | X25: 0 | Y25: ='GeoGazProj (SOG)'!CK7 -> 0 | Z25: 0 | AA25: ='GeoGazProj (SOG)'!CQ7 -> 55000 | AB25: 0 | AC25: ='GeoGazProj (SOG)'!CW7 -> 0 | AD25: 0 | AE25: ='GeoGazProj (SOG)'!DC7 -> 125439 | AF25: 0 | AG25: ='GeoGazProj (SOG)'!DI7 -> 0 | AH25: 522000 | AI25: =K25+M25+O25+Q25+S25+U25+W25+Y25+AA25+AC25+AE25+AG25 -> 470439 | AK25: 0 | AL25: 231000 | AR25: 250000 | AS25: 0
B26: ბრიჯი | C26: 0 | D26: 0 | E26: 0 | F26: 0 | G26: =K26+M26+O26+Q26+S26+U26+W26+Y26+AA26+AC26+AE26+AG26 -> 0 | H26: =F26-E26 -> 0 | I26: =F26-G26 -> 0 | J26: 0 | K26: ='ბრიჯი SOG'!AQ7 -> 0 | L26: 0 | M26: ='ბრიჯი SOG'!AS7 -> 0 | N26: 0 | O26: ='ბრიჯი SOG'!AU7 -> 0 | P26: 0 | Q26: ='ბრიჯი SOG'!AW7 -> 0 | R26: 0 | S26: ='ბრიჯი SOG'!AY7 -> 0 | T26: 0 | U26: ='ბრიჯი SOG'!BA7 -> 0 | V26: 0 | W26: ='ბრიჯი SOG'!BC7 -> 0 | X26: 0 | Y26: ='ბრიჯი SOG'!BE7 -> 0 | Z26: 0 | AA26: ='ბრიჯი SOG'!BG7 -> 0 | AB26: 0 | AC26: ='ბრიჯი SOG'!BI7 -> 0 | AD26: 0 | AE26: ='ბრიჯი SOG'!BK7 -> 0 | AF26: 0 | AG26: ='ბრიჯი SOG'!BM7 -> 0 | AH26: 0 | AI26: =K26+M26+O26+Q26+S26+U26+W26+Y26+AA26+AC26+AE26+AG26 -> 0 | AK26: 0 | AL26: 0 | AR26: 0 | AS26: 0
B27: არქმშენსერვისი | C27: 2000000 | D27: 0 | E27: 2000000 | F27: 4000000 | G27: =K27+M27+O27+Q27+S27+U27+W27+Y27+AA27+AC27+AE27+AG27 -> 0 | H27: =F27-E27 -> 2000000 | I27: =F27-G27 -> 4000000 | J27: 0 | K27: ='არქმშენსერვისი SOG'!AS7 -> 0 | L27: 500000 | M27: ='არქმშენსერვისი SOG'!AY7 -> 0 | N27: =500000+200000 -> 700000 | O27: ='არქმშენსერვისი SOG'!BF7 -> 0 | P27: =500000+150000 -> 650000 | Q27: ='არქმშენსერვისი SOG'!BM7 -> 0 | R27: =500000+100000 -> 600000 | S27: ='არქმშენსერვისი SOG'!BT7 -> 0 | T27: =500000+50000 -> 550000 | U27: ='არქმშენსერვისი SOG'!CA7 -> 0 | V27: 500000 | W27: ='არქმშენსერვისი SOG'!CG7 -> 0 | X27: 500000 | Y27: ='არქმშენსერვისი SOG'!CM7 -> 0 | Z27: 0 | AA27: ='არქმშენსერვისი SOG'!CS7 -> 0 | AB27: 0 | AC27: ='არქმშენსერვისი SOG'!CY7 -> 0 | AD27: 0 | AE27: ='არქმშენსერვისი SOG'!DE7 -> 0 | AF27: 0 | AG27: ='არქმშენსერვისი SOG'!DK7 -> 0 | AH27: 3500000 | AI27: =K27+M27+O27+Q27+S27+U27+W27+Y27+AA27+AC27+AE27+AG27 -> 0 | AK27: 0 | AL27: 2000000 | AR27: 1500000 | AS27: 500000
B28: უნიმშენი | F28: 0 | AK28: 0 | AL28: 0 | AR28: 0 | AS28: 0
B29: ინტერსერვისი 2011 | C29: 3989235.2 | D29: 2855522.7 | E29: 1133712.5 | F29: 1794067.5 | G29: =K29+M29+O29+Q29+S29+U29+W29+Y29+AA29+AC29+AE29+AG29 -> 1144017.3 | H29: =F29-E29 -> 660355 | I29: =F29-G29 -> 650050.15 | J29: 713212.5 | K29: ='ინტერსერვისი SOG'!AQ7 -> 713000 | L29: 297500 | M29: ='ინტერსერვისი SOG'!AW7 -> 297000 | N29: 95355 | O29: ='ინტერსერვისი SOG'!BD7 -> 83764.14 | P29: 28000 | Q29: ='ინტერსერვისი SOG'!BK7 -> 49635.65 | R29: 0 | S29: ='ინტერსერვისი SOG'!BQ7 -> 0 | T29: 0 | U29: ='ინტერსერვისი SOG'!BW7 -> 617.56 | V29: 0 | W29: ='ინტერსერვისი SOG'!CC7 -> 0 | X29: 0 | Y29: ='ინტერსერვისი SOG'!CI7 -> 0 | Z29: 0 | AA29: ='ინტერსერვისი SOG'!CO7 -> 0 | AB29: 0 | AC29: ='ინტერსერვისი SOG'!CU7 -> 0 | AD29: 0 | AE29: ='ინტერსერვისი SOG'!DA7 -> 0 | AF29: 0 | AG29: ='ინტერსერვისი SOG'!DG7 -> 0 | AH29: 1133712.5 | AI29: =K29+M29+O29+Q29+S29+U29+W29+Y29+AA29+AC29+AE29+AG29 -> 1144017.3 | AK29: 300000 | AL29: 350000 | AR29: 300000 | AS29: 250000
B30: გაზსერვისი | C30: 6837995.9 | D30: 2051745.9 | E30: =4786250 -> 4786250 | F30: 7450750 | G30: =K30+M30+O30+Q30+S30+U30+W30+Y30+AA30+AC30+AE30+AG30 -> 5446834 | H30: =F30-E30 -> 2664500 | I30: =F30-G30 -> 2003916 | J30: 2552500 | K30: ='გაზსერვისი SOG'!AR7 -> 2548000 | L30: 783804.51 | M30: ='გაზსერვისი SOG'!AX7 -> 783804.51 | N30: 1000000 | O30: ='გაზსერვისი SOG'!BE7 -> 1000000 | P30: 314445.49 | Q30: ='გაზსერვისი SOG'!BL7 -> 423976.54 | R30: =410000+N("P.6.602 ქვიტირი")+90000+N("P.6.608 ქუთაისი 26 მაისის ქ.") -> 500000 | S30: ='გაზსერვისი SOG'!BR7 -> 528855.93 | T30: 0 | U30: ='გაზსერვისი SOG'!BX7 -> 0 | V30: 0 | W30: ='გაზსერვისი SOG'!CD7 -> 0 | X30: 0 | Y30: ='გაზსერვისი SOG'!CJ7 -> 0 | Z30: 0 | AA30: ='გაზსერვისი SOG'!CP7 -> 0 | AB30: 0 | AC30: ='გაზსერვისი SOG'!CV7 -> 162197 | AD30: 0 | AE30: ='გაზსერვისი SOG'!DB7 -> 0 | AF30: 0 | AG30: ='გაზსერვისი SOG'!DH7 -> 0 | AH30: 5046250 | AI30: =K30+M30+O30+Q30+S30+U30+W30+Y30+AA30+AC30+AE30+AG30 -> 5446834 | AK30: 500000 | AL30: 1500000 | AR30: 750000 | AS30: 300000
B31: არქიტექტ პროჯექტ კომპანი | F31: 350000 | H31: =F31-E31 -> 350000 | I31: =F31-G31 -> 350000 | AK31: 350000 | AL31: 0 | AR31: 0 | AS31: 0
B32: ჯი პი | F32: 15000 | H32: =F32-E32 -> 15000 | I32: =F32-G32 -> 15000 | AK32: 15000 | AL32: 0 | AR32: 0 | AS32: 0
B33: ინტერგაზი | C33: 24379200 | D33: 14109200 | E33: 10270000 | F33: 11196800 | G33: =K33+M33+O33+Q33+S33+U33+W33+Y33+AA33+AC33+AE33+AG33 -> 9917716.3 | H33: =F33-E33 -> 926800 | I33: =F33-G33 -> 1279083.7 | J33: 4870000 | K33: ='ინტერგაზი SOG'!AS7 -> 4594000 | L33: 1300000 | M33: ='ინტერგაზი SOG'!AY7 -> 1330000 | N33: 1538800 | O33: ='ინტერგაზი SOG'!BF7 -> 1112004.1 | P33: 618000 | Q33: ='ინტერგაზი SOG'!BM7 -> 21643 | R33: 500000 | S33: ='ინტერგაზი SOG'!BT7 -> 1500000 | T33: 500000 | U33: ='ინტერგაზი SOG'!CA7 -> 0 | V33: 500000 | W33: ='ინტერგაზი SOG'!CH7 -> 0 | X33: 500000 | Y33: ='ინტერგაზი SOG'!CO7 -> 700000 | Z33: 370000 | AA33: ='ინტერგაზი SOG'!CV7 -> 660069.27 | AB33: 0 | AC33: ='ინტერგაზი SOG'!DB7 -> 0 | AD33: 0 | AE33: ='ინტერგაზი SOG'!DH7 -> 0 | AF33: 0 | AG33: ='ინტერგაზი SOG'!DN7 -> 0 | AH33: 10270000 | AI33: =K33+M33+O33+Q33+S33+U33+W33+Y33+AA33+AC33+AE33+AG33 -> 9917716.3 | AK33: 0 | AL33: 500000 | AR33: 500000 | AS33: 300000
B34: გაზკონსტრაქტი | C34: 4894849.9 | D34: 1310754.8 | E34: 3584095.1 | F34: 5847654.5 | G34: =K34+M34+O34+Q34+S34+U34+W34+Y34+AA34+AC34+AE34+AG34 -> 4072687.8 | H34: =F34-E34 -> 2263559.4 | I34: =F34-G34 -> 1774966.7 | J34: 1273095.1 | K34: ='გაზკონსტრაქტი SOG'!AT7 -> 1260453.6 | L34: 1586000 | M34: ='გაზკონსტრაქტი SOG'!AZ7 -> 1584000 | N34: 294770.42 | O34: ='გაზკონსტრაქტი SOG'!BG7 -> 329885.77 | P34: 95560 | Q34: ='გაზკონსტრაქტი SOG'!BN7 -> 46181.63 | R34: 234400 | S34: ='გაზკონსტრაქტი SOG'!BU7 -> 351688.75 | T34: 113829 | U34: ='გაზკონსტრაქტი SOG'!CB7 -> 23406.07 | V34: 0 | W34: ='გაზკონსტრაქტი SOG'!CH7 -> 127148.8 | X34: 0 | Y34: ='გაზკონსტრაქტი SOG'!CN7 -> 63625.36 | Z34: 0 | AA34: ='გაზკონსტრაქტი SOG'!CT7 -> 18366.72 | AB34: 0 | AC34: ='გაზკონსტრაქტი SOG'!CZ7 -> 18207.93 | AD34: 0 | AE34: ='გაზკონსტრაქტი SOG'!DF7 -> 249723.24 | AF34: 0 | AG34: ='გაზკონსტრაქტი SOG'!DL7 -> 0 | AH34: 3584095.1 | AI34: =K34+M34+O34+Q34+S34+U34+W34+Y34+AA34+AC34+AE34+AG34 -> 4072687.8 | AK34: 1000000 | AL34: 1000000 | AR34: 3400000 | AS34: 350000
B35: ენერჯი სერვისი | C35: 2777000 | D35: 27000 | E35: 2750000 | F35: 2745200 | G35: =K35+M35+O35+Q35+S35+U35+W35+Y35+AA35+AC35+AE35+AG35 -> 2494437.8 | H35: =F35-E35 -> -4800 | I35: =F35-G35 -> 250762.19 | J35: 0 | K35: ='ენერჯი სერვისი SOG'!AQ7 -> 0 | L35: 250000 | M35: ='ენერჯი სერვისი SOG'!AW7 -> 254800 | N35: =250000-4800 -> 245200 | O35: ='ენერჯი სერვისი SOG'!BC7 -> 256200 | P35: 250000 | Q35: ='ენერჯი სერვისი SOG'!BI7 -> 256500 | R35: 250000 | S35: ='ენერჯი სერვისი SOG'!BO7 -> 249192.68 | T35: 250000 | U35: ='ენერჯი სერვისი SOG'!BU7 -> 308546.63 | V35: 250000 | W35: ='ენერჯი სერვისი SOG'!CA7 -> 385897.4 | X35: 250000 | Y35: ='ენერჯი სერვისი SOG'!CG7 -> 385604.1 | Z35: 250000 | AA35: ='ენერჯი სერვისი SOG'!CM7 -> 45000 | AB35: 250000 | AC35: ='ენერჯი სერვისი SOG'!CS7 -> 285000 | AD35: 250000 | AE35: ='ენერჯი სერვისი SOG'!CY7 -> 67697 | AF35: 250000 | AG35: ='ენერჯი სერვისი SOG'!DE7 -> 0 | AH35: 2750000 | AI35: =K35+M35+O35+Q35+S35+U35+W35+Y35+AA35+AC35+AE35+AG35 -> 2494437.8 | AK35: 250000 | AL35: 250000 | AR35: 250000 | AS35: 250000
F36: 0 | G36: =K36+M36+O36+Q36+S36+U36+W36+Y36+AA36+AC36+AE36+AG36 -> 0 | I36: =F36-G36 -> 0
B37: გაგზავნილი ციფრები (6 ნოე 2025) | C37: 1.1585127e+08 | D37: 56708220 | E37: 59143049 | F37: 74190600 | G37: 57264042 | H37: 15047551 | I37: 16561559
B38: SGG + SOG | C38: =SUM(C43:C54) -> 1.1585127e+08 | D38: =SUM(D43:D54) -> 56708220 | E38: =SUM(E43:E54) -> 59143049 | F38: =SUM(F43:F54) -> 74190600 | G38: =SUM(G43:G54) -> 58983622 | H38: =SUM(H43:H54) -> 15047551 | I38: =SUM(I43:I54) -> 15206978 | J38: =SUM(J43:J54) -> 16869899 | ... AI38: =SUM(AI43:AI54) -> 58983622 | AK38: =SUM(AK43:AK53) -> 5668936.6 | AL38: =SUM(AL43:AL53) -> 8941440.4 | AM38: =AL38-AK38 -> 3272503.8 | AN38: =AH38+AK38+AL38 -> 80005977 | AO38: ჯამი ფაქტი+პროგნოზი | AR38: =SUM(AR43:AR53) -> 13100000 | AS38: =SUM(AS43:AS53) -> 4800000
B39: კონტრაქტორი | C39: ობიექტის საპროგნოზო ღირებულება | D39: შუალედური ჩაბარებები 22-24 წწ. | E39: 2025 წლის გეგმა | F39: 2025 წლის გეგმა განახლებული | G39: 2025 წლის ფაქტი | H39: გეგმის ზრდა | I39: გეგმიდან დარჩა ჩასაბარებელი | AK39: დარჩა ჩასაბარებელი | AN39: ნოემბრამდე+დარჩენილი 2 თვე | AR39: 2026
J40: იანვარი 2025 | L40: თებერვალი 2025 | N40: მარტი 2025 | P40: აპრილი 2025 | R40: მაისი 2025 | T40: ივნისი 2025 | V40: ივლისი 2025 | X40: აგვისტო 2025 | Z40: სექტემბერი 2025 | AB40: ოქტომბერი 2025 | AD40: ნოემბერი 2025 | AF40: დეკემბერი 2025 | AH40: სულ 2025 წელი
J41: სულ | L41: სულ | N41: სულ | P41: სულ | R41: სულ | T41: სულ | V41: სულ | X41: სულ | Z41: სულ | AB41: სულ | AD41: სულ | AF41: სულ | AH41: სულ | AK41: ნოემბერი | AL41: დეკემბერი | AR41: იანვარი | AS41: თებერვალი
J42: გეგმა | K42: ფაქტი | L42: გეგმა | M42: ფაქტი | N42: გეგმა | O42: ფაქტი | P42: გეგმა | Q42: ფაქტი | R42: გეგმა | S42: ფაქტი | T42: გეგმა | U42: ფაქტი | V42: გეგმა | W42: ფაქტი | X42: გეგმა | Y42: ფაქტი | Z42: გეგმა | AA42: ფაქტი | AB42: გეგმა | AC42: ფაქტი | AD42: გეგმა | AE42: ფაქტი | AF42: გეგმა | AG42: ფაქტი | AH42: კორექტ. გეგმა | AI42: ფაქტი | AK42: გეგმა | AL42: გეგმა | AR42: გეგმა | AS42: გეგმა
...

Sheet ინტერსერვისი SGG
B1: ინტერსერვისი SGG | F1: 7975074 | G1: 14972276 | BC1: =BC2-BC7 -> 0
F2: =F1-F7 -> 4614610.2 | G2: =G1-G7 -> 4904435.4 | AQ2: =AP7-AQ7 -> 8032.32 | AW2: =AW7-AV7 -> 80248.11 | BC2: 582600 | BJ2: 357784.21 | BX2: 139000
A3: № | B3: ქალაქი, მუნიციპალიტეტი | C3: სემეკის კოდი (P) | D3: სამშენებლო ობიექტის დასახელება | E3: პროექტირება/ მშენებლობა | F3: გეგმა 2025 | G3: ობიექტის საპროგნოზო ღირებულება | H3: ობიექტის ღირებულება სემეკის მიერ დამტკიცებული საინვესტიციო გეგმის მიხედვით | I3: 31.12.23-მდე | K3: 2024 წელი | M3: სულ ჩაბარდა დღემდე | O3: ობიექტის საბოლოო ღირებულება | P3: 01.01.24 -დან 01.11.24 - მდე პერიოდში | R3: სულ 01.11.24-მდე | T3: 2024 წელი | AL3: 2025
N4: დარჩა ჩასაბარებელი | T4: ნოემბერი 2024 | Z4: დეკემბერი 2024 | AF4: 2024 წელი | AL4: იანვარი 2025 | AR4: თებერვალი 2025 | AX4: მარტი 2025 | BE4: აპრილი 2025 | BL4: მაისი 2025 | BS4: ივნისი 2025 | BZ4: ივლისი 2025 | CF4: აგვისტო 2025 | CL4: სექტემბერი 2025 | CR4: ოქტომბერი 2025 | CX4: ნოემბერი 2025 | DD4: დეკემბერი 2025 | DJ4: სულ 2025 წელი
I5: შუალედ. ჩაბარება | J5: მათ შორის ექსპ. მიღებ. | K5: სულ ჩაბარდა | L5: ექსპ. მიღებ. | P5: შუალედ. ჩაბარება | Q5: ბოლო ჩაბარება | R5: შუალედ. ჩაბარება | S5: ბოლო ჩაბარება | T5: შუალედ. ჩაბარება | V5: ბოლო ჩაბარება | X5: სულ | Z5: შუალედ. ჩაბარება | AB5: ბოლო ჩაბარება | AD5: სულ | AF5: შუალედ. ჩაბარება | AH5: ბოლო ჩაბარება | AJ5: სულ | AL5: შუალედ. ჩაბარება | AN5: ბოლო ჩაბარება | AP5: სულ | AR5: შუალედ. ჩაბარება | AT5: ბოლო ჩაბარება | AV5: სულ | AX5: შუალედ. ჩაბარება | AZ5: ბოლო ჩაბარება | BB5: სულ | BE5: შუალედ. ჩაბარება | BG5: ბოლო ჩაბარება | BI5: სულ | BL5: შუალედ. ჩაბარება | BN5: ბოლო ჩაბარება | BP5: სულ | BS5: შუალედ. ჩაბარება | BU5: ბოლო ჩაბარება | BW5: სულ | BZ5: შუალედ. ჩაბარება | CB5: ბოლო ჩაბარება | CD5: სულ | CF5: შუალედ. ჩაბარება | CH5: ბოლო ჩაბარება | CJ5: სულ | CL5: შუალედ. ჩაბარება | CN5: ბოლო ჩაბარება | CP5: სულ | CR5: შუალედ. ჩაბარება | CT5: ბოლო ჩაბარება | CV5: სულ | CX5: შუალედ. ჩაბარება | CZ5: ბოლო ჩაბარება | DB5: სულ | DD5: შუალედ. ჩაბარება | DF5: ბოლო ჩაბარება | DH5: სულ | DJ5: შუალედ. ჩაბარება | DL5: ბოლო ჩაბარება | DN5: სულ
T6: გეგმა | U6: ფაქტი | V6: გეგმა | W6: ფაქტი | X6: გეგმა | Y6: ფაქტი | Z6: გეგმა | AA6: ფაქტი | AB6: გეგმა | AC6: ფაქტი | AD6: გეგმა | AE6: ფაქტი | AF6: გეგმა | AG6: ფაქტი | AH6: გეგმა | AI6: ფაქტი | AJ6: გეგმა | AK6: ფაქტი | AL6: გეგმა | AM6: ფაქტი | AN6: გეგმა | AO6: ფაქტი | AP6: გეგმა | AQ6: ფაქტი | AR6: გეგმა | AS6: ფაქტი | AT6: გეგმა | AU6: ფაქტი | AV6: გეგმა | AW6: ფაქტი | AX6: გეგმა | AY6: ფაქტი | AZ6: გეგმა | BA6: ფაქტი | BB6: გეგმა | BC6: გეგმა 13 მარ | BD6: ფაქტი | BE6: გეგმა | BF6: ფაქტი | BG6: გეგმა | BH6: ფაქტი | BI6: გეგმა | BJ6: გეგმა 13 მარ | BK6: ფაქტი | BL6: გეგმა | BM6: ფაქტი | BN6: გეგმა | BO6: ფაქტი | BP6: გეგმა | BQ6: გეგმა 13 მარ | BR6: ფაქტი | BS6: გეგმა | BT6: ფაქტი | BU6: გეგმა | BV6: ფაქტი | BW6: გეგმა | BX6: გეგმა 13 მარ | BY6: ფაქტი | BZ6: გეგმა | CA6: ფაქტი | CB6: გეგმა | CC6: ფაქტი | CD6: გეგმა | CE6: ფაქტი | CF6: გეგმა | CG6: ფაქტი | CH6: გეგმა | CI6: ფაქტი | CJ6: გეგმა | CK6: ფაქტი | CL6: გეგმა | CM6: ფაქტი | CN6: გეგმა | CO6: ფაქტი | CP6: გეგმა | CQ6: ფაქტი | CR6: გეგმა | CS6: ფაქტი | CT6: გეგმა | CU6: ფაქტი | CV6: გეგმა | CW6: ფაქტი | CX6: გეგმა | CY6: ფაქტი | CZ6: გეგმა | DA6: ფაქტი | DB6: გეგმა | DC6: ფაქტი | DD6: გეგმა | DE6: ფაქტი | DF6: გეგმა | DG6: ფაქტი | DH6: გეგმა | DI6: ფაქტი | DJ6: გეგმა | DK6: ფაქტი | DL6: გეგმა | DM6: ფაქტი | DN6: გეგმა | DO6: ფაქტი
A7: =SUBTOTAL(3,A9:A155) -> 147 | B7: =SUBTOTAL(3,B9:B155) -> 147 | C7: =SUBTOTAL(3,C9:C155) -> 144 | D7: =SUBTOTAL(3,D9:D155) -> 147 | E7: =SUBTOTAL(3,E9:E155) -> 147 | F7: =SUBTOTAL(9,F9:F155) -> 3360463.8 | G7: =SUBTOTAL(9,G9:G155) -> 10067841 | H7: =SUBTOTAL(9,H9:H155) -> 11648998 | I7: =SUBTOTAL(9,I9:I155) -> 494716.25 | J7: =SUBTOTAL(9,J9:J155) -> 0 | K7: =SUBTOTAL(9,K9:K155) -> 6502485.6 | L7: =SUBTOTAL(9,L9:L155) -> 3108485.6 | M7: =SUBTOTAL(9,M9:M155) -> 6997201.8 | ... DO7: =SUBTOTAL(9,DO9:DO155) -> 2339837.6
A9: 1 | B9: გარდაბანი | D9: მარტყოფი (აკრიანის არეალი)(I ეტაპი) | E9: მშენებლობა | F9: =SUM(DN9) -> 950000 | G9: =I9+AK9+DN9 -> 950000 | H9: 850000 | I9: 0 | J9: 0 | K9: =AK9 -> 0 | L9: =IF(AI9>0,I9+AK9-J9,0) -> 0 | M9: =I9+K9 -> 0 | N9: =G9-M9 -> 950000 | O9: =IF(AND(AI9>0,DM9>0),"შეცდომაა! ერთზე მეტი ბოლო ჩაბარება!",IF(OR(AI9>0,DM9>0,),IF(AI9>0,I9+AK9,I9+AK9+DO9),IF(AND(I9=0,K9=0,DO9=0),"ნულოვანი შესრულება","მიმდინარეობს"))) -> ნულოვანი შესრულება | R9: =I9+P9 -> 0 | S9: =Q9 -> 0 | X9: =T9+V9 -> 0 | Y9: =U9+W9 -> 0 | AD9: =Z9+AB9 -> 0 | AE9: =AA9+AC9 -> 0 | AF9: =P9+T9+Z9 -> 0 | AG9: =P9+U9+AA9 -> 0 | AH9: =Q9+V9+AB9 -> 0 | AI9: =Q9+W9+AC9 -> 0 | AJ9: =AF9+AH9 -> 0 | AK9: =AG9+AI9 -> 0 | AP9: =AL9+AN9 -> 0 | AQ9: =AM9+AO9 -> 0 | AR9: 200000 | AV9: =AR9+AT9 -> 200000 | AW9: =AS9+AU9 -> 0 | AX9: 250000 | BB9: =AX9+AZ9 -> 250000 | BD9: =AY9+BA9 -> 0 | BE9: 250000 | BI9: =BE9+BG9 -> 250000 | BK9: =BF9+BH9 -> 0 | BL9: 250000 | BP9: =BL9+BN9 -> 250000 | BR9: =BM9+BO9 -> 0 | BU9: 100000 | BW9: =BS9+BU9 -> 100000 | BY9: =BT9+BV9 -> 0 | CD9: =BZ9+CB9 -> 0 | CE9: =CA9+CC9 -> 0 | CJ9: =CF9+CH9 -> 0 | CK9: =CG9+CI9 -> 0 | CP9: =CL9+CN9 -> 0 | CQ9: =CM9+CO9 -> 0 | CV9: =CR9+CT9 -> 0 | CW9: =CS9+CU9 -> 0 | DB9: =CX9+CZ9 -> 0 | DC9: =CY9+DA9 -> 0 | DH9: =DD9+DF9 -> 0 | DI9: =DE9+DG9 -> 0 | DJ9: =AL9+AR9+AX9+BE9+BL9+BS9+BZ9+CF9+CL9+CR9+CX9+DD9 -> 950000 | DK9: =AM9+AS9+AY9+BF9+BM9+BT9+CA9+CG9+CM9+CS9+CY9+DE9 -> 0 | DL9: =AN9+AT9+BC9+BJ9+BQ9+BX9+CB9+CH9+CN9+CT9+CZ9+DF9 -> 0 | DM9: =AO9+AU9+BA9+BH9+BO9+BV9+CC9+CI9+CO9+CU9+DA9+DG9 -> 0 | DN9: =DJ9+DL9 -> 950000 | DO9: =DK9+DM9 -> 0
A10: 2 | B10: ახმეტა | C10: P.2.94 | D10: ქ. ახმეტა რუსთაველის ქუჩის გაზსადენის რეაბილიტაცია | E10: მშენებლობა | F10: =SUM(DN10) -> 0 | G10: =I10+AK10+DN10 -> 364847.96 | H10: 150120 | I10: 0 | J10: 0 | K10: =AK10 -> 364847.96 | L10: =IF(AI10>0,I10+AK10-J10,0) -> 364847.96 | M10: =I10+K10 -> 364847.96 | N10: =G10-M10 -> 0 | O10: =IF(AND(AI10>0,DM10>0),"შეცდომაა! ერთზე მეტი ბოლო ჩაბარება!",IF(OR(AI10>0,DM10>0,),IF(AI10>0,I10+AK10,I10+AK10+DO10),IF(AND(I10=0,K10=0,DO10=0),"ნულოვანი შესრულება","მიმდინარეობს"))) -> 364847.96 | P10: 320000 | Q10: 44847.96 | R10: =I10+P10 -> 320000 | S10: =Q10 -> 44847.96 | X10: =T10+V10 -> 0 | Y10: =U10+W10 -> 0 | AD10: =Z10+AB10 -> 0 | AE10: =AA10+AC10 -> 0 | AF10: =P10+T10+Z10 -> 320000 | AG10: =P10+U10+AA10 -> 320000 | AH10: =Q10+V10+AB10 -> 44847.96 | AI10: =Q10+W10+AC10 -> 44847.96 | AJ10: =AF10+AH10 -> 364847.96 | AK10: =AG10+AI10 -> 364847.96 | AP10: =AL10+AN10 -> 0 | AQ10: =AM10+AO10 -> 0 | AV10: =AR10+AT10 -> 0 | AW10: =AS10+AU10 -> 0 | BB10: =AX10+AZ10 -> 0 | BD10: =AY10+BA10 -> 0 | BI10: =BE10+BG10 -> 0 | BK10: =BF10+BH10 -> 0 | BP10: =BL10+BN10 -> 0 | BR10: =BM10+BO10 -> 0 | BW10: =BS10+BU10 -> 0 | BY10: =BT10+BV10 -> 0 | CD10: =BZ10+CB10 -> 0 | CE10: =CA10+CC10 -> 0 | CJ10: =CF10+CH10 -> 0 | CK10: =CG10+CI10 -> 0 | CP10: =CL10+CN10 -> 0 | CQ10: =CM10+CO10 -> 0 | CV10: =CR10+CT10 -> 0 | CW10: =CS10+CU10 -> 0 | DB10: =CX10+CZ10 -> 0 | DC10: =CY10+DA10 -> 0 | DH10: =DD10+DF10 -> 0 | DI10: =DE10+DG10 -> 0 | DJ10: =AL10+AR10+AX10+BE10+BL10+BS10+BZ10+CF10+CL10+CR10+CX10+DD10 -> 0 | DK10: =AM10+AS10+AY10+BF10+BM10+BT10+CA10+CG10+CM10+CS10+CY10+DE10 -> 0 | DL10: =AN10+AT10+BC10+BJ10+BQ10+BX10+CB10+CH10+CN10+CT10+CZ10+DF10 -> 0 | DM10: =AO10+AU10+BA10+BH10+BO10+BV10+CC10+CI10+CO10+CU10+DA10+DG10 -> 0 | DN10: =DJ10+DL10 -> 0 | DO10: =DK10+DM10 -> 0
A11: 3 | B11: ახმეტა | C11: P.2.518 | D11: (16) ახმეტის მუნიციპალიტეტი სოფელი მატანის გაზსადენის რეაბილიტაცია მატნის საუბნოდან სოფლის შესასვლელამდე | E11: დაპროექტება | F11: =SUM(DN11) -> 0 | G11: =I11+AK11+DN11 -> 3766 | I11: 0 | J11: 0 | K11: =AK11 -> 3766 | L11: =IF(AI11>0,I11+AK11-J11,0) -> 3766 | M11: =I11+K11 -> 3766 | N11: =G11-M11 -> 0 | O11: =IF(AND(AI11>0,DM11>0),"შეცდომაა! ერთზე მეტი ბოლო ჩაბარება!",IF(OR(AI11>0,DM11>0,),IF(AI11>0,I11+AK11,I11+AK11+DO11),IF(AND(I11=0,K11=0,DO11=0),"ნულოვანი შესრულება","მიმდინარეობს"))) -> 3766 | Q11: 3766 | R11: =I11+P11 -> 0 | S11: =Q11 -> 3766 | X11: =T11+V11 -> 0 | Y11: =U11+W11 -> 0 | AD11: =Z11+AB11 -> 0 | AE11: =AA11+AC11 -> 0 | AF11: =P11+T11+Z11 -> 0 | AG11: =P11+U11+AA11 -> 0 | AH11: =Q11+V11+AB11 -> 3766 | AI11: =Q11+W11+AC11 -> 3766 | AJ11: =AF11+AH11 -> 3766 | AK11: =AG11+AI11 -> 3766 | AP11: =AL11+AN11 -> 0 | AQ11: =AM11+AO11 -> 0 | AV11: =AR11+AT11 -> 0 | AW11: =AS11+AU11 -> 0 | BB11: =AX11+AZ11 -> 0 | BD11: =AY11+BA11 -> 0 | BI11: =BE11+BG11 -> 0 | BK11: =BF11+BH11 -> 0 | BP11: =BL11+BN11 -> 0 | BR11: =BM11+BO11 -> 0 | BW11: =BS11+BU11 -> 0 | BY11: =BT11+BV11 -> 0 | CD11: =BZ11+CB11 -> 0 | CE11: =CA11+CC11 -> 0 | CJ11: =CF11+CH11 -> 0 | CK11: =CG11+CI11 -> 0 | CP11: =CL11+CN11 -> 0 | CQ11: =CM11+CO11 -> 0 | CV11: =CR11+CT11 -> 0 | CW11: =CS11+CU11 -> 0 | DB11: =CX11+CZ11 -> 0 | DC11: =CY11+DA11 -> 0 | DH11: =DD11+DF11 -> 0 | DI11: =DE11+DG11 -> 0 | DJ11: =AL11+AR11+AX11+BE11+BL11+BS11+BZ11+CF11+CL11+CR11+CX11+DD11 -> 0 | DK11: =AM11+AS11+AY11+BF11+BM11+BT11+CA11+CG11+CM11+CS11+CY11+DE11 -> 0 | DL11: =AN11+AT11+BC11+BJ11+BQ11+BX11+CB11+CH11+CN11+CT11+CZ11+DF11 -> 0 | DM11: =AO11+AU11+BA11+BH11+BO11+BV11+CC11+CI11+CO11+CU11+DA11+DG11 -> 0 | DN11: =DJ11+DL11 -> 0 | DO11: =DK11+DM11 -> 0
A12: 4 | B12: ახმეტა | C12: P.2.526 | D12: (40) ქ. ახმეტა გორგასლის პირველი შესახვევი მიწისქვეშა გაზსადენის რეაბილიტაცია | E12: დაპროექტება | F12: =SUM(DN12) -> 0 | G12: =I12+AK12+DN12 -> 1242.5 | I12: 0 | J12: 0 | K12: =AK12 -> 1242.5 | L12: =IF(AI12>0,I12+AK12-J12,0) -> 1242.5 | M12: =I12+K12 -> 1242.5 | N12: =G12-M12 -> 0 | O12: =IF(AND(AI12>0,DM12>0),"შეცდომაა! ერთზე მეტი ბოლო ჩაბარება!",IF(OR(AI12>0,DM12>0,),IF(AI12>0,I12+AK12,I12+AK12+DO12),IF(AND(I12=0,K12=0,DO12=0),"ნულოვანი შესრულება","მიმდინარეობს"))) -> 1242.5 | Q12: 1242.5 | R12: =I12+P12 -> 0 | S12: =Q12 -> 1242.5 | X12: =T12+V12 -> 0 | Y12: =U12+W12 -> 0 | AD12: =Z12+AB12 -> 0 | AE12: =AA12+AC12 -> 0 | AF12: =P12+T12+Z12 -> 0 | AG12: =P12+U12+AA12 -> 0 | AH12: =Q12+V12+AB12 -> 1242.5 | AI12: =Q12+W12+AC12 -> 1242.5 | AJ12: =AF12+AH12 -> 1242.5 | AK12: =AG12+AI12 -> 1242.5 | AP12: =AL12+AN12 -> 0 | AQ12: =AM12+AO12 -> 0 | AV12: =AR12+AT12 -> 0 | AW12: =AS12+AU12 -> 0 | BB12: =AX12+AZ12 -> 0 | BD12: =AY12+BA12 -> 0 | BI12: =BE12+BG12 -> 0 | BK12: =BF12+BH12 -> 0 | BP12: =BL12+BN12 -> 0 | BR12: =BM12+BO12 -> 0 | BW12: =BS12+BU12 -> 0 | BY12: =BT12+BV12 -> 0 | CD12: =BZ12+CB12 -> 0 | CE12: =CA12+CC12 -> 0 | CJ12: =CF12+CH12 -> 0 | CK12: =CG12+CI12 -> 0 | CP12: =CL12+CN12 -> 0 | CQ12: =CM12+CO12 -> 0 | CV12: =CR12+CT12 -> 0 | CW12: =CS12+CU12 -> 0 | DB12: =CX12+CZ12 -> 0 | DC12: =CY12+DA12 -> 0 | DH12: =DD12+DF12 -> 0 | DI12: =DE12+DG12 -> 0 | DJ12: =AL12+AR12+AX12+BE12+BL12+BS12+BZ12+CF12+CL12+CR12+CX12+DD12 -> 0 | DK12: =AM12+AS12+AY12+BF12+BM12+BT12+CA12+CG12+CM12+CS12+CY12+DE12 -> 0 | DL12: =AN12+AT12+BC12+BJ12+BQ12+BX12+CB12+CH12+CN12+CT12+CZ12+DF12 -> 0 | DM12: =AO12+AU12+BA12+BH12+BO12+BV12+CC12+CI12+CO12+CU12+DA12+DG12 -> 0 | DN12: =DJ12+DL12 -> 0 | DO12: =DK12+DM12 -> 0
A13: 5 | B13: ახმეტა | C13: P.2.506 | D13: (37) ქ. ახმეტა დედის ქუჩის გაზსადენის რეაბილიტაცია პირველი მაისის ქუჩის გაზსადენის რეაბილიტაცია | E13: მშენებლობა | F13: =SUM(DN13) -> 0 | G13: =I13+AK13+DN13 -> 55798.55 | I13: 0 | J13: 0 | K13: =AK13 -> 55798.55 | L13: =IF(AI13>0,I13+AK13-J13,0) -> 55798.55 | M13: =I13+K13 -> 55798.55 | N13: =G13-M13 -> 0 | O13: =IF(AND(AI13>0,DM13>0),"შეცდომაა! ერთზე მეტი ბოლო ჩაბარება!",IF(OR(AI13>0,DM13>0,),IF(AI13>0,I13+AK13,I13+AK13+DO13),IF(AND(I13=0,K13=0,DO13=0),"ნულოვანი შესრულება","მიმდინარეობს"))) -> 55798.55 | P13: 30000 | Q13: 25798.55 | R13: =I13+P13 -> 30000 | S13: =Q13 -> 25798.55 | X13: =T13+V13 -> 0 | Y13: =U13+W13 -> 0 | AD13: =Z13+AB13 -> 0 | AE13: =AA13+AC13 -> 0 | AF13: =P13+T13+Z13 -> 30000 | AG13: =P13+U13+AA13 -> 30000 | AH13: =Q13+V13+AB13 -> 25798.55 | AI13: =Q13+W13+AC13 -> 25798.55 | AJ13: =AF13+AH13 -> 55798.55 | AK13: =AG13+AI13 -> 55798.55 | AP13: =AL13+AN13 -> 0 | AQ13: =AM13+AO13 -> 0 | AV13: =AR13+AT13 -> 0 | AW13: =AS13+AU13 -> 0 | BB13: =AX13+AZ13 -> 0 | BD13: =AY13+BA13 -> 0 | BI13: =BE13+BG13 -> 0 | BK13: =BF13+BH13 -> 0 | BP13: =BL13+BN13 -> 0 | BR13: =BM13+BO13 -> 0 | BW13: =BS13+BU13 -> 0 | BY13: =BT13+BV13 -> 0 | CD13: =BZ13+CB13 -> 0 | CE13: =CA13+CC13 -> 0 | CJ13: =CF13+CH13 -> 0 | CK13: =CG13+CI13 -> 0 | CP13: =CL13+CN13 -> 0 | CQ13: =CM13+CO13 -> 0 | CV13: =CR13+CT13 -> 0 | CW13: =CS13+CU13 -> 0 | DB13: =CX13+CZ13 -> 0 | DC13: =CY13+DA13 -> 0 | DH13: =DD13+DF13 -> 0 | DI13: =DE13+DG13 -> 0 | DJ13: =AL13+AR13+AX13+BE13+BL13+BS13+BZ13+CF13+CL13+CR13+CX13+DD13 -> 0 | DK13: =AM13+AS13+AY13+BF13+BM13+BT13+CA13+CG13+CM13+CS13+CY13+DE13 -> 0 | DL13: =AN13+AT13+BC13+BJ13+BQ13+BX13+CB13+CH13+CN13+CT13+CZ13+DF13 -> 0 | DM13: =AO13+AU13+BA13+BH13+BO13+BV13+CC13+CI13+CO13+CU13+DA13+DG13 -> 0 | DN13: =DJ13+DL13 -> 0 | DO13: =DK13+DM13 -> 0
A14: 6 | B14: მარნეული | C14: P.2.906 | D14: (1) სოფ ჯანდარის დაბალი წნევის მილის რეაბილიტაცია. (P.2.906) | E14: მშენებლობა | F14: =SUM(DN14) -> 0 | G14: =I14+AK14+DN14 -> 0 | H14: 540000 | I14: 0 | J14: 0 | K14: =AK14 -> 0 | L14: =IF(AI14>0,I14+AK14-J14,0) -> 0 | M14: =I14+K14 -> 0 | N14: =G14-M14 -> 0 | O14: =IF(AND(AI14>0,DM14>0),"შეცდომაა! ერთზე მეტი ბოლო ჩაბარება!",IF(OR(AI14>0,DM14>0,),IF(AI14>0,I14+AK14,I14+AK14+DO14),IF(AND(I14=0,K14=0,DO14=0),"ნულოვანი შესრულება","მიმდინარეობს"))) -> ნულოვანი შესრულება | R14: =I14+P14 -> 0 | S14: =Q14 -> 0 | X14: =T14+V14 -> 0 | Y14: =U14+W14 -> 0 | AD14: =Z14+AB14 -> 0 | AE14: =AA14+AC14 -> 0 | AF14: =P14+T14+Z14 -> 0 | AG14: =P14+U14+AA14 -> 0 | AH14: =Q14+V14+AB14 -> 0 | AI14: =Q14+W14+AC14 -> 0 | AJ14: =AF14+AH14 -> 0 | AK14: =AG14+AI14 -> 0 | AP14: =AL14+AN14 -> 0 | AQ14: =AM14+AO14 -> 0 | AV14: =AR14+AT14 -> 0 | AW14: =AS14+AU14 -> 0 | BB14: =AX14+AZ14 -> 0 | BD14: =AY14+BA14 -> 0 | BI14: =BE14+BG14 -> 0 | BK14: =BF14+BH14 -> 0 | BP14: =BL14+BN14 -> 0 | BR14: =BM14+BO14 -> 0 | BW14: =BS14+BU14 -> 0 | BY14: =BT14+BV14 -> 0 | CD14: =BZ14+CB14 -> 0 | CE14: =CA14+CC14 -> 0 | CJ14: =CF14+CH14 -> 0 | CK14: =CG14+CI14 -> 0 | CP14: =CL14+CN14 -> 0 | CQ14: =CM14+CO14 -> 0 | CV14: =CR14+CT14 -> 0 | CW14: =CS14+CU14 -> 0 | DB14: =CX14+CZ14 -> 0 | DC14: =CY14+DA14 -> 0 | DH14: =DD14+DF14 -> 0 | DI14: =DE14+DG14 -> 0 | DJ14: =AL14+AR14+AX14+BE14+BL14+BS14+BZ14+CF14+CL14+CR14+CX14+DD14 -> 0 | DK14: =AM14+AS14+AY14+BF14+BM14+BT14+CA14+CG14+CM14+CS14+CY14+DE14 -> 0 | DL14: =AN14+AT14+BC14+BJ14+BQ14+BX14+CB14+CH14+CN14+CT14+CZ14+DF14 -> 0 | DM14: =AO14+AU14+BA14+BH14+BO14+BV14+CC14+CI14+CO14+CU14+DA14+DG14 -> 0 | DN14: =DJ14+DL14 -> 0 | DO14: =DK14+DM14 -> 0
A15: 7 | B15: გარდაბანი | C15: P.2.134 | D15: 1.1.2. В Гардабанском муниципалитете реабилитационные работы питающего газопровода c. Караджалар и с. Каратаклия. (P.2.134) | E15: მშენებლობა | F15: =SUM(DN15) -> 0 | G15: =I15+AK15+DN15 -> 0 | H15: 335000 | I15: 0 | J15: 0 | K15: =AK15 -> 0 | L15: =IF(AI15>0,I15+AK15-J15,0) -> 0 | M15: =I15+K15 -> 0 | N15: =G15-M15 -> 0 | O15: =IF(AND(AI15>0,DM15>0),"შეცდომაა! ერთზე მეტი ბოლო ჩაბარება!",IF(OR(AI15>0,DM15>0,),IF(AI15>0,I15+AK15,I15+AK15+DO15),IF(AND(I15=0,K15=0,DO15=0),"ნულოვანი შესრულება","მიმდინარეობს"))) -> ნულოვანი შესრულება | R15: =I15+P15 -> 0 | S15: =Q15 -> 0 | X15: =T15+V15 -> 0 | Y15: =U15+W15 -> 0 | AD15: =Z15+AB15 -> 0 | AE15: =AA15+AC15 -> 0 | AF15: =P15+T15+Z15 -> 0 | AG15: =P15+U15+AA15 -> 0 | AH15: =Q15+V15+AB15 -> 0 | AI15: =Q15+W15+AC15 -> 0 | AJ15: =AF15+AH15 -> 0 | AK15: =AG15+AI15 -> 0 | AP15: =AL15+AN15 -> 0 | AQ15: =AM15+AO15 -> 0 | AV15: =AR15+AT15 -> 0 | AW15: =AS15+AU15 -> 0 | BB15: =AX15+AZ15 -> 0 | BD15: =AY15+BA15 -> 0 | BI15: =BE15+BG15 -> 0 | BK15: =BF15+BH15 -> 0 | BP15: =BL15+BN15 -> 0 | BR15: =BM15+BO15 -> 0 | BW15: =BS15+BU15 -> 0 | BY15: =BT15+BV15 -> 0 | CD15: =BZ15+CB15 -> 0 | CE15: =CA15+CC15 -> 0 | CJ15: =CF15+CH15 -> 0 | CK15: =CG15+CI15 -> 0 | CP15: =CL15+CN15 -> 0 | CQ15: =CM15+CO15 -> 0 | CV15: =CR15+CT15 -> 0 | CW15: =CS15+CU15 -> 0 | DB15: =CX15+CZ15 -> 0 | DC15: =CY15+DA15 -> 0 | DH15: =DD15+DF15 -> 0 | DI15: =DE15+DG15 -> 0 | DJ15: =AL15+AR15+AX15+BE15+BL15+BS15+BZ15+CF15+CL15+CR15+CX15+DD15 -> 0 | DK15: =AM15+AS15+AY15+BF15+BM15+BT15+CA15+CG15+CM15+CS15+CY15+DE15 -> 0 | DL15: =AN15+AT15+BC15+BJ15+BQ15+BX15+CB15+CH15+CN15+CT15+CZ15+DF15 -> 0 | DM15: =AO15+AU15+BA15+BH15+BO15+BV15+CC15+CI15+CO15+CU15+DA15+DG15 -> 0 | DN15: =DJ15+DL15 -> 0 | DO15: =DK15+DM15 -> 0 | DP15: 2026 წელშია გადასატანი
A16: 8 | B16: გარდაბანი | C16: P.2.843 | D16: (16) გარდაბანი, სოფ. ყარაჯალაში მიწისქვეშა გადასვლების რეაბილიტაცია და მრიცხველების გამოტანა,შეცვლა P.2.843 | E16: მშენებლობა | F16: =SUM(DN16) -> 0 | G16: =I16+AK16+DN16 -> 0 | H16: 260000 | I16: 0 | J16: 0 | K16: =AK16 -> 0 | L16: =IF(AI16>0,I16+AK16-J16,0) -> 0 | M16: =I16+K16 -> 0 | N16: =G16-M16 -> 0 | O16: =IF(AND(AI16>0,DM16>0),"შეცდომაა! ერთზე მეტი ბოლო ჩაბარება!",IF(OR(AI16>0,DM16>0,),IF(AI16>0,I16+AK16,I16+AK16+DO16),IF(AND(I16=0,K16=0,DO16=0),"ნულოვანი შესრულება","მიმდინარეობს"))) -> ნულოვანი შესრულება | R16: =I16+P16 -> 0 | S16: =Q16 -> 0 | X16: =T16+V16 -> 0 | Y16: =U16+W16 -> 0 | AD16: =Z16+AB16 -> 0 | AE16: =AA16+AC16 -> 0 | AF16: =P16+T16+Z16 -> 0 | AG16: =P16+U16+AA16 -> 0 | AH16: =Q16+V16+AB16 -> 0 | AI16: =Q16+W16+AC16 -> 0 | AJ16: =AF16+AH16 -> 0 | AK16: =AG16+AI16 -> 0 | AP16: =AL16+AN16 -> 0 | AQ16: =AM16+AO16 -> 0 | AV16: =AR16+AT16 -> 0 | AW16: =AS16+AU16 -> 0 | BB16: =AX16+AZ16 -> 0 | BD16: =AY16+BA16 -> 0 | BI16: =BE16+BG16 -> 0 | BK16: =BF16+BH16 -> 0 | BP16: =BL16+BN16 -> 0 | BR16: =BM16+BO16 -> 0 | BW16: =BS16+BU16 -> 0 | BY16: =BT16+BV16 -> 0 | CD16: =BZ16+CB16 -> 0 | CE16: =CA16+CC16 -> 0 | CJ16: =CF16+CH16 -> 0 | CK16: =CG16+CI16 -> 0 | CP16: =CL16+CN16 -> 0 | CQ16: =CM16+CO16 -> 0 | CV16: =CR16+CT16 -> 0 | CW16: =CS16+CU16 -> 0 | DB16: =CX16+CZ16 -> 0 | DC16: =CY16+DA16 -> 0 | DH16: =DD16+DF16 -> 0 | DI16: =DE16+DG16 -> 0 | DJ16: =AL16+AR16+AX16+BE16+BL16+BS16+BZ16+CF16+CL16+CR16+CX16+DD16 -> 0 | DK16: =AM16+AS16+AY16+BF16+BM16+BT16+CA16+CG16+CM16+CS16+CY16+DE16 -> 0 | DL16: =AN16+AT16+BC16+BJ16+BQ16+BX16+CB16+CH16+CN16+CT16+CZ16+DF16 -> 0 | DM16: =AO16+AU16+BA16+BH16+BO16+BV16+CC16+CI16+CO16+CU16+DA16+DG16 -> 0 | DN16: =DJ16+DL16 -> 0 | DO16: =DK16+DM16 -> 0
A17: 9 | B17: გურჯაანი | C17: P.2.874 | D17: (4) 43-ე საუბნო კვანძზე (მელაანიდან გზის პირი, გაჩერებამდე) (ჩალაუბანში საშ. წნევის მიყვანა სოფ. მელაანამდე) დაბალი წნევის გაზსადენის რეაბილიტაცია. (P.2.874) | E17: მშენებლობა | F17: =SUM(DN17) -> 0 | H17: 240000 | I17: 0 | J17: 0 | K17: =AK17 -> 0 | L17: =IF(AI17>0,I17+AK17-J17,0) -> 0 | M17: =I17+K17 -> 0 | N17: =G17-M17 -> 0 | O17: =IF(AND(AI17>0,DM17>0),"შეცდომაა! ერთზე მეტი ბოლო ჩაბარება!",IF(OR(AI17>0,DM17>0,),IF(AI17>0,I17+AK17,I17+AK17+DO17),IF(AND(I17=0,K17=0,DO17=0),"ნულოვანი შესრულება","მიმდინარეობს"))) -> ნულოვანი შესრულება | R17: =I17+P17 -> 0 | S17: =Q17 -> 0 | X17: =T17+V17 -> 0 | Y17: =U17+W17 -> 0 | AD17: =Z17+AB17 -> 0 | AE17: =AA17+AC17 -> 0 | AF17: =P17+T17+Z17 -> 0 | AG17: =P17+U17+AA17 -> 0 | AH17: =Q17+V17+AB17 -> 0 | AI17: =Q17+W17+AC17 -> 0 | AJ17: =AF17+AH17 -> 0 | AK17: =AG17+AI17 -> 0 | AP17: =AL17+AN17 -> 0 | AQ17: =AM17+AO17 -> 0 | AV17: =AR17+AT17 -> 0 | AW17: =AS17+AU17 -> 0 | BB17: =AX17+AZ17 -> 0 | BD17: =AY17+BA17 -> 0 | BI17: =BE17+BG17 -> 0 | BK17: =BF17+BH17 -> 0 | BP17: =BL17+BN17 -> 0 | BR17: =BM17+BO17 -> 0 | BW17: =BS17+BU17 -> 0 | BY17: =BT17+BV17 -> 0 | CD17: =BZ17+CB17 -> 0 | CE17: =CA17+CC17 -> 0 | CJ17: =CF17+CH17 -> 0 | CK17: =CG17+CI17 -> 0 | CP17: =CL17+CN17 -> 0 | CQ17: =CM17+CO17 -> 0 | CV17: =CR17+CT17 -> 0 | CW17: =CS17+CU17 -> 0 | DB17: =CX17+CZ17 -> 0 | DC17: =CY17+DA17 -> 0 | DH17: =DD17+DF17 -> 0 | DI17: =DE17+DG17 -> 0 | DJ17: =AL17+AR17+AX17+BE17+BL17+BS17+BZ17+CF17+CL17+CR17+CX17+DD17 -> 0 | DK17: =AM17+AS17+AY17+BF17+BM17+BT17+CA17+CG17+CM17+CS17+CY17+DE17 -> 0 | DL17: =AN17+AT17+BC17+BJ17+BQ17+BX17+CB17+CH17+CN17+CT17+CZ17+DF17 -> 0 | DM17: =AO17+AU17+BA17+BH17+BO17+BV17+CC17+CI17+CO17+CU17+DA17+DG17 -> 0 | DN17: =DJ17+DL17 -> 0 | DO17: =DK17+DM17 -> 0
A18: 10 | B18: გურჯაანი | C18: P.2.871 | D18: (3) 34-ე საუბნო (სოფ. დარჩეთი, ცენტრალური გზა, ორივე მხრიდან) (არაშენდიდან ქოდალომდე) ბესოს ფერმასთან (შესასვლელში) (დარჩეთის სკოლასთან) წნევის გაზსადენის რეაბილიტაცია. (P.2.871) | E18: მშენებლობა | F18: =SUM(DN18) -> 0 | G18: =I18+AK18+DN18 -> 0 | H18: 300000 | I18: 0 | J18: 0 | K18: =AK18 -> 0 | L18: =IF(AI18>0,I18+AK18-J18,0) -> 0 | M18: =I18+K18 -> 0 | N18: =G18-M18 -> 0 | O18: =IF(AND(AI18>0,DM18>0),"შეცდომაა! ერთზე მეტი ბოლო ჩაბარება!",IF(OR(AI18>0,DM18>0,),IF(AI18>0,I18+AK18,I18+AK18+DO18),IF(AND(I18=0,K18=0,DO18=0),"ნულოვანი შესრულება","მიმდინარეობს"))) -> ნულოვანი შესრულება | R18: =I18+P18 -> 0 | S18: =Q18 -> 0 | X18: =T18+V18 -> 0 | Y18: =U18+W18 -> 0 | AD18: =Z18+AB18 -> 0 | AE18: =AA18+AC18 -> 0 | AF18: =P18+T18+Z18 -> 0 | AG18: =P18+U18+AA18 -> 0 | AH18: =Q18+V18+AB18 -> 0 | AI18: =Q18+W18+AC18 -> 0 | AJ18: =AF18+AH18 -> 0 | AK18: =AG18+AI18 -> 0 | AP18: =AL18+AN18 -> 0 | AQ18: =AM18+AO18 -> 0 | AV18: =AR18+AT18 -> 0 | AW18: =AS18+AU18 -> 0 | BB18: =AX18+AZ18 -> 0 | BD18: =AY18+BA18 -> 0 | BI18: =BE18+BG18 -> 0 | BK18: =BF18+BH18 -> 0 | BP18: =BL18+BN18 -> 0 | BR18: =BM18+BO18 -> 0 | BW18: =BS18+BU18 -> 0 | BY18: =BT18+BV18 -> 0 | CD18: =BZ18+CB18 -> 0 | CE18: =CA18+CC18 -> 0 | CJ18: =CF18+CH18 -> 0 | CK18: =CG18+CI18 -> 0 | CP18: =CL18+CN18 -> 0 | CQ18: =CM18+CO18 -> 0 | CV18: =CR18+CT18 -> 0 | CW18: =CS18+CU18 -> 0 | DB18: =CX18+CZ18 -> 0 | DC18: =CY18+DA18 -> 0 | DH18: =DD18+DF18 -> 0 | DI18: =DE18+DG18 -> 0 | DJ18: =AL18+AR18+AX18+BE18+BL18+BS18+BZ18+CF18+CL18+CR18+CX18+DD18 -> 0 | DK18: =AM18+AS18+AY18+BF18+BM18+BT18+CA18+CG18+CM18+CS18+CY18+DE18 -> 0 | DL18: =AN18+AT18+BC18+BJ18+BQ18+BX18+CB18+CH18+CN18+CT18+CZ18+DF18 -> 0 | DM18: =AO18+AU18+BA18+BH18+BO18+BV18+CC18+CI18+CO18+CU18+DA18+DG18 -> 0 | DN18: =DJ18+DL18 -> 0 | DO18: =DK18+DM18 -> 0
A19: 11 | B19: მარნეული | C19: P.2.902 | D19: (8) 740 ცალი მრიცხველის გამოტანა საკუთარი სახლებიდან მარნეულის სერვის ცენტრში P.2.902 | E19: მშენებლობა | F19: =SUM(DN19) -> 0 | G19: =I19+AK19+DN19 -> 0 | H19: 300000 | I19: 0 | J19: 0 | K19: =AK19 -> 0 | L19: =IF(AI19>0,I19+AK19-J19,0) -> 0 | M19: =I19+K19 -> 0 | N19: =G19-M19 -> 0 | O19: =IF(AND(AI19>0,DM19>0),"შეცდომაა! ერთზე მეტი ბოლო ჩაბარება!",IF(OR(AI19>0,DM19>0,),IF(AI19>0,I19+AK19,I19+AK19+DO19),IF(AND(I19=0,K19=0,DO19=0),"ნულოვანი შესრულება","მიმდინარეობს"))) -> ნულოვანი შესრულება | R19: =I19+P19 -> 0 | S19: =Q19 -> 0 | X19: =T19+V19 -> 0 | Y19: =U19+W19 -> 0 | AD19: =Z19+AB19 -> 0 | AE19: =AA19+AC19 -> 0 | AF19: =P19+T19+Z19 -> 0 | AG19: =P19+U19+AA19 -> 0 | AH19: =Q19+V19+AB19 -> 0 | AI19: =Q19+W19+AC19 -> 0 | AJ19: =AF19+AH19 -> 0 | AK19: =AG19+AI19 -> 0 | AP19: =AL19+AN19 -> 0 | AQ19: =AM19+AO19 -> 0 | AV19: =AR19+AT19 -> 0 | AW19: =AS19+AU19 -> 0 | BB19: =AX19+AZ19 -> 0 | BD19: =AY19+BA19 -> 0 | BI19: =BE19+BG19 -> 0 | BK19: =BF19+BH19 -> 0 | BP19: =BL19+BN19 -> 0 | BR19: =BM19+BO19 -> 0 | BW19: =BS19+BU19 -> 0 | BY19: =BT19+BV19 -> 0 | CD19: =BZ19+CB19 -> 0 | CE19: =CA19+CC19 -> 0 | CJ19: =CF19+CH19 -> 0 | CK19: =CG19+CI19 -> 0 | CP19: =CL19+CN19 -> 0 | CQ19: =CM19+CO19 -> 0 | CV19: =CR19+CT19 -> 0 | CW19: =CS19+CU19 -> 0 | DB19: =CX19+CZ19 -> 0 | DC19: =CY19+DA19 -> 0 | DH19: =DD19+DF19 -> 0 | DI19: =DE19+DG19 -> 0 | DJ19: =AL19+AR19+AX19+BE19+BL19+BS19+BZ19+CF19+CL19+CR19+CX19+DD19 -> 0 | DK19: =AM19+AS19+AY19+BF19+BM19+BT19+CA19+CG19+CM19+CS19+CY19+DE19 -> 0 | DL19: =AN19+AT19+BC19+BJ19+BQ19+BX19+CB19+CH19+CN19+CT19+CZ19+DF19 -> 0 | DM19: =AO19+AU19+BA19+BH19+BO19+BV19+CC19+CI19+CO19+CU19+DA19+DG19 -> 0 | DN19: =DJ19+DL19 -> 0 | DO19: =DK19+DM19 -> 0
A20: 12 | B20: გარდაბანი | C20: P.2.844 | D20: (14) გარდაბანი, სოფ. ყარათაკლიაში მიწისქვეშა გადასვლების შეცვლა და მრიცხველების გამოტანა,შეცვლა P.2.844 | E20: მშენებლობა | F20: =SUM(DN20) -> 0 | G20: =I20+AK20+DN20 -> 0 | H20: 155000 | I20: 0 | J20: 0 | K20: =AK20 -> 0 | L20: =IF(AI20>0,I20+AK20-J20,0) -> 0 | M20: =I20+K20 -> 0 | N20: =G20-M20 -> 0 | O20: =IF(AND(AI20>0,DM20>0),"შეცდომაა! ერთზე მეტი ბოლო ჩაბარება!",IF(OR(AI20>0,DM20>0,),IF(AI20>0,I20+AK20,I20+AK20+DO20),IF(AND(I20=0,K20=0,DO20=0),"ნულოვანი შესრულება","მიმდინარეობს"))) -> ნულოვანი შესრულება | R20: =I20+P20 -> 0 | S20: =Q20 -> 0 | X20: =T20+V20 -> 0 | Y20: =U20+W20 -> 0 | AD20: =Z20+AB20 -> 0 | AE20: =AA20+AC20 -> 0 | AF20: =P20+T20+Z20 -> 0 | AG20: =P20+U20+AA20 -> 0 | AH20: =Q20+V20+AB20 -> 0 | AI20: =Q20+W20+AC20 -> 0 | AJ20: =AF20+AH20 -> 0 | AK20: =AG20+AI20 -> 0 | AP20: =AL20+AN20 -> 0 | AQ20: =AM20+AO20 -> 0 | AV20: =AR20+AT20 -> 0 | AW20: =AS20+AU20 -> 0 | BB20: =AX20+AZ20 -> 0 | BD20: =AY20+BA20 -> 0 | BI20: =BE20+BG20 -> 0 | BK20: =BF20+BH20 -> 0 | BP20: =BL20+BN20 -> 0 | BR20: =BM20+BO20 -> 0 | BW20: =BS20+BU20 -> 0 | BY20: =BT20+BV20 -> 0 | CD20: =BZ20+CB20 -> 0 | CE20: =CA20+CC20 -> 0 | CJ20: =CF20+CH20 -> 0 | CK20: =CG20+CI20 -> 0 | CP20: =CL20+CN20 -> 0 | CQ20: =CM20+CO20 -> 0 | CV20: =CR20+CT20 -> 0 | CW20: =CS20+CU20 -> 0 | DB20: =CX20+CZ20 -> 0 | DC20: =CY20+DA20 -> 0 | DH20: =DD20+DF20 -> 0 | DI20: =DE20+DG20 -> 0 | DJ20: =AL20+AR20+AX20+BE20+BL20+BS20+BZ20+CF20+CL20+CR20+CX20+DD20 -> 0 | DK20: =AM20+AS20+AY20+BF20+BM20+BT20+CA20+CG20+CM20+CS20+CY20+DE20 -> 0 | DL20: =AN20+AT20+BC20+BJ20+BQ20+BX20+CB20+CH20+CN20+CT20+CZ20+DF20 -> 0 | DM20: =AO20+AU20+BA20+BH20+BO20+BV20+CC20+CI20+CO20+CU20+DA20+DG20 -> 0 | DN20: =DJ20+DL20 -> 0 | DO20: =DK20+DM20 -> 0
A21: 13 | B21: გარდაბანი | C21: P.2.845 | D21: (12) გარდაბანი, სოფ. ნორიოში მიწისქვეშა გადასვლების რეაბილიტაცია და მრიცხველების გამოტანა,შეცვლა. P.2.845 | E21: მშენებლობა | F21: =SUM(DN21) -> 478975 | G21: 425000 | H21: 237000 | I21: 0 | J21: 0 | K21: =AK21 -> 251000 | L21: =IF(AI21>0,I21+AK21-J21,0) -> 0 | M21: =I21+K21 -> 251000 | N21: =G21-M21 -> 174000 | O21: =IF(AND(AI21>0,DM21>0),"შეცდომაა! ერთზე მეტი ბოლო ჩაბარება!",IF(OR(AI21>0,DM21>0,),IF(AI21>0,I21+AK21,I21+AK21+DO21),IF(AND(I21=0,K21=0,DO21=0),"ნულოვანი შესრულება","მიმდინარეობს"))) -> 693000 | P21: 251000 | R21: =I21+P21 -> 251000 | S21: =Q21 -> 0 | X21: =T21+V21 -> 0 | Y21: =U21+W21 -> 0 | AD21: =Z21+AB21 -> 0 | AE21: =AA21+AC21 -> 0 | AF21: =P21+T21+Z21 -> 251000 | AG21: =P21+U21+AA21 -> 251000 | AH21: =Q21+V21+AB21 -> 0 | AI21: =Q21+W21+AC21 -> 0 | AJ21: =AF21+AH21 -> 251000 | AK21: =AG21+AI21 -> 251000 | AM21: 100000 | AP21: =AL21+AN21 -> 0 | AQ21: =AM21+AO21 -> 100000 | AV21: =AR21+AT21 -> 0 | AW21: =AS21+AU21 -> 0 | AY21: 250000 | BB21: =AX21+AZ21 -> 0 | BC21: 250000 | BD21: =AY21+BA21 -> 250000 | BE21: 100000 | BF21: 40000 | BI21: =BE21+BG21 -> 100000 | BJ21: 40000 | BK21: =BF21+BH21 -> 40000 | BL21: 50000 | BM21: 30000 | BP21: =BL21+BN21 -> 50000 | BQ21: 30000 | BR21: =BM21+BO21 -> 30000 | BU21: 24000 | BV21: 5000 | BW21: =BS21+BU21 -> 24000 | BX21: 8975 | BY21: =BT21+BV21 -> 5000 | CD21: =BZ21+CB21 -> 0 | CE21: =CA21+CC21 -> 0 | CG21: 2000 | CJ21: =CF21+CH21 -> 0 | CK21: =CG21+CI21 -> 2000 | CM21: 5000 | CP21: =CL21+CN21 -> 0 | CQ21: =CM21+CO21 -> 5000 | CS21: 5000 | CV21: =CR21+CT21 -> 0 | CW21: =CS21+CU21 -> 5000 | CY21: 5000 | DB21: =CX21+CZ21 -> 0 | DC21: =CY21+DA21 -> 5000 | DH21: =DD21+DF21 -> 0 | DI21: =DE21+DG21 -> 0 | DJ21: =AL21+AR21+AX21+BE21+BL21+BS21+BZ21+CF21+CL21+CR21+CX21+DD21 -> 150000 | DK21: =AM21+AS21+AY21+BF21+BM21+BT21+CA21+CG21+CM21+CS21+CY21+DE21 -> 437000 | DL21: =AN21+AT21+BC21+BJ21+BQ21+BX21+CB21+CH21+CN21+CT21+CZ21+DF21 -> 328975 | DM21: =AO21+AU21+BA21+BH21+BO21+BV21+CC21+CI21+CO21+CU21+DA21+DG21 -> 5000 | DN21: =DJ21+DL21 -> 478975 | DO21: =DK21+DM21 -> 442000
A22: 14 | B22: ლაგოდეხი | C22: P.2.1161 | D22: (16) სოფ. კაბალში და სოფ. ყარაჯალაში აღრიცხვიანობის მოწესრიგება (P.2.1161) | E22: მშენებლობა | F22: =SUM(DN22) -> 0 | H22: 160000 | I22: 0 | J22: 0 | K22: =AK22 -> 0 | L22: =IF(AI22>0,I22+AK22-J22,0) -> 0 | M22: =I22+K22 -> 0 | N22: =G22-M22 -> 0 | O22: =IF(AND(AI22>0,DM22>0),"შეცდომაა! ერთზე მეტი ბოლო ჩაბარება!",IF(OR(AI22>0,DM22>0,),IF(AI22>0,I22+AK22,I22+AK22+DO22),IF(AND(I22=0,K22=0,DO22=0),"ნულოვანი შესრულება","მიმდინარეობს"))) -> ნულოვანი შესრულება | R22: =I22+P22 -> 0 | S22: =Q22 -> 0 | X22: =T22+V22 -> 0 | Y22: =U22+W22 -> 0 | AD22: =Z22+AB22 -> 0 | AE22: =AA22+AC22 -> 0 | AF22: =P22+T22+Z22 -> 0 | AG22: =P22+U22+AA22 -> 0 | AH22: =Q22+V22+AB22 -> 0 | AI22: =Q22+W22+AC22 -> 0 | AJ22: =AF22+AH22 -> 0 | AK22: =AG22+AI22 -> 0 | AP22: =AL22+AN22 -> 0 | AQ22: =AM22+AO22 -> 0 | AR22: 0 | AV22: =AR22+AT22 -> 0 | AW22: =AS22+AU22 -> 0 | AX22: 0 | BB22: =AX22+AZ22 -> 0 | BD22: =AY22+BA22 -> 0 | BE22: 0 | BI22: =BE22+BG22 -> 0 | BK22: =BF22+BH22 -> 0 | BN22: 0 | BP22: =BL22+BN22 -> 0 | BR22: =BM22+BO22 -> 0 | BW22: =BS22+BU22 -> 0 | BY22: =BT22+BV22 -> 0 | CD22: =BZ22+CB22 -> 0 | CE22: =CA22+CC22 -> 0 | CJ22: =CF22+CH22 -> 0 | CK22: =CG22+CI22 -> 0 | CP22: =CL22+CN22 -> 0 | CQ22: =CM22+CO22 -> 0 | CV22: =CR22+CT22 -> 0 | CW22: =CS22+CU22 -> 0 | DB22: =CX22+CZ22 -> 0 | DC22: =CY22+DA22 -> 0 | DH22: =DD22+DF22 -> 0 | DI22: =DE22+DG22 -> 0 | DJ22: =AL22+AR22+AX22+BE22+BL22+BS22+BZ22+CF22+CL22+CR22+CX22+DD22 -> 0 | DK22: =AM22+AS22+AY22+BF22+BM22+BT22+CA22+CG22+CM22+CS22+CY22+DE22 -> 0 | DL22: =AN22+AT22+BC22+BJ22+BQ22+BX22+CB22+CH22+CN22+CT22+CZ22+DF22 -> 0 | DM22: =AO22+AU22+BA22+BH22+BO22+BV22+CC22+CI22+CO22+CU22+DA22+DG22 -> 0 | DN22: =DJ22+DL22 -> 0 | DO22: =DK22+DM22 -> 0
A23: 15 | B23: ბოლნისი | C23: P.2.809 | D23: (5) N11 საუბნოზე ი ჭავჭავაძის და წმინდა ნინოს ქუჩებზე კერძო საკუთრებაში გამავალი გაზსადენის გამოტანა მრიცხველების შეცვლა 140 აბონენტზე, რეაბილიტაცია . (P.2.809) | E23: მშენებლობა | F23: =SUM(DN23) -> 0 | G23: =I23+AK23+DN23 -> 0 | H23: 230000 | I23: 0 | J23: 0 | K23: =AK23 -> 0 | L23: =IF(AI23>0,I23+AK23-J23,0) -> 0 | M23: =I23+K23 -> 0 | N23: =G23-M23 -> 0 | O23: =IF(AND(AI23>0,DM23>0),"შეცდომაა! ერთზე მეტი ბოლო ჩაბარება!",IF(OR(AI23>0,DM23>0,),IF(AI23>0,I23+AK23,I23+AK23+DO23),IF(AND(I23=0,K23=0,DO23=0),"ნულოვანი შესრულება","მიმდინარეობს"))) -> ნულოვანი შესრულება | R23: =I23+P23 -> 0 | S23: =Q23 -> 0 | X23: =T23+V23 -> 0 | Y23: =U23+W23 -> 0 | AD23: =Z23+AB23 -> 0 | AE23: =AA23+AC23 -> 0 | AF23: =P23+T23+Z23 -> 0 | AG23: =P23+U23+AA23 -> 0 | AH23: =Q23+V23+AB23 -> 0 | AI23: =Q23+W23+AC23 -> 0 | AJ23: =AF23+AH23 -> 0 | AK23: =AG23+AI23 -> 0 | AP23: =AL23+AN23 -> 0 | AQ23: =AM23+AO23 -> 0 | AV23: =AR23+AT23 -> 0 | AW23: =AS23+AU23 -> 0 | BB23: =AX23+AZ23 -> 0 | BD23: =AY23+BA23 -> 0 | BI23: =BE23+BG23 -> 0 | BK23: =BF23+BH23 -> 0 | BP23: =BL23+BN23 -> 0 | BR23: =BM23+BO23 -> 0 | BW23: =BS23+BU23 -> 0 | BY23: =BT23+BV23 -> 0 | CD23: =BZ23+CB23 -> 0 | CE23: =CA23+CC23 -> 0 | CJ23: =CF23+CH23 -> 0 | CK23: =CG23+CI23 -> 0 | CP23: =CL23+CN23 -> 0 | CQ23: =CM23+CO23 -> 0 | CV23: =CR23+CT23 -> 0 | CW23: =CS23+CU23 -> 0 | DB23: =CX23+CZ23 -> 0 | DC23: =CY23+DA23 -> 0 | DH23: =DD23+DF23 -> 0 | DI23: =DE23+DG23 -> 0 | DJ23: =AL23+AR23+AX23+BE23+BL23+BS23+BZ23+CF23+CL23+CR23+CX23+DD23 -> 0 | DK23: =AM23+AS23+AY23+BF23+BM23+BT23+CA23+CG23+CM23+CS23+CY23+DE23 -> 0 | DL23: =AN23+AT23+BC23+BJ23+BQ23+BX23+CB23+CH23+CN23+CT23+CZ23+DF23 -> 0 | DM23: =AO23+AU23+BA23+BH23+BO23+BV23+CC23+CI23+CO23+CU23+DA23+DG23 -> 0 | DN23: =DJ23+DL23 -> 0 | DO23: =DK23+DM23 -> 0
A24: 16 | B24: ბოლნისი | C24: P.2.810 | D24: (6) N12 საუბნოზე თამარმეფის ქუჩისა და წმინდა ნინოს ქუჩებზე კერძო საკუთრებაში გამავალი გაზსადენის გამოტანა მრიცხველების შეცვლა 190 აბონენტზე, რეაბილიტაცია. (P.2.810) | E24: მშენებლობა | F24: =SUM(DN24) -> 0 | G24: =I24+AK24+DN24 -> 0 | H24: 225000 | I24: 0 | J24: 0 | K24: =AK24 -> 0 | L24: =IF(AI24>0,I24+AK24-J24,0) -> 0 | M24: =I24+K24 -> 0 | N24: =G24-M24 -> 0 | O24: =IF(AND(AI24>0,DM24>0),"შეცდომაა! ერთზე მეტი ბოლო ჩაბარება!",IF(OR(AI24>0,DM24>0,),IF(AI24>0,I24+AK24,I24+AK24+DO24),IF(AND(I24=0,K24=0,DO24=0),"ნულოვანი შესრულება","მიმდინარეობს"))) -> ნულოვანი შესრულება | R24: =I24+P24 -> 0 | S24: =Q24 -> 0 | X24: =T24+V24 -> 0 | Y24: =U24+W24 -> 0 | AD24: =Z24+AB24 -> 0 | AE24: =AA24+AC24 -> 0 | AF24: =P24+T24+Z24 -> 0 | AG24: =P24+U24+AA24 -> 0 | AH24: =Q24+V24+AB24 -> 0 | AI24: =Q24+W24+AC24 -> 0 | AJ24: =AF24+AH24 -> 0 | AK24: =AG24+AI24 -> 0 | AP24: =AL24+AN24 -> 0 | AQ24: =AM24+AO24 -> 0 | AV24: =AR24+AT24 -> 0 | AW24: =AS24+AU24 -> 0 | BB24: =AX24+AZ24 -> 0 | BD24: =AY24+BA24 -> 0 | BI24: =BE24+BG24 -> 0 | BK24: =BF24+BH24 -> 0 | BP24: =BL24+BN24 -> 0 | BR24: =BM24+BO24 -> 0 | BW24: =BS24+BU24 -> 0 | BY24: =BT24+BV24 -> 0 | CD24: =BZ24+CB24 -> 0 | CE24: =CA24+CC24 -> 0 | CJ24: =CF24+CH24 -> 0 | CK24: =CG24+CI24 -> 0 | CP24: =CL24+CN24 -> 0 | CQ24: =CM24+CO24 -> 0 | CV24: =CR24+CT24 -> 0 | CW24: =CS24+CU24 -> 0 | DB24: =CX24+CZ24 -> 0 | DC24: =CY24+DA24 -> 0 | DH24: =DD24+DF24 -> 0 | DI24: =DE24+DG24 -> 0 | DJ24: =AL24+AR24+AX24+BE24+BL24+BS24+BZ24+CF24+CL24+CR24+CX24+DD24 -> 0 | DK24: =AM24+AS24+AY24+BF24+BM24+BT24+CA24+CG24+CM24+CS24+CY24+DE24 -> 0 | DL24: =AN24+AT24+BC24+BJ24+BQ24+BX24+CB24+CH24+CN24+CT24+CZ24+DF24 -> 0 | DM24: =AO24+AU24+BA24+BH24+BO24+BV24+CC24+CI24+CO24+CU24+DA24+DG24 -> 0 | DN24: =DJ24+DL24 -> 0 | DO24: =DK24+DM24 -> 0
A25: 17 | B25: გურჯაანი | C25: P.2.875 | D25: (47) სოფ. ჩალაუბანში მრიცხველების გამოტანა 170 ც. ვოდების და მრიცხველების გამოატანა ეზოებიდან, 250ც. P.2.875 | E25: მშენებლობა | F25: =SUM(DN25) -> 0 | G25: =I25+AK25+DN25 -> 0 | H25: 47000 | I25: 0 | J25: 0 | K25: =AK25 -> 0 | L25: =IF(AI25>0,I25+AK25-J25,0) -> 0 | M25: =I25+K25 -> 0 | N25: =G25-M25 -> 0 | O25: =IF(AND(AI25>0,DM25>0),"შეცდომაა! ერთზე მეტი ბოლო ჩაბარება!",IF(OR(AI25>0,DM25>0,),IF(AI25>0,I25+AK25,I25+AK25+DO25),IF(AND(I25=0,K25=0,DO25=0),"ნულოვანი შესრულება","მიმდინარეობს"))) -> ნულოვანი შესრულება | R25: =I25+P25 -> 0 | S25: =Q25 -> 0 | X25: =T25+V25 -> 0 | Y25: =U25+W25 -> 0 | AD25: =Z25+AB25 -> 0 | AE25: =AA25+AC25 -> 0 | AF25: =P25+T25+Z25 -> 0 | AG25: =P25+U25+AA25 -> 0 | AH25: =Q25+V25+AB25 -> 0 | AI25: =Q25+W25+AC25 -> 0 | AJ25: =AF25+AH25 -> 0 | AK25: =AG25+AI25 -> 0 | AP25: =AL25+AN25 -> 0 | AQ25: =AM25+AO25 -> 0 | AV25: =AR25+AT25 -> 0 | AW25: =AS25+AU25 -> 0 | BB25: =AX25+AZ25 -> 0 | BD25: =AY25+BA25 -> 0 | BI25: =BE25+BG25 -> 0 | BK25: =BF25+BH25 -> 0 | BP25: =BL25+BN25 -> 0 | BR25: =BM25+BO25 -> 0 | BW25: =BS25+BU25 -> 0 | BY25: =BT25+BV25 -> 0 | CD25: =BZ25+CB25 -> 0 | CE25: =CA25+CC25 -> 0 | CJ25: =CF25+CH25 -> 0 | CK25: =CG25+CI25 -> 0 | CP25: =CL25+CN25 -> 0 | CQ25: =CM25+CO25 -> 0 | CV25: =CR25+CT25 -> 0 | CW25: =CS25+CU25 -> 0 | DB25: =CX25+CZ25 -> 0 | DC25: =CY25+DA25 -> 0 | DH25: =DD25+DF25 -> 0 | DI25: =DE25+DG25 -> 0 | DJ25: =AL25+AR25+AX25+BE25+BL25+BS25+BZ25+CF25+CL25+CR25+CX25+DD25 -> 0 | DK25: =AM25+AS25+AY25+BF25+BM25+BT25+CA25+CG25+CM25+CS25+CY25+DE25 -> 0 | DL25: =AN25+AT25+BC25+BJ25+BQ25+BX25+CB25+CH25+CN25+CT25+CZ25+DF25 -> 0 | DM25: =AO25+AU25+BA25+BH25+BO25+BV25+CC25+CI25+CO25+CU25+DA25+DG25 -> 0 | DN25: =DJ25+DL25 -> 0 | DO25: =DK25+DM25 -> 0
A26: 18 | B26: სიღნაღი | C26: P.2.780 | D26: (31) ქ. წნორი ჯავაშვილი ფილიმონის უბნიდან ბოდბისხევის ბაზრამდე ქუჩის რეაბილიტაცია (P.2.780) | E26: მშენებლობა | F26: =SUM(DN26) -> 0 | G26: =I26+AK26+DN26 -> 0 | H26: 75000 | I26: 0 | J26: 0 | K26: =AK26 -> 0 | L26: =IF(AI26>0,I26+AK26-J26,0) -> 0 | M26: =I26+K26 -> 0 | N26: =G26-M26 -> 0 | O26: =IF(AND(AI26>0,DM26>0),"შეცდომაა! ერთზე მეტი ბოლო ჩაბარება!",IF(OR(AI26>0,DM26>0,),IF(AI26>0,I26+AK26,I26+AK26+DO26),IF(AND(I26=0,K26=0,DO26=0),"ნულოვანი შესრულება","მიმდინარეობს"))) -> ნულოვანი შესრულება | R26: =I26+P26 -> 0 | S26: =Q26 -> 0 | X26: =T26+V26 -> 0 | Y26: =U26+W26 -> 0 | AD26: =Z26+AB26 -> 0 | AE26: =AA26+AC26 -> 0 | AF26: =P26+T26+Z26 -> 0 | AG26: =P26+U26+AA26 -> 0 | AH26: =Q26+V26+AB26 -> 0 | AI26: =Q26+W26+AC26 -> 0 | AJ26: =AF26+AH26 -> 0 | AK26: =AG26+AI26 -> 0 | AP26: =AL26+AN26 -> 0 | AQ26: =AM26+AO26 -> 0 | AV26: =AR26+AT26 -> 0 | AW26: =AS26+AU26 -> 0 | BB26: =AX26+AZ26 -> 0 | BD26: =AY26+BA26 -> 0 | BI26: =BE26+BG26 -> 0 | BK26: =BF26+BH26 -> 0 | BP26: =BL26+BN26 -> 0 | BR26: =BM26+BO26 -> 0 | BW26: =BS26+BU26 -> 0 | BY26: =BT26+BV26 -> 0 | CD26: =BZ26+CB26 -> 0 | CE26: =CA26+CC26 -> 0 | CJ26: =CF26+CH26 -> 0 | CK26: =CG26+CI26 -> 0 | CP26: =CL26+CN26 -> 0 | CQ26: =CM26+CO26 -> 0 | CV26: =CR26+CT26 -> 0 | CW26: =CS26+CU26 -> 0 | DB26: =CX26+CZ26 -> 0 | DC26: =CY26+DA26 -> 0 | DH26: =DD26+DF26 -> 0 | DI26: =DE26+DG26 -> 0 | DJ26: =AL26+AR26+AX26+BE26+BL26+BS26+BZ26+CF26+CL26+CR26+CX26+DD26 -> 0 | DK26: =AM26+AS26+AY26+BF26+BM26+BT26+CA26+CG26+CM26+CS26+CY26+DE26 -> 0 | DL26: =AN26+AT26+BC26+BJ26+BQ26+BX26+CB26+CH26+CN26+CT26+CZ26+DF26 -> 0 | DM26: =AO26+AU26+BA26+BH26+BO26+BV26+CC26+CI26+CO26+CU26+DA26+DG26 -> 0 | DN26: =DJ26+DL26 -> 0 | DO26: =DK26+DM26 -> 0
